Workbook

Sheet LISEZ-MOI
B1: SquirreLingo — Relecture du français (Français (France))
B2: Merci d’avoir accepté cette relecture. Ce fichier contient tout le français que l’application affiche à ses utilisateurs dans la version 3.2.0. Il a été rédigé par une IA et n’a jamais été relu par un locuteur natif ; vos corrections sont reprises telles quelles dans le produit. Ne jugez que le français : les autres langues présentes ici (espagnol, portugais, italien, allemand, japonais, coréen, chinois, anglais) sont la matière enseignée et ont leur propre relecteur natif.
B4: D’abord : quel français nous voulons
B5: • Variété : français de France. PAS de français québécois. Là où un terme diverge — « bug » contre « bogue », « e-mail » contre « courriel », « appli » contre « application », « chrono » contre « minuteur » — nous voulons la forme de France.
B6: • Registre : tutoiement (« tu ») dans toute l’application, jamais de vouvoiement. La question est tranchée — arbitrage du propriétaire du produit le 29 juillet 2026 — et elle n’est pas rouverte ici. Signalez seulement les phrases où le tutoiement sonne forcé, en proposant une meilleure tournure au « tu ».
B7: • Genre : l’application s’adresse directement à la personne qui l’utilise, donc nous cherchons des formulations épicènes partout où c’est possible — pas de parenthèse de genre, pas de point médian, et pas d’accord de participe ou d’adjectif qui présume du genre de la personne qui lit.
B8: • Ton : proche, bref et encourageant. L’application ne gronde jamais et ne punit jamais.
B10: Comment remplir le fichier
B11: 1. Traitez un onglet à la fois. L’ordre conseillé figure dans l’onglet SYNTHÈSE.
B12: 2. Chaque ligne porte une colonne VERDICT avec une liste déroulante. Choisissez une valeur :
B13: – OK — le français convient tel quel. Rien d’autre à écrire.
B14: – CORRIGER — il y a quelque chose à reprendre. Écrivez le texte corrigé en entier dans « CORRECTION PROPOSÉE ».
... B26: Exemple d’une ligne correctement remplie
B27: Français actuel | C27: VERDICT | D27: CORRECTION PROPOSÉE | E27: NOTE / MOTIF
B28: Prêt à passer à {level} ? | C28: CORRIGER | D28: Envie de passer à {level} ? | E28: L’adjectif « Prêt » s’accorde au masculin alors que la phrase s’adresse à n’importe qui. La reformulation est épicène, garde l’espace insécable devant le point d’interrogation et recopie {level} à l’identique. Même traitement partout où un participe ou un adjectif présume du genre.
B31: Ce qui compte le plus
B32: • L’onglet 1-Variantes-régionales est le plus risqué : l’application y affirme qu’en France on dit un terme et qu’au Québec on en dit un autre. Une attribution fausse est une erreur visible qui abîme la crédibilité. Sachez toutefois ce que vous regardez : le registre français de la carte est une AMORCE de deux concepts seulement, « car » et « girlfriend » — pas un répertoire construit. Vous relisez une amorce, et la vraie question est ce qu’il faut y ajouter (voir la fiche de décision correspondante).
B33: • Dans cet onglet, ce sont les lignes RÉFÉRENCE qui vous appartiennent : elles portent les termes de FRANCE, et cette voie en est l’autorité — le registre des voies donne à fr-fr le périmètre « reference ». Ce sont les seules lignes que vous ayez à juger. Les lignes PAR DÉFAUT et RÉGIONAL portent les termes du QUÉBEC : fond gris, italique, marquées « indicatif » dans la colonne « Variété responsable », elles relèvent de la voie fr-ca et tout verdict que vous y posez est rangé au dépouillement dans la section hors périmètre. Elles sont affichées parce que la carte montre les deux moitiés ensemble et que, sans le contraste, la vôtre est difficile à juger. Si quelque chose vous saute aux yeux, dites-le — nous le prenons comme indication, pas comme verdict.
B34: • L’onglet 2-Décisions rassemble des choix que nous avons faits volontairement et sur lesquels nous avons besoin de votre avis explicite. Peu de lignes, et elles valent cher : vos réponses tranchent d’avance des dizaines de lignes dans les autres onglets.
B35: • Ce que nous savons déjà, pour que vous n’ayez pas à nous le signaler. (1) Les 10 lignes de l’onglet 4-Questions-sécurité ont une cellule française vide : lib/securityQuestions.js ne contient aucun français et son résolveur est codé en dur sur l’espagnol. C’est un correctif de code, pas un trou de traduction. (2) Les 184 lignes de l’onglet 8-Nouveautés sont vides elles aussi : l’historique des versions n’a pas encore été écrit en français, et cette traduction est en dernière priorité. Ces deux onglets ne demandent pas votre attention ; ils sont dans le fichier pour que vous en voyiez l’ampleur.
B37: Pour finir
B38: Renseignez votre nom et la date dans l’onglet SYNTHÈSE, puis renvoyez ce même fichier .xlsx. Inutile d’en changer le format ou de rédiger un rapport à part : nous lisons les colonnes directement.

Sheet SYNTHÈSE
B2: Bilan et signature de la relecture — Français (France) · Interface
B3: Ce que l’application dit à ses utilisateurs
B5: Nom de la personne qui relit :
B6: Pays / région d’origine :
B7: Date de remise :
B8: Est-ce que je valide l’ensemble ?
A11: Ordre | B11: Onglet | C11: Contenu | D11: Lignes | E11: OK | F11: CORRIGER | G11: DOUTE | H11: Non relu
A12: 1 | B12: 1-Variantes-régionales | C12: Termes par région. LE PLUS IMPORTANT — commencez par là. Les lignes RÉFÉRENCE (France) sont les vôtres. | D12: 6 | E12: =COUNTIF('1-Variantes-régionales'!$I$2:$I$7,"OK") -> 0 | F12: =COUNTIF('1-Variantes-régionales'!$I$2:$I$7,"CORRIGER") -> 0 | G12: =COUNTIF('1-Variantes-régionales'!$I$2:$I$7,"DOUTE") -> 0 | H12: =D12-E12-F12-G12 -> 6
A13: 2 | B13: 2-Décisions | C13: Décisions prises à dessein, sur lesquelles nous voulons votre avis. | D13: 16 | E13: =COUNTIF('2-Décisions'!$E$2:$E$17,"VALIDÉ") -> 0 | F13: =COUNTIF('2-Décisions'!$E$2:$E$17,"CORRIGER") -> 0 | G13: =COUNTIF('2-Décisions'!$E$2:$E$17,"DOUTE") -> 0 | H13: =D13-E13-F13-G13 -> 16
A14: 3 | B14: 3-Config-carte | C14: Textes de la carte des variantes, noms de régions et libellés. | D14: 15 | E14: =COUNTIF('3-Config-carte'!$F$2:$F$16,"OK") -> 0 | F14: =COUNTIF('3-Config-carte'!$F$2:$F$16,"CORRIGER") -> 0 | G14: =COUNTIF('3-Config-carte'!$F$2:$F$16,"DOUTE") -> 0 | H14: =D14-E14-F14-G14 -> 15
A15: 4 | B15: 4-Questions-sécurité | C15: Les 10 questions de récupération du mot de passe. | D15: 10 | E15: =COUNTIF('4-Questions-sécurité'!$F$2:$F$11,"OK") -> 0 | F15: =COUNTIF('4-Questions-sécurité'!$F$2:$F$11,"CORRIGER") -> 0 | G15: =COUNTIF('4-Questions-sécurité'!$F$2:$F$11,"DOUTE") -> 0 | H15: =D15-E15-F15-G15 -> 10
A16: 5 | B16: 5-Interface | C16: Toute l’interface : compte, paramètres, formulaires, jeu. | D16: 403 | E16: =COUNTIF('5-Interface'!$F$2:$F$404,"OK") -> 0 | F16: =COUNTIF('5-Interface'!$F$2:$F$404,"CORRIGER") -> 0 | G16: =COUNTIF('5-Interface'!$F$2:$F$404,"DOUTE") -> 0 | H16: =D16-E16-F16-G16 -> 403
A17: 6 | B17: 6-Autres-textes | C17: Visite guidée, noms de langues, niveaux, sous-titres. | D17: 57 | E17: =COUNTIF('6-Autres-textes'!$F$2:$F$58,"OK") -> 0 | F17: =COUNTIF('6-Autres-textes'!$F$2:$F$58,"CORRIGER") -> 0 | G17: =COUNTIF('6-Autres-textes'!$F$2:$F$58,"DOUTE") -> 0 | H17: =D17-E17-F17-G17 -> 57
A18: 7 | B18: 7-Aide-APropos | C18: Textes longs des pages Aide et À propos. | D18: 110 | E18: =COUNTIF('7-Aide-APropos'!$F$2:$F$111,"OK") -> 0 | F18: =COUNTIF('7-Aide-APropos'!$F$2:$F$111,"CORRIGER") -> 0 | G18: =COUNTIF('7-Aide-APropos'!$F$2:$F$111,"DOUTE") -> 0 | H18: =D18-E18-F18-G18 -> 110
A19: 8 | B19: 8-Nouveautés | C19: Notes de version traduites. Priorité basse, c’est de l’historique. | D19: 184 | E19: =COUNTIF('8-Nouveautés'!$F$2:$F$185,"OK") -> 0 | F19: =COUNTIF('8-Nouveautés'!$F$2:$F$185,"CORRIGER") -> 0 | G19: =COUNTIF('8-Nouveautés'!$F$2:$F$185,"DOUTE") -> 0 | H19: =D19-E19-F19-G19 -> 184
C20: TOTAL | D20: =SUM(D12:D19) -> 801 | E20: =SUM(E12:E19) -> 0 | F20: =SUM(F12:F19) -> 0 | G20: =SUM(G12:G19) -> 0 | H20: =SUM(H12:H19) -> 801
B22: « Non relu » ne tombe à zéro que lorsque chaque ligne porte un verdict. Il n’est pas nécessaire d’arriver à zéro pour nous renvoyer le fichier : envoyez ce que vous avez et nous repartons de là.

Sheet 1-Variantes-régionales
A1: ID | B1: Concept nº | C1: Concept (anglais) | D1: Type | E1: Terme actuel | F1: Régions attribuées | G1: Libellé de groupe | H1: Variété responsable | I1: VERDICT | J1: TERME CORRIGÉ | K1: RÉGIONS CORRIGÉES | L1: NOTE / MOTIF
A2: VR-001-REF | B2: 1 | C2: car | D2: RÉFÉRENCE | E2: voiture | F2: FR | G2: France | H2: fr-fr
A3: VR-001-DEF | B3: 1 | C3: car | D3: PAR DÉFAUT | E3: voiture | F3: (unlisted countries) | G3: Québec | H3: fr-ca (indicatif)
A4: VR-001-a | B4: 1 | C4: car | D4: RÉGIONAL | E4: char | F4: CA | G4: Québec | H4: fr-ca (indicatif)
A5: VR-002-REF | B5: 2 | C5: girlfriend | D5: RÉFÉRENCE | E5: copine | F5: FR | G5: France | H5: fr-fr
A6: VR-002-DEF | B6: 2 | C6: girlfriend | D6: PAR DÉFAUT | E6: copine | F6: (unlisted countries) | G6: Québec | H6: fr-ca (indicatif)
A7: VR-002-a | B7: 2 | C7: girlfriend | D7: RÉGIONAL | E7: blonde | F7: CA | G7: Québec | H7: fr-ca (indicatif)

Sheet 2-Décisions
A1: ID | B1: Sujet | C1: Ce que nous avons décidé et pourquoi | D1: Exemple / où | E1: DÉCISION | F1: AUTRE PROPOSITION | G1: NOTE
A2: DEC-01 | B2: Variété et registre (déjà tranché) | C2: Tout le français de l’application est du français de France, jamais du français québécois. Le registre est DÉJÀ TRANCHÉ : SquirreLingo tutoie ses utilisateurs — « tu », informel, partout, jamais « vous ». Arbitrage du propriétaire du produit, 29 juillet 2026. La question est CLOSE : ne rouvrez pas « tu » contre « vous ». Ce que nous vous demandons, c’est de signaler les tournures au « tu » qui sonnent maladroites et d’en proposer de meilleures, toujours au « tu ». Seule exception, ailleurs que dans l’interface : une phrase d’exercice dont le sujet est un véritable pluriel de deuxième personne emploie « vous » — c’est du nombre grammatical, pas du registre. | D2: « Mot de passe oublié ? » · « Tu as déjà un compte ? Connecte-toi » · « Définis un nouveau mot de passe »
A3: DEC-02 | B3: Formulations épicènes | C3: L’application s’adresse directement à la personne qui l’utilise, donc nous évitons les formes « (e) », le point médian et les accords qui présument du genre. Deux cas ont déjà été repris : l’accueil dit maintenant « Bienvenue » et le niveau expert « Tu es à l'aise ». Cinq accords au masculin subsistent, listés à côté. Nous cherchons des reformulations neutres, pas une convention d’écriture inclusive. | D3: « Pas sûr ? » (notSureTakeQuiz) · « Prêt à passer à {level} ? » (readyToAdvance) · « tu seras connecté tout de suite » (baAcctIntro) · « Un indice que toi seul comprends » (baPhHint) · « une fois arrivé à un niveau avancé » (setGpTogTense)
A4: DEC-03 | B4: Anglicismes conservés | C4: Nous laissons en anglais les termes techniques déjà courants en France, ainsi que les noms de marques. À l’inverse, certains ont été francisés : l’anglais « Apply to beta test » est rendu par « Demande à être bêta-testeur », et « flashcards » par « cartes mémoire ». Dites-nous si l’un des anglicismes conservés détonne, ou si l’un des termes francisés devrait au contraire revenir à l’anglais. | D4: « e-mail » · « Chromebook » · « bug » · « chrono » · « combo » · « XP »
A5: DEC-04 | B5: Lexique de France | C5: Nous choisissons délibérément la forme de France plutôt que la forme québécoise. Un point à confirmer en particulier : l’écran de configuration s’appelle « Réglages » partout — cinq fois dans lib/playStrings.js, treize fois dans le français de lib/helpAboutContent.js — et « Paramètres » n’apparaît nulle part. Si vous préférez « Paramètres », dites-le ici une seule fois : il faudra changer les deux fichiers d’un coup. Vérifiez par ailleurs qu’aucun québécisme ne s’est glissé dans l’interface. | D5: « Réglages » · « e-mail » · « ordinateur portable » · « cartes mémoire » · « icône » · « appli »
A6: DEC-05 | B6: « Verbes » pour la catégorie héritée verbo | C6: Deux clés de catégorie coexistent dans lib/playStrings.js : gram, rendue par « Grammaire », et verbo, la clé héritée des cours espagnols, rendue par « Verbes ». L’anglais dit « Grammar » pour les deux. Sur le cours de français, la catégorie affichée à l’écran est donc « Verbes » alors qu’elle ne contient que de la conjugaison. Est-ce le bon nom, ou faut-il « Conjugaison » ? Votre réponse vaut aussi pour l’italien et le portugais, qui partagent la clé. | D6: CATEGORY_NAMES.verbo → « Verbes » · CATEGORY_NAMES.gram → « Grammaire » (lib/playStrings.js)
A7: DEC-06 | B7: « Roues d'appoint » — un nom, trois formulations | C7: Les pastilles qui nomment le temps verbal attendu sont appelées « training-wheels » en anglais ; nous avons gardé l’image, « Roues d'appoint », et le ton joueur est volontaire. Mais la même fonction porte trois noms différents selon l’écran, et tous les trois sont en production aujourd’hui. Deux questions : l’image fonctionne-t-elle en France, et quel nom unique faut-il retenir pour les trois surfaces ? | D7: « Roues d'appoint pour les temps verbaux » (setGpTogTense) · « indications de temps verbal » (setGpSummary) · « indices de temps » (page d’aide)
A8: DEC-07 | B8: Guillemets, apostrophe et tiret cadratin | C8: Style maison : guillemets français « ainsi » plutôt que les guillemets droits, apostrophe typographique ’ et tiret cadratin — pour les incises. Les guillemets et le tiret sont bien appliqués ; l’apostrophe ne l’est PAS. Les 403 chaînes françaises de lib/playStrings.js emploient 94 apostrophes droites et aucune typographique, tandis que le français de lib/helpAboutContent.js en emploie 191 typographiques et aucune droite. Faut-il tout basculer sur ’, et est-ce visible pour un lecteur français ? | D8: « Ce nom d'utilisateur est déjà pris » (droite) contre « Trouver l’aide et le menu » (typographique)
A9: DEC-08 | B9: Glossaire du produit | C9: Noms fixes qui reviennent dans toute l’application. Si vous en changez un, il faut le changer partout : dites-le une seule fois ici plutôt que ligne par ligne dans les autres onglets. | D9: Quiz Rapide · Leçons · Gym de grammaire · Banque de mots · mode Alphabet · Réglages · CECR · test de niveau · série · combo · Mode révision · « Attention » · TDAH
A10: DEC-09 | B10: Les termes de FRANCE — vos lignes (risque élevé) | C10: Sur l’onglet 1-Variantes-régionales, les lignes RÉFÉRENCE portent les termes de France. C’est la moitié dont cette voie est l’autorité, et la seule que vous ayez à juger. Elle ne contient aujourd’hui que deux concepts : c’est une amorce, pas un répertoire. La vraie question est donc ce qu’il faut y mettre. Le dossier de cette voie recense huit termes où le français de France et le québécois divergent — bug/bogue, e-mail/courriel, appli/application, chrono/minuteur, Achats/Magasinage, cartes mémoire/fiches, soutien scolaire/tutorat, et Se déconnecter, neutre. L’application n’a qu’UNE colonne française : il nous faut une seule réponse acceptable des deux côtés. Lesquels valent la peine d’entrer dans la carte ? | D10: « voiture » (concept car) · « copine » (concept girlfriend) — les deux seules lignes RÉFÉRENCE du paquet
A11: DEC-10 | B11: Les termes du QUÉBEC (hors de votre périmètre) | C11: Les lignes PAR DÉFAUT et RÉGIONAL portent les termes du Québec. Elles relèvent de la voie fr-ca, qui n’a pas encore de relecteur. Elles sont affichées en gris et en italique, marquées « indicatif » dans la colonne « Variété responsable », et tout verdict que vous y posez est rangé au dépouillement dans la section hors périmètre : indicatif, jamais contraignant. Elles sont là parce que la carte montre les deux moitiés côte à côte et que, sans le contraste, votre moitié est difficile à juger. | D11: « char » (car) · « blonde » (girlfriend) — étiquette de groupe « Québec »
A12: DEC-11 | B12: Espaces insécables | C12: Style maison : une espace insécable (U+00A0) devant les deux-points, le point-virgule, le point d’interrogation et le point d’exclamation, et à l’intérieur des guillemets. Sur les 403 chaînes françaises de lib/playStrings.js la règle est déjà tenue partout, et nous aimerions que vous le confirmiez plutôt que de le supposer. Le seul manque connu est ailleurs : il vient d’une phrase assemblée à l’exécution (voir la note sur homeGreeting). Si vous en repérez d’autres du même genre, signalez-les : ils sont invisibles dans un diff. | D12: « Niveau : » (levelLabel) · « Focus de la manche : » (roundFocus) · « Pas sûr ? » (notSureTakeQuiz)
A13: DEC-12 | B13: Noms de fonctionnalités traduits | C13: Nous avons traduit les noms de fonctionnalités au lieu de les garder en anglais. Est-ce que cela se lit naturellement pour un utilisateur français, ou faut-il en laisser certains en anglais ? | D13: « Gym de grammaire » (Grammar Gym) · « Banque de mots » (Word Bank) · « manche » (a round of play) · « CECR » (CEFR) · « série » (streak)
... A17: DEC-16 | B17: Le contenu des cours n’est pas dans ce paquet | C17: Ce paquet ne contient aucun échantillon de contenu : il ne porte que sur l’interface. Le français des cours est relu dans les deux autres paquets — 959 questions pour le cours de français, et 13 554 entrées des tables l10n plus 1 548 questions pour le français qui explique d’autres langues. Ce que nous vous demandons ici, c’est de signaler tout motif qui se répète : une tournure, un choix de terme, une règle typographique. Nous l’appliquons ensuite sur tout le corpus, pas seulement sur la ligne où vous l’avez vu. | D17: Signalez le motif UNE fois dans la note ; nous le propageons à l’ensemble du corpus.

Sheet 3-Config-carte
A1: ID | B1: Section | C1: Clé / emplacement | D1: Anglais (référence) | E1: Français actuel | F1: VERDICT | G1: CORRECTION PROPOSÉE | H1: NOTE / MOTIF | I1: Priorité | J1: Note de l’équipe | K1: Fichier
A2: CF-01 | B2: Textes de la carte | C2: title | D2: ui.title | E2: On dit aussi | I2: Haute
A3: CF-02 | B3: Textes de la carte | C3: inYourRegion | D3: ui.inYourRegion | E3: dans ta région | I3: Haute
A4: CF-03 | B4: Textes de la carte | C4: variantes | D4: ui.variantes | E4: variantes régionales | I4: Haute
A5: CF-04 | B5: Textes de la carte | C5: hide | D5: ui.hide | E5: masquer | I5: Haute
A6: CF-05 | B6: Textes de la carte | C6: refPhrase | D6: ui.refPhrase | E6: En France | I6: Haute
A7: CF-06 | B7: Textes de la carte | C7: regGroupPhrase | D7: ui.regGroupPhrase | E7: Au Québec | I7: Haute
A8: CF-07 | B8: Textes de la carte | C8: refFlag | D8: ui.refFlag | E8: 🇫🇷 | I8: Haute
A9: CF-08 | B9: Textes de la carte | C9: regFlag | D9: ui.regFlag | E9: 🇨🇦 | I9: Haute
A10: CF-09 | B10: Noms de pays | C10: FR | D10: ISO FR | E10: France | I10: Haute
A11: CF-10 | B11: Noms de pays | C11: CA | D11: ISO CA | E11: Quebec | I11: Haute
A12: CF-11 | B12: Noms de pays | C12: BE | D12: ISO BE | E12: Belgique | I12: Haute
A13: CF-12 | B13: Noms de pays | C13: CH | D13: ISO CH | E13: Suisse | I13: Haute
... A16: CF-15 | B16: Libellés de groupes de pays | C16: reference.label | D16: (reference variety name) | E16: France | I16: Haute

Sheet 4-Questions-sécurité
A1: ID | B1: Section | C1: Clé / emplacement | D1: Anglais (référence) | E1: Français actuel | F1: VERDICT | G1: CORRECTION PROPOSÉE | H1: NOTE / MOTIF | I1: Priorité | J1: Note de l’équipe | K1: Fichier
A2: PS-01 | B2: Question de sécurité | C2: first_pet | D2: What was the name of your first pet? | I2: Haute | K2: lib/securityQuestions.js
A3: PS-02 | B3: Question de sécurité | C3: childhood_street | D3: What street did you live on as a child? | I3: Haute | J3: La cellule française est VIDE, et c’est normal : lib/securityQuestions.js ne contient aucun français, et son résolveur est codé en dur sur l’espagnol. C’est un correctif de code, pas un trou de traduction, et les dix lignes de cet onglet sont dans le même cas : rien à relire. Si vous voulez nous faire gagner un tour, dites-nous quelle formulation française de « What street did you live on as a child? » évite un accord de genre. | K3: lib/securityQuestions.js
A4: PS-03 | B4: Question de sécurité | C4: mother_maiden | D4: What is your mother's maiden name? | I4: Haute | K4: lib/securityQuestions.js
A5: PS-04 | B5: Question de sécurité | C5: first_school | D5: What was the name of your first school? | I5: Haute | K5: lib/securityQuestions.js
A6: PS-05 | B6: Question de sécurité | C6: childhood_nickname | D6: What was your childhood nickname? | I6: Haute | K6: lib/securityQuestions.js
A7: PS-06 | B7: Question de sécurité | C7: first_car | D7: What was the make of your first car? | I7: Haute | K7: lib/securityQuestions.js
A8: PS-07 | B8: Question de sécurité | C8: birth_city | D8: In what city were you born? | I8: Haute | K8: lib/securityQuestions.js
A9: PS-08 | B9: Question de sécurité | C9: best_friend | D9: What is the first name of your oldest friend? | I9: Haute | K9: lib/securityQuestions.js
A10: PS-09 | B10: Question de sécurité | C10: first_job | D10: What was your first job? | I10: Haute | K10: lib/securityQuestions.js
A11: PS-10 | B11: Question de sécurité | C11: grandmother_name | D11: What was your maternal grandmother's first name? | I11: Haute | K11: lib/securityQuestions.js

Sheet 5-Interface
A1: ID | B1: Section | C1: Clé / emplacement | D1: Anglais (référence) | E1: Français actuel | F1: VERDICT | G1: CORRECTION PROPOSÉE | H1: NOTE / MOTIF | I1: Priorité | J1: Note de l’équipe | K1: Fichier
A2: IU-0001 | B2: Connexion et inscription | C2: authAgreeMid | D2: and | E2: et la | I2: Haute | J2: Ce fragment vaut « et la ». Il est assemblé à l’exécution avec « J'accepte les », « Conditions d'utilisation » et « Politique de confidentialité ». Vérifiez que la phrase entière se lit bien et que « et la » s’accorde avec ce qui suit. | K2: lib/playStrings.js
A3: IU-0002 | B3: Connexion et inscription | C3: authAgreePp | D3: Privacy Policy | E3: Politique de confidentialité | I3: Moyenne | K3: lib/playStrings.js
A4: IU-0003 | B4: Connexion et inscription | C4: authAgreePre | D4: I agree to the | E4: J'accepte les | I4: Haute | J4: Fragment assemblé — voir authAgreeMid. Il vaut « J'accepte les » et il est immédiatement suivi du lien « Conditions d'utilisation ». La correction doit tenir compte de l’espace final, qui est significative. | K4: lib/playStrings.js
A5: IU-0004 | B5: Connexion et inscription | C5: authAgreeTos | D5: Terms of Service | E5: Conditions d'utilisation | I5: Moyenne | K5: lib/playStrings.js
A6: IU-0005 | B6: Connexion et inscription | C6: authBetaLink | D6: Apply to beta test | E6: Demande à être bêta-testeur | I6: Haute | J6: Même texte que baTitle, « Demande à être bêta-testeur », mais affiché ici comme lien juste après « Pas encore d'invitation ? ». Vérifiez que l’enchaînement des deux fragments se lit bien. | K6: lib/playStrings.js
A7: IU-0006 | B7: Connexion et inscription | C7: authBetaPre | D7: Don't have an invite yet? | E7: Pas encore d'invitation ? | I7: Moyenne | K7: lib/playStrings.js
A8: IU-0007 | B8: Connexion et inscription | C8: authBtnSignin | D8: SIGN IN | E8: SE CONNECTER | I8: Moyenne | K8: lib/playStrings.js
A9: IU-0008 | B9: Connexion et inscription | C9: authBtnSignup | D9: SIGN UP | E9: S'INSCRIRE | I9: Moyenne | K9: lib/playStrings.js
A10: IU-0009 | B10: Connexion et inscription | C10: authConfirmEmail | D10: Confirm email | E10: Confirmer l'e-mail | I10: Moyenne | K10: lib/playStrings.js
A11: IU-0010 | B11: Connexion et inscription | C11: authConfirmPassword | D11: Confirm password | E11: Confirmer le mot de passe | I11: Moyenne | K11: lib/playStrings.js
A12: IU-0011 | B12: Connexion et inscription | C12: authEmail | D12: Email | E12: E-mail | I12: Moyenne | K12: lib/playStrings.js
A13: IU-0012 | B13: Connexion et inscription | C13: authErrAgree | D13: You need to agree to the Terms of Service and Privacy Policy to continue. | E13: Tu dois accepter les Conditions d'utilisation et la Politique de confidentialité pour continuer. | I13: Moyenne | K13: lib/playStrings.js
A14: IU-0013 | B14: Connexion et inscription | C14: authErrEmailExists | D14: An account with that email already exists. Try signing in, or use 'Forgot password' if you don't remember your password. | E14: Un compte avec cet e-mail existe déjà. Essaie de te connecter, ou utilise « Mot de passe oublié ? » si tu ne t'en souviens pas. | I14: Moyenne | K14: lib/playStrings.js
A15: IU-0014 | B15: Connexion et inscription | C15: authErrEmailExistsShort | D15: An account with that email already exists. Try signing in instead. | E15: Un compte avec cet e-mail existe déjà. Essaie plutôt de te connecter. | I15: Moyenne | K15: lib/playStrings.js
A16: IU-0015 | B16: Connexion et inscription | C16: authErrEmailMismatch | D16: Email addresses don't match. | E16: Les adresses e-mail ne correspondent pas. | I16: Moyenne | K16: lib/playStrings.js
A17: IU-0016 | B17: Connexion et inscription | C17: authErrGeneric | D17: Something went wrong. | E17: Quelque chose s'est mal passé. | I17: Moyenne | K17: lib/playStrings.js
A18: IU-0017 | B18: Connexion et inscription | C18: authErrInvalidCreds | D18: Invalid login credentials. | E18: Identifiants incorrects. | I18: Moyenne | K18: lib/playStrings.js
... A84: IU-0083 | B84: Réglages | C84: setComingSoon | D84: Coming soon. | E84: Bientôt disponible. | I84: Moyenne | K84: lib/playStrings.js
A85: IU-0084 | B85: Réglages | C85: setCountryNote | D85: Combined with your native language, this determines the regional label shown on the home screen (e.g. Spanish + Venezuela → "Español (Latinoamérica)"). | E85: Combiné à ta langue maternelle, ceci détermine l'étiquette régionale affichée sur l'écran d'accueil (p. ex. français + Canada → « Français (Canada) »). | I85: Haute | J85: La typographie est déjà conforme : guillemets français et espaces insécables dans « Français (Canada) ». C’est l’exemple lui-même qui interroge : il est canadien alors que cette voie est celle de la France. Un exemple métropolitain serait-il plus parlant, ou le cas canadien illustre-t-il mieux le mécanisme ? | K85: lib/playStrings.js
A86: IU-0085 | B86: Réglages | C86: setDrawerTitle | D86: Settings | E86: Réglages | I86: Moyenne | K86: lib/playStrings.js
A87: IU-0086 | B87: Réglages | C87: setErrChoosePhoto | D87: Choose a photo to upload. | E87: Choisis une photo à envoyer. | I87: Moyenne | K87: lib/playStrings.js
A88: IU-0087 | B88: Réglages | C88: setErrCurPwRequired | D88: Enter your current password to confirm this change. | E88: Saisis ton mot de passe actuel pour confirmer ce changement. | I88: Moyenne | K88: lib/playStrings.js
A89: IU-0088 | B89: Réglages | C89: setErrCurPwWrong | D89: Current password is incorrect. | E89: Le mot de passe actuel est incorrect. | I89: Moyenne | K89: lib/playStrings.js
A90: IU-0089 | B90: Réglages | C90: setErrEmailsMismatch | D90: Emails don't match. | E90: Les e-mails ne correspondent pas. | I90: Moyenne | K90: lib/playStrings.js
A91: IU-0090 | B91: Réglages | C91: setErrGeneric | D91: Something went wrong. | E91: Quelque chose s'est mal passé. | I91: Moyenne | K91: lib/playStrings.js
A92: IU-0091 | B92: Réglages | C92: setErrPhotoSize | D92: Photo must be under 3MB. | E92: La photo doit peser moins de 3 Mo. | I92: Moyenne | K92: lib/playStrings.js
A93: IU-0092 | B93: Réglages | C93: setErrPickFlag | D93: Pick a flag. | E93: Choisis un drapeau. | I93: Moyenne | K93: lib/playStrings.js
A94: IU-0093 | B94: Réglages | C94: setErrPickIcon | D94: Pick an icon. | E94: Choisis une icône. | I94: Moyenne | K94: lib/playStrings.js
A95: IU-0094 | B95: Réglages | C95: setErrPwLen | D95: New password must be at least 6 characters. | E95: Le nouveau mot de passe doit comporter au moins 6 caractères. | I95: Moyenne | K95: lib/playStrings.js
A96: IU-0095 | B96: Réglages | C96: setErrPwMismatch | D96: New passwords don't match. | E96: Les nouveaux mots de passe ne correspondent pas. | I96: Moyenne | K96: lib/playStrings.js
A97: IU-0096 | B97: Réglages | C97: setErrRecoveryDupes | D97: Pick three different questions. | E97: Choisis trois questions différentes. | I97: Moyenne | K97: lib/playStrings.js
... A116: IU-0115 | B116: Réglages | C116: setGpSummaryPhon | D116: ({time}s phonetics) | E116: ({time}s phonétique) | I116: Moyenne | K116: lib/playStrings.js
A117: IU-0116 | B117: Réglages | C117: setGpTogCaudio | D117: Show a speaker button on the answer choices too — only after you've answered (in review/pause), tap to hear an option read aloud. Rolling out per track; appears where option audio exists. | E117: Afficher aussi un bouton haut-parleur sur les options de réponse — seulement après avoir répondu (en révision/pause), touche pour écouter une option à voix haute. Déployé langue par langue ; apparaît là où l'audio des options existe. | I117: Haute | J117: L’anglais dit « Rolling out per track », où « track » désigne un COURS de langue. Le français le rend par « Déployé langue par langue ; apparaît là où l'audio des options existe. » Est-ce compris tel quel, ou faut-il dire « cours par cours » ? | K117: lib/playStrings.js
A118: IU-0117 | B118: Réglages | C118: setGpTogQaudio | D118: Show a speaker button on questions that have audio (tap to hear the prompt read aloud — never plays automatically) | E118: Afficher un bouton haut-parleur sur les questions qui ont de l'audio (touche pour écouter la consigne à voix haute — ne se lance jamais tout seul) | I118: Moyenne | K118: lib/playStrings.js
A119: IU-0118 | B119: Réglages | C119: setGpTogReview | D119: Pause after each answer to review the explanation (tap "Next" to continue) | E119: Faire une pause après chaque réponse pour lire l'explication (touche « Suivant » pour continuer) | I119: Moyenne | K119: lib/playStrings.js
A120: IU-0119 | B120: Réglages | C120: setGpTogTense | D120: Tense training-wheels: on verb-conjugation questions, name the tense being asked for and why. On by default; you can also dismiss it in-round once you reach an advanced level. | E120: Roues d'appoint pour les temps verbaux : sur les questions de conjugaison, indique quel temps est demandé et pourquoi. Activé par défaut ; tu peux aussi le masquer en pleine manche une fois arrivé à un niveau avancé. | I120: Haute | J120: Le libellé commence par « Roues d'appoint pour les temps verbaux », traduction de « training-wheels » : le ton joueur est volontaire. Deux questions : l’image fonctionne-t-elle en France, et la fin de la phrase, « une fois arrivé à un niveau avancé », s’accorde au masculin — une reformulation épicène ? | K120: lib/playStrings.js
A121: IU-0120 | B121: Réglages | C121: setGroupAccount | D121: Account | E121: Compte | I121: Moyenne | K121: lib/playStrings.js
A122: IU-0121 | B122: Réglages | C122: setGroupFeedback | D122: Feedback | E122: Commentaires | I122: Moyenne | K122: lib/playStrings.js
A123: IU-0122 | B123: Réglages | C123: setGroupLang | D123: Language & Learning | E123: Langue et apprentissage | I123: Moyenne | K123: lib/playStrings.js
...

Sheet 6-Autres-textes
A1: ID | B1: Section | C1: Clé / emplacement | D1: Anglais (référence) | E1: Français actuel | F1: VERDICT | G1: CORRECTION PROPOSÉE | H1: NOTE / MOTIF | I1: Priorité | J1: Note de l’équipe | K1: Fichier
A2: OT-001 | B2: Visite guidée (premier lancement) | C2: STEPS[0].title | D2: Welcome to SquirreLingo! | E2: Welcome to SquirreLingo! | I2: Moyenne | K2: lib/guideSteps.js
A3: OT-002 | B3: Visite guidée (premier lancement) | C3: STEPS[0].body | D3: Language practice built for short, low-pressure bursts — answer a handful of questions, see how you did, stop whenever you like. Here's a quick 60-second tour of how to get around. | E3: Language practice built for short, low-pressure bursts — answer a handful of questions, see how you did, stop whenever you like. Here's a quick 60-second tour of how to get around. | I3: Moyenne | K3: lib/guideSteps.js
A4: OT-003 | B4: Visite guidée (premier lancement) | C4: STEPS[1].title | D4: Pick a language | E4: Pick a language | I4: Moyenne | K4: lib/guideSteps.js
A5: OT-004 | B5: Visite guidée (premier lancement) | C5: STEPS[1].body | D5: Tap any language bubble on the home screen to start practicing it. Each bubble shows your current level and progress, and every language is tracked separately — so you can dabble in a few without losing your place in any. | E5: Tap any language bubble on the home screen to start practicing it. Each bubble shows your current level and progress, and every language is tracked separately — so you can dabble in a few without losing your place in any. | I5: Moyenne | K5: lib/guideSteps.js
A6: OT-005 | B6: Visite guidée (premier lancement) | C6: STEPS[2].title | D6: Find your level | E6: Find your level | I6: Moyenne | K6: lib/guideSteps.js
A7: OT-006 | B7: Visite guidée (premier lancement) | C7: STEPS[2].body | D7: New to a language? Take its short, untimed placement quiz from the start screen — it samples every difficulty tier and sets you at the right one. Not sure? Just start playing; you'll be offered a level-up once you're answering well. | E7: New to a language? Take its short, untimed placement quiz from the start screen — it samples every difficulty tier and sets you at the right one. Not sure? Just start playing; you'll be offered a level-up once you're answering well. | I7: Moyenne | K7: lib/guideSteps.js
A8: OT-007 | B8: Visite guidée (premier lancement) | C8: STEPS[3].title | D8: Two ways to practice | E8: Two ways to practice | I8: Moyenne | K8: lib/guideSteps.js
A9: OT-008 | B9: Visite guidée (premier lancement) | C9: STEPS[3].body | D9: Quick Quiz is fast and game-style — a timer, a combo counter, and streaks. Lessons is calmer — no timer, one topic at a time, with the explanation right after each answer. Switch between them anytime; both build the same progress. | E9: Quick Quiz is fast and game-style — a timer, a combo counter, and streaks. Lessons is calmer — no timer, one topic at a time, with the explanation right after each answer. Switch between them anytime; both build the same progress. | I9: Moyenne | K9: lib/guideSteps.js
A10: OT-009 | B10: Visite guidée (premier lancement) | C10: STEPS[4].title | D10: Play a round | E10: Play a round | I10: Moyenne | K10: lib/guideSteps.js
A11: OT-010 | B11: Visite guidée (premier lancement) | C11: STEPS[4].body | D11: Each round mixes a few question types — a colored tag shows which is which. There's no penalty for a wrong answer, and a combo (⚡) builds as you chain correct ones. Where audio exists, tap the speaker to hear the question read aloud. | E11: Each round mixes a few question types — a colored tag shows which is which. There's no penalty for a wrong answer, and a combo (⚡) builds as you chain correct ones. Where audio exists, tap the speaker to hear the question read aloud. | I11: Moyenne | K11: lib/guideSteps.js
A12: OT-011 | B12: Visite guidée (premier lancement) | C12: STEPS[5].title | D12: Wrong answers teach you | E12: Wrong answers teach you | I12: Moyenne | K12: lib/guideSteps.js
A13: OT-012 | B13: Visite guidée (premier lancement) | C13: STEPS[5].body | D13: Miss one and you get a quick “Heads up” — the rule, plus which form you actually picked — so a wrong tap becomes a mini-lesson instead of just a red mark. Turn on Review mode in Settings to pause on each explanation. | E13: Miss one and you get a quick “Heads up” — the rule, plus which form you actually picked — so a wrong tap becomes a mini-lesson instead of just a red mark. Turn on Review mode in Settings to pause on each explanation. | I13: Moyenne | K13: lib/guideSteps.js
... A44: OT-043 | B44: Niveaux de compétence | C44: LEVEL_DESCRIPTIONS.intermediate | D44: You can hold a conversation — rounds lean toward richer grammar and phrasing. | E44: Tu peux tenir une conversation — les manches privilégient une grammaire et des tournures plus riches. | I44: Moyenne | K44: lib/skillLevels.js
A45: OT-044 | B45: Niveaux de compétence | C45: LEVEL_DESCRIPTIONS.expert | D45: You're comfortable — rounds lean toward nuance, idioms, and tricky details. | E45: Tu es à l'aise — les manches privilégient les nuances, les expressions idiomatiques et les détails délicats. | I45: Haute | J45: Formulation déjà épicène : « Tu es à l'aise — les manches privilégient les nuances, les expressions idiomatiques et les détails délicats. » Reste le sens : « à l'aise » rend-il bien l’anglais « You're comfortable » pour un niveau avancé, et « détails délicats » est-il le meilleur rendu de « tricky details » ? | K45: lib/skillLevels.js
A46: OT-045 | B46: Niveaux de compétence | C46: LEVEL_DESCRIPTIONS.native | D46: No difficulty bias — everything in the track is fair game. | E46: Aucun biais de difficulté — tout le contenu de la langue peut apparaître. | I46: Moyenne | K46: lib/skillLevels.js
A47: OT-046 | B47: Sélecteur de langue | C47: LANG_LABELS | D47: English | E47: Français | I47: Moyenne | K47: lib/LangSwitcher.js
A48: OT-047 | B48: Visite guidée (premier lancement) | C48: OVERLAY_DONE | D48: Let's go! | I48: Moyenne | K48: lib/GuideOverlay.js
A49: OT-048 | B49: Sous-titres de langue (écran d’accueil) | C49: es-latam-for-en | E49: Pour les francophones · Espagnol d'Amérique latine | I49: Moyenne | K49: lib/trackSublabels.js
A50: OT-049 | B50: Sous-titres de langue (écran d’accueil) | C50: es-spain-for-en | E50: Pour les francophones · Espagnol d'Espagne · vosotros, distinction | I50: Moyenne | K50: lib/trackSublabels.js
A51: OT-050 | B51: Sous-titres de langue (écran d’accueil) | C51: it-for-en | E51: Pour les francophones · Italien | I51: Moyenne | K51: lib/trackSublabels.js
A52: OT-051 | B52: Sous-titres de langue (écran d’accueil) | C52: pt-br-for-en | E52: Pour les francophones · Portugais brésilien | I52: Moyenne | K52: lib/trackSublabels.js
A53: OT-052 | B53: Sous-titres de langue (écran d’accueil) | C53: pt-pt-for-en | E53: Pour les francophones · Portugais européen | I53: Moyenne | K53: lib/trackSublabels.js
A54: OT-053 | B54: Sous-titres de langue (écran d’accueil) | C54: de-for-en | E54: Pour les francophones · Allemand | I54: Moyenne | K54: lib/trackSublabels.js
A55: OT-054 | B55: Sous-titres de langue (écran d’accueil) | C55: ru-for-en | E55: Pour les francophones · Russe | I55: Moyenne | K55: lib/trackSublabels.js
A56: OT-055 | B56: Sous-titres de langue (écran d’accueil) | C56: ja-for-en | E56: Pour les francophones · Japonais | I56: Moyenne | K56: lib/trackSublabels.js
A57: OT-056 | B57: Sous-titres de langue (écran d’accueil) | C57: zh-for-en | E57: Pour les francophones · Chinois mandarin | I57: Moyenne | K57: lib/trackSublabels.js
A58: OT-057 | B58: Sous-titres de langue (écran d’accueil) | C58: ko-for-en | E58: Pour les francophones · Coréen | I58: Moyenne | K58: lib/trackSublabels.js

Sheet 7-Aide-APropos
A1: ID | B1: Section | C1: Clé / emplacement | D1: Anglais (référence) | E1: Français actuel | F1: VERDICT | G1: CORRECTION PROPOSÉE | H1: NOTE / MOTIF | I1: Priorité | J1: Note de l’équipe | K1: Fichier
A2: AY-0001 | B2: Page d’aide | C2: title | D2: How SquirreLingo works | E2: Comment fonctionne SquirreLingo | I2: Moyenne | K2: lib/helpAboutContent.js
A3: AY-0002 | B3: Page d’aide | C3: crossref | D3: Looking for the bigger picture instead? See the {{about|About page}}. | E3: Tu cherches plutôt une vue d’ensemble ? Va voir la {{about|page À propos}}. | I3: Moyenne | K3: lib/helpAboutContent.js
A4: AY-0003 | B4: Page d’aide | C4: sections[0].title | D4: Finding Help and the menu | E4: Trouver l’aide et le menu | I4: Moyenne | K4: lib/helpAboutContent.js
A5: AY-0004 | B5: Page d’aide | C5: sections[0].body[0] | D5: The *?* button in the top-right corner of the home screen opens this Help page anytime — it’s right there so you never have to go hunting for it. | E5: Le bouton *?* dans le coin supérieur droit de l’écran d’accueil ouvre cette page d’aide quand tu veux — il est bien en vue, pour que tu n’aies jamais à partir à sa recherche. | I5: Moyenne | K5: lib/helpAboutContent.js
A6: AY-0005 | B6: Page d’aide | C6: sections[0].body[1] | D6: Next to it, your *profile picture* opens a slide-out menu with everything else: *What’s New* (a dot appears when there’s a release you haven’t seen yet), *How to use SquirreLingo* (the same quick animated tour you got on your first sign-in — reopen it anytime), and *About* (what the app is, how the modes work, and what’s planned next). Below a divider, the full *Settings* section sits right there too — username, email, password, native language/country, profile picture, gameplay preferences — no extra tap needed to open it. This whole menu and every Settings label appear in your native language. | E6: Juste à côté, ta *photo de profil* ouvre un menu latéral avec tout le reste : *Nouveautés* (un point apparaît quand une version que tu n’as pas encore vue est sortie), *Comment utiliser SquirreLingo* (le même petit tour animé que tu as eu à ta première connexion — rouvre-le quand tu veux) et *À propos* (ce qu’est l’appli, comment marchent les modes, et ce qui est prévu ensuite). Sous un séparateur se trouve aussi toute la section *Réglages* — nom d’utilisateur, e-mail, mot de passe, langue et pays d’origine, photo de profil, préférences de jeu — sans aucun clic supplémentaire pour l’ouvrir. Tout ce menu et chaque libellé des Réglages s’affichent dans ta langue maternelle. | I6: Moyenne | K6: lib/helpAboutContent.js
A7: AY-0006 | B7: Page d’aide | C7: sections[1].title | D7: SquirreLingo in your language | E7: SquirreLingo dans ta langue | I7: Moyenne | K7: lib/helpAboutContent.js
A8: AY-0007 | B8: Page d’aide | C8: sections[1].body[0] | D8: SquirreLingo doesn’t just teach in your language — *the app itself adapts to it*. Wherever your native language is supported, the whole interface follows it: the sign-in and sign-up screens, password recovery, the first-run onboarding, the slide-out menu and every Settings label, the beta-application form, and everything inside a round — subtitles, answer choices, explanations and the Word Bank. | E8: SquirreLingo n’enseigne pas seulement dans ta langue — *l’appli elle-même s’y adapte*. Partout où ta langue maternelle est prise en charge, toute l’interface la suit : les écrans de connexion et d’inscription, la récupération de mot de passe, la première prise en main, le menu latéral et chaque libellé des Réglages, le formulaire de candidature à la bêta, et tout ce qui se passe pendant une manche — sous-titres, options de réponse, explications et Banque de mots. | I8: Moyenne | K8: lib/helpAboutContent.js
A9: AY-0008 | B9: Page d’aide | C9: sections[1].body[1] | D9: The app *picks your language automatically* from your browser the first time you arrive, so there’s nothing to set up. Prefer a different one? A small *🌐 language pill* sits in the corner of every screen before you sign in — tap it to switch anytime, and your choice sticks. | E9: L’appli *choisit ta langue automatiquement* d’après ton navigateur la première fois que tu arrives, il n’y a donc rien à configurer. Tu en préfères une autre ? Une petite *pastille 🌐* se trouve dans le coin de chaque écran avant la connexion — touche-la pour changer quand tu veux, et ton choix est conservé. | I9: Moyenne | K9: lib/helpAboutContent.js
A10: AY-0009 | B10: Page d’aide | C10: sections[1].body[2] | D10: More interface languages are being added over time, and coverage keeps widening as native-language content fills in. | E10: D’autres langues d’interface sont ajoutées au fil du temps, et la couverture s’élargit à mesure que le contenu en langue maternelle se remplit. | I10: Moyenne | K10: lib/helpAboutContent.js
A11: AY-0010 | B11: Page d’aide | C11: sections[2].title | D11: Choosing what to learn | E11: Choisir ce que tu apprends | I11: Moyenne | K11: lib/helpAboutContent.js
A12: AY-0011 | B12: Page d’aide | C12: sections[2].body[0] | D12: Your *native language* (set in Settings) decides which languages show up as bubbles to learn — you’ll see the languages available to learn from your own, and more language pairs keep getting added over time. Each bubble’s name shows in your native language too (e.g. you’d see “German” rather than “Deutsch”) — no need to recognize a language from its flag or name in its own script. Your *native country* is separate — it just personalizes the badge in the top icon row. | E12: Ta *langue maternelle* (définie dans les Réglages) détermine quelles langues apparaissent sous forme de bulles à apprendre — tu verras les langues disponibles à partir de la tienne, et de nouvelles paires de langues s’ajoutent régulièrement. Le nom de chaque bulle s’affiche aussi dans ta langue maternelle (par exemple tu verras « Allemand » plutôt que « Deutsch ») — pas besoin de reconnaître une langue à son drapeau ou à son nom dans sa propre écriture. Ton *pays d’origine* est séparé — il ne sert qu’à personnaliser le badge dans la rangée d’icônes du haut. | I12: Moyenne | K12: lib/helpAboutContent.js
A13: AY-0012 | B13: Page d’aide | C13: sections[2].body[1] | D13: Each language bubble shows your current skill level and XP progress toward the next one. Tap any bubble to start practicing that language — progress is tracked independently per language. | E13: Chaque bulle de langue affiche ton niveau actuel et ta progression en XP vers le suivant. Touche une bulle pour commencer à t’entraîner dans cette langue — la progression est suivie séparément pour chaque langue. | I13: Moyenne | K13: lib/helpAboutContent.js
... A111: AY-0110 | B111: Page À propos | C111: footer | D111: Questions about how something specific works? The {{help|Help page}} has a full walkthrough of every screen and icon. Found a bug, or have an idea? There’s a {{feedback|feedback form}} for that too. Know someone who’d like to {{beta|apply to beta test}}? | E111: Des questions sur le fonctionnement précis de quelque chose ? La {{help|page d’Aide}} contient un guide complet de chaque écran et de chaque icône. Tu as trouvé un bug ou tu as une idée ? Il y a aussi un {{feedback|formulaire de commentaires}} pour ça. Tu connais quelqu’un qui aimerait {{beta|postuler comme bêta-testeur}} ? | I111: Moyenne | K111: lib/helpAboutContent.js

Sheet 8-Nouveautés
A1: ID | B1: Section | C1: Clé / emplacement | D1: Anglais (référence) | E1: Français actuel | F1: VERDICT | G1: CORRECTION PROPOSÉE | H1: NOTE / MOTIF | I1: Priorité | J1: Note de l’équipe | K1: Fichier
A2: NV-0001 | B2: v3.2.0 — 2026-07-27 | C2: v3.2.0 · bullet 1 | D2: Newest native language available: Portuguese. Set your native language to Portuguese and the whole app follows — the menus, Settings, sign-in and onboarding, the subtitle under each question, the answer choices, the explanations, the Word Bank and pronunciation practice, plus the Help and About pages. Portuguese speakers get 12 languages to study: Spanish (Latin America & Spain), French (France & Québec), Italian, German, Russian, Japanese, Korean and Mandarin, plus American and British English — each a full course, not a starter set. A card surfaces the Brazil↔Portugal differences (ônibus/autocarro, trem/comboio, tela/ecrã, geladeira/frigorífico) as they come up. | I2: Basse | K2: lib/version.js
A3: NV-0002 | B3: v3.2.0 — 2026-07-27 | C3: v3.2.0 · bullet 2 | D3: A new look: SquirreLingo now wears a friendly two-squirrel mascot logo — the same characters as the animated co-hosts — on the browser tab, the home-screen icon, link-share previews and inside the app itself, replacing the old pink squirrel mark. The pinks and purples across the app have been warmed to match it. | I3: Basse | K3: lib/version.js
A4: NV-0003 | B4: v3.2.0 — 2026-07-27 | C4: v3.2.0 · bullet 3 | D4: Add SquirreLingo to your home screen and it now opens as a real app — its own icon, its own name, and no browser bars around it. | I4: Basse | K4: lib/version.js
A5: NV-0004 | B5: v3.2.0 — 2026-07-27 | C5: v3.2.0 · bullet 4 | D5: Other general bug fixes and code changes. | I5: Basse | K5: lib/version.js
A6: NV-0005 | B6: v3.1.1 — 2026-07-26 | C6: v3.1.1 · bullet 1 | D6: Learning English is now a full course for Spanish speakers — the complete grammar set (hundreds of questions) plus both American and British English, so it matches every other language. | I6: Basse | K6: lib/version.js
A7: NV-0006 | B7: v3.1.1 — 2026-07-26 | C7: v3.1.1 · bullet 2 | D7: The slide-out menu and the “How to use SquirreLingo” walkthrough now appear fully in your native language — the last few labels and the walkthrough that still showed in English when set to Spanish are fixed. | I7: Basse | K7: lib/version.js
A8: NV-0007 | B8: v3.1.1 — 2026-07-26 | C8: v3.1.1 · bullet 3 | D8: The card that shows how a word changes from country to country and region to region now covers more everyday words. | I8: Basse | K8: lib/version.js
A9: NV-0008 | B9: v3.1.1 — 2026-07-26 | C9: v3.1.1 · bullet 4 | D9: Other general bug fixes and code changes. | I9: Basse | K9: lib/version.js
A10: NV-0009 | B10: v3.1.0 — 2026-07-25 | C10: v3.1.0 · bullet 1 | D10: Newest native language available: Spanish. Set your native language to Spanish and the whole app adapts to it — the menus, Settings, sign-in and onboarding, the subtitle under each question, the answer choices, the explanations and the Word Bank all appear in your native language, on every language you can study. What you're learning still leads each question, so the immersion is unchanged — your native language now rides underneath instead of English. | I10: Basse | K10: lib/version.js
A11: NV-0010 | B11: v3.1.0 — 2026-07-25 | C11: v3.1.0 · bullet 2 | D11: SquirreLingo now detects your device's language when you first arrive and switches automatically, with a language switcher in the corner to change it whenever you like. | I11: Basse | K11: lib/version.js
A12: NV-0011 | B12: v3.1.0 — 2026-07-25 | C12: v3.1.0 · bullet 3 | D12: A new card shows how a word changes from country to country and region to region — highlighting the form used where you're from, and how it's said elsewhere. | I12: Basse | K12: lib/version.js
A13: NV-0012 | B13: v3.1.0 — 2026-07-25 | C13: v3.1.0 · bullet 4 | D13: Other general bug fixes and code changes. | I13: Basse | K13: lib/version.js
... A185: NV-0184 | B185: v1.0.0 — 2026-07-05 | C185: v1.0.0 · bullet 7 | D185: "Don't repeat too soon" freshness rotation across questions | I185: Basse | K185: lib/version.js
