Workbook

Sheet LISEZ-MOI
B1: SquirreLingo — Contenu enseigné en français (Français (France))
B2: Ce fichier contient le français que l’application ENSEIGNE : les questions, les réponses, les explications et le vocabulaire du cours de français destiné aux anglophones, dans la version 3.2.0. Il est différent du paquet Interface : ici une erreur ne met pas mal à l’aise, elle enseigne faux. Tout a été rédigé par une IA et n’a jamais été relu ; vos corrections repartent directement dans le produit.
B4: Ce que nous vous demandons
B5: • La réponse marquée comme correcte est-elle correcte ?
B6: • Une des options incorrectes pourrait-elle être valable elle aussi ? Si oui, la question est cassée même si la bonne réponse est bonne. C’est la trouvaille la plus précieuse que vous puissiez faire.
B7: • L’explication en français dit-elle quelque chose de vrai et d’utile, et sonne-t-elle naturelle ?
B8: • Le niveau (A1–C2) est-il bien placé pour cette question ?
B10: Variété
B11: • Français standard de France. Le cours n’enseigne aujourd’hui AUCUNE divergence régionale comme contenu : on y trouve « week-end », « le dîner » au sens du repas du soir et « la voiture », jamais leurs équivalents québécois. Dites-nous si certaines divergences mériteraient d’être enseignées explicitement.
B12: • Les explications et les notes de la Banque de mots sont en ANGLAIS : la personne qui suit ce cours parle anglais. Vérifiez que l’information est juste, pas qu’elle est traduite. N’« améliorez » pas l’anglais non plus — ce n’est pas votre périmètre.
B14: Comment remplir le fichier
B15: 1. Traitez un onglet à la fois. L’ordre conseillé figure dans l’onglet SYNTHÈSE.
... B27: Exemple d’une ligne correctement remplie
B28: Énoncé | C28: VERDICT | D28: CORRECTION PROPOSÉE | E28: NOTE / MOTIF
B29: 'Fenêtre' signifie... | C29: CORRIGER | D29: « Fenêtre » signifie… | E29: L’énoncé emploie des apostrophes droites et trois points au lieu des guillemets français et des points de suspension. Toute la série des énoncés en « X signifie... » est dans ce cas : signalez-le UNE fois ici, nous l’appliquons à l’ensemble.
B32: Pour finir
B33: Renseignez votre nom et la date dans l’onglet SYNTHÈSE, puis renvoyez ce même fichier .xlsx.

Sheet SYNTHÈSE
B2: Bilan et signature de la relecture — Français (France) · Contenu enseigné
B3: Le français que l’application enseigne à celles et ceux qui l’apprennent
B5: Nom de la personne qui relit :
B6: Pays / région d’origine :
B7: Date de remise :
B8: Est-ce que je valide l’ensemble ?
A11: Ordre | B11: Onglet | C11: Contenu | D11: Lignes | E11: OK | F11: CORRIGER | G11: DOUTE | H11: Non relu
A12: 1 | B12: 1-Questions | C12: Chaque question entière : énoncé, bonne réponse, options incorrectes et explication. | D12: 959 | E12: =COUNTIF('1-Questions'!$L$2:$L$960,"OK") -> 0 | F12: =COUNTIF('1-Questions'!$L$2:$L$960,"CORRIGER") -> 0 | G12: =COUNTIF('1-Questions'!$L$2:$L$960,"DOUTE") -> 0 | H12: =D12-E12-F12-G12 -> 959
A13: 2 | B13: 2-Prononciation | C13: Exercices de prononciation : phrase, transcription et paires minimales. | D13: 76 | E13: =COUNTIF('2-Prononciation'!$K$2:$K$77,"OK") -> 0 | F13: =COUNTIF('2-Prononciation'!$K$2:$K$77,"CORRIGER") -> 0 | G13: =COUNTIF('2-Prononciation'!$K$2:$K$77,"DOUTE") -> 0 | H13: =D13-E13-F13-G13 -> 76
A14: 3 | B14: 3-Banque-de-mots | C14: La Banque de mots — vocabulaire à haute fréquence. | D14: 588 | E14: =COUNTIF('3-Banque-de-mots'!$H$2:$H$589,"OK") -> 0 | F14: =COUNTIF('3-Banque-de-mots'!$H$2:$H$589,"CORRIGER") -> 0 | G14: =COUNTIF('3-Banque-de-mots'!$H$2:$H$589,"DOUTE") -> 0 | H14: =D14-E14-F14-G14 -> 588
A15: 4 | B15: 4-Décisions | C15: Décisions prises à dessein, sur lesquelles nous voulons votre avis. | D15: 8 | E15: =COUNTIF('4-Décisions'!$E$2:$E$9,"VALIDÉ") -> 0 | F15: =COUNTIF('4-Décisions'!$E$2:$E$9,"CORRIGER") -> 0 | G15: =COUNTIF('4-Décisions'!$E$2:$E$9,"DOUTE") -> 0 | H15: =D15-E15-F15-G15 -> 8
C16: TOTAL | D16: =SUM(D12:D15) -> 1631 | E16: =SUM(E12:E15) -> 0 | F16: =SUM(F12:F15) -> 0 | G16: =SUM(G12:G15) -> 0 | H16: =SUM(H12:H15) -> 1631
B18: « Non relu » ne tombe à zéro que lorsque chaque ligne porte un verdict. Il n’est pas nécessaire d’arriver à zéro pour nous renvoyer le fichier : envoyez ce que vous avez et nous repartons de là.

Sheet 1-Questions
A1: ID | B1: Cours | C1: Catégorie | D1: Niveau | E1: Clé | F1: Énoncé | G1: Bonne réponse | H1: Options incorrectes | I1: Explication en français | J1: Explication en anglais (référence) | K1: Notes des options | L1: VERDICT | M1: CORRECTION PROPOSÉE | N1: NOTE / MOTIF | O1: Fichier
A2: PR-0001 | B2: frForEn | C2: vocab | D2: A1 | E2: vocab[0] | F2: 'Bonjour' signifie... | G2: hello/good day | H2: good night · goodbye · please | I2: 'Bonjour' is the standard daytime greeting, used from morning until early evening. | O2: data/tracks/frForEn.js
A3: PR-0002 | B3: frForEn | C3: vocab | D3: A1 | E3: vocab[1] | F3: 'Merci' signifie... | G3: thank you | H3: please · sorry · you're welcome | I3: 'Merci' is thank you — one of the most essential words to know. | O3: data/tracks/frForEn.js
A4: PR-0003 | B4: frForEn | C4: vocab | D4: A1 | E4: vocab[2] | F4: 'Ami/Amie' signifie... | G4: friend | H4: enemy · neighbor · teacher | I4: 'Ami' (masculine)/'amie' (feminine) means friend. | O4: data/tracks/frForEn.js
A5: PR-0004 | B5: frForEn | C5: vocab | D5: A2 | E5: vocab[3] | F5: 'Fenêtre' signifie... | G5: window | H5: door · wall · floor | I5: 'Fenêtre' means window — the circumflex (^) often marks a letter that used to be there historically (here, an 's': 'fenestre' in Old French). | O5: data/tracks/frForEn.js
A6: PR-0005 | B6: frForEn | C6: vocab | D6: A2 | E6: vocab[4] | F6: 'Famille' signifie... | G6: family | H6: friend group · neighborhood · team | I6: 'Famille' means family — pronounced "fah-MEE" (the double 'll' after 'i' sounds like a 'y', not an 'l'). | O6: data/tracks/frForEn.js
A7: PR-0006 | B7: frForEn | C7: vocab | D7: A2 | E7: vocab[5] | F7: 'Travail' signifie... | G7: work/job | H7: worker · factory · working (gerund) | I7: 'Travail' means work or job (the noun); 'travailler' is the verb "to work." | O7: data/tracks/frForEn.js
A8: PR-0007 | B8: frForEn | C8: vocab | D8: B1 | E8: vocab[6] | F8: 'Librairie' signifie... | G8: bookstore | H8: library · bookshelf · librarian | I8: Classic false friend: 'librairie' means bookstore. The place you borrow books is 'bibliothèque'. | O8: data/tracks/frForEn.js
A9: PR-0008 | B9: frForEn | C9: vocab | D9: B1 | E9: vocab[7] | F9: 'Coin' signifie... | G9: corner | H9: coin (money) · corner store · edge | I9: False friend — 'coin' means corner. A coin (money) is 'pièce' in French. | O9: data/tracks/frForEn.js
A10: PR-0009 | B10: frForEn | C10: vocab | D10: B1 | E10: vocab[8] | F10: 'Demander' signifie... | G10: to ask | H10: to demand · to require · to order | I10: False friend — 'demander' just means to ask (a question or for something), not the forceful "demand." To demand is 'exiger'. | O10: data/tracks/frForEn.js
A11: PR-0010 | B11: frForEn | C11: vocab | D11: B2 | E11: vocab[9] | F11: 'Actuellement' signifie... | G11: currently/right now | H11: actually/in fact · eventually · usually | I11: False friend — 'actuellement' means "currently," not "actually." "Actually/in fact" is 'en fait'. | O11: data/tracks/frForEn.js
A12: PR-0011 | B12: frForEn | C12: vocab | D12: B2 | E12: vocab[10] | F12: 'Assister à' signifie... | G12: to attend | H12: to assist/help · to watch on TV · to organize | I12: False friend — 'assister à' means to attend (an event). "To assist/help" is 'aider'. | O12: data/tracks/frForEn.js
A13: PR-0012 | B13: frForEn | C13: vocab | D13: B2 | E13: vocab[11] | F13: 'Sensible' signifie... | G13: sensitive | H13: sensible/reasonable · sensory · senseless | I13: False friend — 'sensible' means emotionally sensitive. "Sensible/reasonable" is 'raisonnable' in French. | O13: data/tracks/frForEn.js
... A960: PR-0959 | B960: frForEn | C960: trad | D960: C2 | E960: trad[117] | F960: Translate: 'to turn a blind eye.' | G960: fermer les yeux | H960: tourner un oeil aveugle · detourner un oeil aveugle · faire la sourde oreille | I960: To ignore a fault on purpose you 'close your eyes'; 'faire la sourde oreille' is to turn a deaf ear instead. | O960: data/tracks/frForEn.js

Sheet 2-Prononciation
A1: ID | B1: Cours | C1: Clé | D1: Niveau | E1: Phrase | F1: Prononciation écrite | G1: Bonne réponse | H1: Options incorrectes | I1: Explication en français | J1: Paires minimales | K1: VERDICT | L1: CORRECTION PROPOSÉE | M1: NOTE / MOTIF | N1: Fichier
A2: FO-001 | B2: frForEn | C2: FONO_BANK[0] | D2: B1 | E2: Nous avons deux enfants. | F2: noo-za-VOHN duh-zahn-FAHN | G2: Nous avons deux enfants. | H2: Nous avons des enfants. · Nous avions deux enfants. · Vous avez deux enfants. | N2: data/tracks/frForEn.js
A3: FO-002 | B3: frForEn | C3: FONO_BANK[1] | D3: B1 | E3: C'est un grand arbre. | F3: seh-tuhn grahn-TARbr | G3: C'est un grand arbre. | H3: C'est un grand arbre là-bas. · C'est un petit arbre. · C'est un grand arbuste. | N3: data/tracks/frForEn.js
A4: FO-003 | B4: frForEn | C4: FONO_BANK[2] | D4: A2 | E4: Le pain est bon. | F4: luh PAN eh BOHN | G4: Le pain est bon. | H4: Le pain est blanc. · Le vin est bon. · Le pain est bien. | N4: data/tracks/frForEn.js
A5: FO-004 | B5: frForEn | C5: FONO_BANK[3] | D5: B1 | E5: Il fait beaucoup de vent. | F5: eel feh boh-KOO duh VAHN | G5: Il fait beaucoup de vent. | H5: Il fait beaucoup de temps. · Il fait un peu de vent. · Il fait beaucoup de bruit. | N5: data/tracks/frForEn.js
A6: FO-005 | B6: frForEn | C6: FONO_BANK[4] | D6: A2 | E6: Je voudrais un café, s'il vous plaît. | F6: zhuh voo-DREH uhn kah-FEH, seel voo PLEH | G6: Je voudrais un café, s'il vous plaît. | H6: Je voudrais du café, s'il vous plaît. · Je voudrais un thé, s'il vous plaît. · Je voudrais un café, merci. | N6: data/tracks/frForEn.js
A7: FO-006 | B7: frForEn | C7: FONO_BANK[5] | D7: B1 | E7: Qu'est-ce que tu fais? | F7: kes-kuh tu FEH? | G7: Qu'est-ce que tu fais? | H7: Qu'est-ce que tu veux? · Qu'est-ce qui se passe? · Qu'est-ce que c'est? | N7: data/tracks/frForEn.js
A8: FO-007 | B8: frForEn | C8: FONO_BANK[6] | D8: B1 | E8: Il y a beaucoup de monde ici. | F8: eel-yah boh-KOO duh MOHND ee-see | G8: Il y a beaucoup de monde ici. | H8: Il y a beaucoup de bruit ici. · Il n'y a personne ici. · Il y a beaucoup de monde là-bas. | N8: data/tracks/frForEn.js
A9: FO-008 | B9: frForEn | C9: FONO_BANK[7] | D9: B1 | E9: Nous allons au marché demain. | F9: noo-zah-LOHN oh mar-SHEH duh-MAN | G9: Nous allons au marché demain. | H9: Nous allons au marché aujourd'hui. · Nous allons au parc demain. · Nous irons au marché demain. | N9: data/tracks/frForEn.js
A10: FO-009 | B10: frForEn | C10: FONO_BANK[8] | D10: A2 | E10: Il est huit heures. | F10: ee-leh wee-TUHR | G10: Il est huit heures. | H10: Il est huit heure. · Il est douze heures. · Il est huit ans. | N10: data/tracks/frForEn.js
A11: FO-010 | B11: frForEn | C11: FONO_BANK[9] | D11: A2 | E11: Je voudrais un peu de pain. | F11: zhuh voo-DREH uhn puh duh PAN | G11: Je voudrais un peu de pain. | H11: Je voudrais un peu de vin. · Je voudrais un peu de bain. · Je voudrais un père de pain. | N11: data/tracks/frForEn.js
A12: FO-011 | B12: frForEn | C12: FONO_BANK[10] | D12: A2 | E12: Elle est très fatiguée. | F12: eh-leh treh fah-tee-GAY | G12: Elle est très fatiguée. | H12: Il est très fatigué. · Elle est très fatiguer. · Elle est très fatiguè. | N12: data/tracks/frForEn.js
A13: FO-012 | B13: frForEn | C13: FONO_BANK[11] | D13: A2 | E13: Vous êtes américain ? | F13: voo-zeht ah-may-ree-KAN | G13: Vous êtes américain ? | H13: Vous aidez américain ? · Vous êtes à Marseille ? · Vous êtes américaine ? | N13: data/tracks/frForEn.js
... A77: FO-076 | B77: frForEn | C77: FONO_BANK[75] | D77: C1 | E77: Le serveur nous a recommande le roti. | F77: luh sehr-VUHR noo za ruh-ko-mahn-DAY luh ro-TEE | G77: Le serveur nous a recommande le roti. | H77: Le serveur nous a recommande les rotis. · Le serveur nous a recommande le radis. · Le serveur nous a recommence le roti. | N77: data/tracks/frForEn.js

Sheet 3-Banque-de-mots
A1: ID | B1: Clé | C1: Mot en français | D1: Sens en anglais | E1: Catégorie grammaticale | F1: Niveau | G1: Note pédagogique | H1: VERDICT | I1: CORRECTION PROPOSÉE | J1: NOTE / MOTIF | K1: Fichier
A2: BP-0001 | B2: [0] | C2: le temps | D2: time; weather | E2: n | F2: A1 | G2: Covers both time and weather; context decides. | K2: data/vocab/frWords.js
A3: BP-0002 | B3: [1] | C3: l'année | D3: year | E3: n | F3: A1 | G3: Feminine: l'année. | K3: data/vocab/frWords.js
A4: BP-0003 | B4: [2] | C4: la fois | D4: time (occasion) | E4: n | F4: A1 | G4: Une fois = once; des fois = sometimes. | K4: data/vocab/frWords.js
A5: BP-0004 | B5: [3] | C5: la vie | D5: life | E5: n | F5: A1 | K5: data/vocab/frWords.js
A6: BP-0005 | B6: [4] | C6: l'homme | D6: man | E6: n | F6: A1 | G6: Silent h; masculine. | K6: data/vocab/frWords.js
A7: BP-0006 | B7: [5] | C7: la femme | D7: woman; wife | E7: n | F7: A1 | G7: Also means wife; pronounced 'fam'. | K7: data/vocab/frWords.js
A8: BP-0007 | B8: [6] | C8: l'enfant | D8: child; boy | E8: n | F8: A1 | G8: Same form for a boy or a girl: un/une enfant. | K8: data/vocab/frWords.js
A9: BP-0008 | B9: [7] | C9: la main | D9: hand | E9: n | F9: A1 | K9: data/vocab/frWords.js
A10: BP-0009 | B10: [8] | C10: l'œil | D10: eye | E10: n | F10: A1 | G10: Irregular plural: les yeux. | K10: data/vocab/frWords.js
A11: BP-0010 | B11: [9] | C11: l'eau | D11: water | E11: n | F11: A1 | G11: Feminine: l'eau froide. | K11: data/vocab/frWords.js
A12: BP-0011 | B12: [10] | C12: la table | D12: table | E12: n | F12: A1 | K12: data/vocab/frWords.js
A13: BP-0012 | B13: [11] | C13: la chaise | D13: chair | E13: n | F13: A1 | K13: data/vocab/frWords.js
A14: BP-0013 | B14: [12] | C14: la porte | D14: door | E14: n | F14: A1 | K14: data/vocab/frWords.js
A15: BP-0014 | B15: [13] | C15: le livre | D15: book | E15: n | F15: A1 | K15: data/vocab/frWords.js
A16: BP-0015 | B16: [14] | C16: l'école | D16: school | E16: n | F16: A1 | G16: Feminine: l'école. | K16: data/vocab/frWords.js
A17: BP-0016 | B17: [15] | C17: la ville | D17: city | E17: n | F17: A1 | K17: data/vocab/frWords.js
A18: BP-0017 | B18: [16] | C18: le pays | D18: country (nation) | E18: n | F18: A1 | G18: Final s is silent: 'pay-ee'. | K18: data/vocab/frWords.js
A19: BP-0018 | B19: [17] | C19: le monde | D19: world | E19: n | F19: A1 | K19: data/vocab/frWords.js
A20: BP-0019 | B20: [18] | C20: la nuit | D20: night | E20: n | F20: A1 | K20: data/vocab/frWords.js
A21: BP-0020 | B21: [19] | C21: le matin | D21: morning | E21: n | F21: A1 | K21: data/vocab/frWords.js
A22: BP-0021 | B22: [20] | C22: la semaine | D22: week | E22: n | F22: A1 | K22: data/vocab/frWords.js
A23: BP-0022 | B23: [21] | C23: le mois | D23: month | E23: n | F23: A1 | K23: data/vocab/frWords.js
A24: BP-0023 | B24: [22] | C24: l'heure | D24: hour; time of day | E24: n | F24: A1 | G24: Feminine: l'heure. | K24: data/vocab/frWords.js
A25: BP-0024 | B25: [23] | C25: la minute | D25: minute | E25: n | F25: A1 | K25: data/vocab/frWords.js
A26: BP-0025 | B26: [24] | C26: le nom | D26: name | E26: n | F26: A1 | K26: data/vocab/frWords.js
A27: BP-0026 | B27: [25] | C27: le père | D27: father | E27: n | F27: A1 | G27: Les parents = parents, not just fathers. | K27: data/vocab/frWords.js
A28: BP-0027 | B28: [26] | C28: la mère | D28: mother | E28: n | F28: A1 | K28: data/vocab/frWords.js
A29: BP-0028 | B29: [27] | C29: le fils | D29: son | E29: n | F29: A1 | G29: Pronounced 'fisse'; the l is silent. | K29: data/vocab/frWords.js
A30: BP-0029 | B30: [28] | C30: la fille | D30: daughter | E30: n | F30: A1 | G30: La fille also means girl. | K30: data/vocab/frWords.js
A31: BP-0030 | B31: [29] | C31: le frère | D31: brother | E31: n | F31: A1 | K31: data/vocab/frWords.js
A32: BP-0031 | B32: [30] | C32: la sœur | D32: sister | E32: n | F32: A1 | K32: data/vocab/frWords.js
A33: BP-0032 | B33: [31] | C33: le chat | D33: cat | E33: n | F33: A1 | K33: data/vocab/frWords.js
A34: BP-0033 | B34: [32] | C34: le pain | D34: bread | E34: n | F34: A1 | K34: data/vocab/frWords.js
A35: BP-0034 | B35: [33] | C35: le lait | D35: milk | E35: n | F35: A1 | K35: data/vocab/frWords.js
A36: BP-0035 | B36: [34] | C36: le café | D36: coffee | E36: n | F36: A1 | K36: data/vocab/frWords.js
A37: BP-0036 | B37: [35] | C37: le fruit | D37: fruit | E37: n | F37: A1 | K37: data/vocab/frWords.js
A38: BP-0037 | B38: [36] | C38: la viande | D38: meat | E38: n | F38: A1 | K38: data/vocab/frWords.js
A39: BP-0038 | B39: [37] | C39: le poisson | D39: fish (as food) | E39: n | F39: A1 | G39: Same word for the live fish and the food. | K39: data/vocab/frWords.js
A40: BP-0039 | B40: [38] | C40: l'œuf | D40: egg | E40: n | F40: A1 | G40: Plural 'les œufs' drops the f sound. | K40: data/vocab/frWords.js
...

Sheet 4-Décisions
A1: ID | B1: Sujet | C1: Ce que nous avons décidé et pourquoi | D1: Exemple / où | E1: DÉCISION | F1: AUTRE PROPOSITION | G1: NOTE
A2: DEC-01 | B2: Ce que nous vous demandons ici | C2: Ce paquet ne porte pas sur la façon dont l’application se lit. Il porte sur le français qu’elle ENSEIGNE à des anglophones en train de l’apprendre. Une erreur ici ne met pas mal à l’aise : elle enseigne faux. | D2: data/tracks/frForEn.js — 959 questions et 76 items de prononciation · data/vocab/frWords.js — 588 entrées de Banque de mots
A3: DEC-02 | B3: Les options incorrectes comptent autant que la bonne | C3: Chaque question a une bonne réponse et trois mauvaises. Si l’une des « mauvaises » est en fait défendable, la question est cassée même si la réponse marquée est bonne. C’est la trouvaille la plus précieuse que vous puissiez faire. | D3: « 'Fenêtre' signifie... » → window / door / wall / floor (data/tracks/frForEn.js)
A4: DEC-03 | B4: Variété | C4: Le cours enseigne le français standard de France. À ce jour il ne présente aucune variante québécoise : « courriel » par exemple n’apparaît nulle part. Faut-il enseigner certaines divergences comme contenu, ou laisser la carte des variantes s’en charger ? | D4: « week-end » · « le dîner » (repas du soir) · « la voiture » — formes de France
A5: DEC-04 | B5: Explications en anglais (problème connu) | C5: La colonne « Explication en français » affiche de l’anglais sur les 959 questions, parce que data/tracks/frForEn.js ne contient aucune explication française : la piste est destinée à des anglophones et l’extracteur retombe sur l’anglais. Inutile de le marquer ligne par ligne. Dites-nous en revanche si l’anglais affirme quelque chose de FAUX sur le français. | D5: Colonne « Explication en français » — 959 lignes
A6: DEC-05 | B6: Prononciation : deux colonnes vides (problème connu) | C6: Les 76 lignes de l’onglet 2-Prononciation ont une colonne « Explication en français » vide et une colonne « Paires minimales » vide : ces champs n’existent pas encore dans le fichier source. Jugez la phrase, sa transcription et les options. | D6: Onglet 2-Prononciation — 76 lignes
A7: DEC-06 | B7: Niveau CECR | C7: Chaque question porte un niveau (A1–C2). Si l’un vous semble mal placé, dites-le : cela change à qui la question est montrée. | D7: Colonne « Niveau »
A8: DEC-07 | B8: Notes pédagogiques de la Banque de mots | C8: Les 588 notes de la Banque de mots sont en anglais à dessein, puisque le cours s’adresse à des anglophones. Vérifiez que l’information sur le français est juste — genre, prononciation, pluriel irrégulier — pas la langue de la note. | D8: « le musée » → « Masculine despite the -ée: le musée. » (data/vocab/frWords.js)
A9: DEC-08 | B9: Prononciation écrite | C9: La prononciation est écrite en transcription lisible pour un anglophone, pas en API. Vérifiez qu’elle se lit bien. Notez au passage que ces phrases ne portent pas l’espace insécable devant le point d’interrogation, contrairement à l’interface : faut-il l’ajouter ici aussi ? | D9: « Qu'est-ce que tu fais? » → « kes-kuh tu FEH? »
