Workbook

Sheet LISEZ-MOI
B1: SquirreLingo — Explications en français (Français (France))
B2: Dans ce fichier, le français n’est pas ce qui est enseigné : c’est la voix qui EXPLIQUE une autre langue. Il s’agit des cours d’anglais pour francophones, des gloses françaises de la Banque de mots des autres langues, et d’un échantillon de la couche française qui accompagne chaque cours. Version 3.3.0. Tout est rédigé par une IA et jamais relu ; vos corrections repartent directement dans le produit.
B4: Ce que nous vous demandons
B5: • L’explication en français est-elle exacte à propos de la langue qu’elle décrit ?
B6: • Sonne-t-elle naturelle, ou sent-elle la traduction de l’anglais ?
B7: • Dans les gloses de la Banque de mots : est-ce le meilleur mot français pour ce sens ?
B8: • Une explication peut être dans un français impeccable et dire malgré tout quelque chose de faux sur l’anglais. Si vous voyez une erreur de contenu, dites-le : elle nous sert autant que l’erreur de langue.
B10: Si vous ne maîtrisez pas la langue du cours
B11: • Inutile de savoir le japonais ou le russe. La colonne de référence en anglais vous dit ce que le mot devrait signifier ; à vous de juger si la glose française le dit bien. N’« améliorez » pas la langue enseignée elle-même : elle a son propre relecteur natif. Si le contexte ne vous suffit pas, mettez DOUTE et nous prenons le relais.
B13: Comment remplir le fichier
B14: 1. Traitez un onglet à la fois. L’ordre conseillé figure dans l’onglet SYNTHÈSE.
B15: 2. Chaque ligne porte une colonne VERDICT avec une liste déroulante. Choisissez une valeur :
... B22: Exemple d’une ligne correctement remplie
B23: Énoncé en français | C23: VERDICT | D23: CORRECTION PROPOSÉE | E23: NOTE / MOTIF
B24: « Die Zeit » signifie… | C24: CORRIGER | D24: remplacer l’option « moment » par un intrus sans rapport | E24: « moment » et « heure » sont eux aussi des traductions défendables de Zeit selon le contexte : deux mauvaises réponses acceptables cassent la question, même si « temps » reste la meilleure. Un intrus franchement faux contraste mieux.
B27: Ce que nous savons déjà, et l’onglet d’échantillon
B28: • Trois choses avant de commencer. (1) L’onglet 3-Banque-de-mots est VIDE : il n’existe pas de fichiers data/vocab/*.fr.js ; les gloses françaises ont été écrites directement dans les tables data/tracks/l10n/*.fr.js, et elles ne sont donc couvertes que par l’échantillon. (2) L’onglet 4-Échantillon-explications contient 400 lignes tirées de 13 554 entrées : il sert à repérer les motifs qui se répètent, pas à tout relire. Si vous voyez un motif, signalez-le UNE fois dans la note et nous le corrigeons sur tout le corpus. (3) Sur l’onglet 2-Prononciation, la colonne « Paires minimales » est vide sur les 156 lignes — ces données n’existent pas encore. Rien de tout cela n’est à nous signaler.
B30: Pour finir
B31: Renseignez votre nom et la date dans l’onglet SYNTHÈSE, puis renvoyez ce même fichier .xlsx.

Sheet SYNTHÈSE
B2: Bilan et signature de la relecture — Français (France) · Explications en français
B3: Le français qui explique D’AUTRES langues
B5: Nom de la personne qui relit :
B6: Pays / région d’origine :
B7: Date de remise :
B8: Est-ce que je valide l’ensemble ?
A11: Ordre | B11: Onglet | C11: Contenu | D11: Lignes | E11: OK | F11: CORRIGER | G11: DOUTE | H11: Non relu
A12: 1 | B12: 1-Questions | C12: Chaque question entière : énoncé, bonne réponse, options incorrectes et explication. | D12: 1548 | E12: =COUNTIF('1-Questions'!$L$2:$L$1549,"OK") | F12: =COUNTIF('1-Questions'!$L$2:$L$1549,"CORRIGER") | G12: =COUNTIF('1-Questions'!$L$2:$L$1549,"DOUTE") | H12: =D12-E12-F12-G12
A13: 2 | B13: 2-Prononciation | C13: Exercices de prononciation : phrase, transcription et paires minimales. | D13: 156 | E13: =COUNTIF('2-Prononciation'!$K$2:$K$157,"OK") | F13: =COUNTIF('2-Prononciation'!$K$2:$K$157,"CORRIGER") | G13: =COUNTIF('2-Prononciation'!$K$2:$K$157,"DOUTE") | H13: =D13-E13-F13-G13
A14: 3 | B14: 3-Banque-de-mots | C14: La Banque de mots — vocabulaire à haute fréquence. | D14: 0 | E14: 0 | F14: 0 | G14: 0
A15: 4 | B15: 4-Échantillon-explications | C15: Échantillon de la couche française posée sur les cours des autres langues (400 lignes sur 13 554). | D15: 400 | E15: =COUNTIF('4-Échantillon-explications'!$G$2:$G$401,"OK") | F15: =COUNTIF('4-Échantillon-explications'!$G$2:$G$401,"CORRIGER") | G15: =COUNTIF('4-Échantillon-explications'!$G$2:$G$401,"DOUTE") | H15: =D15-E15-F15-G15
A16: 5 | B16: 5-Décisions | C16: Décisions prises à dessein, sur lesquelles nous voulons votre avis. | D16: 6 | E16: =COUNTIF('5-Décisions'!$E$2:$E$7,"VALIDÉ") | F16: =COUNTIF('5-Décisions'!$E$2:$E$7,"CORRIGER") | G16: =COUNTIF('5-Décisions'!$E$2:$E$7,"DOUTE") | H16: =D16-E16-F16-G16
C17: TOTAL | D17: =SUM(D12:D16) | E17: =SUM(E12:E16) | F17: =SUM(F12:F16) | G17: =SUM(G12:G16) | H17: =SUM(H12:H16)
B19: « Non relu » ne tombe à zéro que lorsque chaque ligne porte un verdict. Il n’est pas nécessaire d’arriver à zéro pour nous renvoyer le fichier : envoyez ce que vous avez et nous repartons de là.

Sheet 1-Questions
A1: ID | B1: Cours | C1: Catégorie | D1: Niveau | E1: Clé | F1: Énoncé | G1: Bonne réponse | H1: Options incorrectes | I1: Explication en français | J1: Explication en anglais (référence) | K1: Notes des options | L1: VERDICT | M1: CORRECTION PROPOSÉE | N1: NOTE / MOTIF | O1: Fichier
A2: PR-0001 | B2: enUsForFr | C2: vocab | D2: A2 | E2: vocab[0] | F2: « Boring » se traduit par… | G2: ennuyeux (qui provoque l’ennui) | H2: ennuyé (qui ressent l’ennui) · agaçant · accablant | I2: « Boring » décrit ce qui PROVOQUE l’ennui (un film boring). « Bored » décrit la personne qui le RESSENT. | J2: 'Boring' describes something that CAUSES boredom (a boring movie). 'Bored' describes the person who FEELS it. | O2: data/tracks/enUsForFr.js
A3: PR-0002 | B3: enUsForFr | C3: vocab | D3: A2 | E3: vocab[1] | F3: « I am bored » signifie… | G3: je m’ennuie (je le ressens) | H3: je suis ennuyeux (j’ennuie les autres) · je suis agaçant · je suis en train d’ennuyer | I3: « Bored » (-ed), c’est ce que tu RESSENS. Utilise-le pour toi : « I am bored ». Ne confonds pas avec « boring » (-ing). | J3: 'Bored' (-ed) is how you FEEL. Use it for yourself: 'I am bored.' Don't confuse with 'boring' (-ing). | O3: data/tracks/enUsForFr.js
A4: PR-0003 | B4: enUsForFr | C4: vocab | D4: A2 | E4: vocab[2] | F4: « Fun » (comme dans « The party was fun ») se traduit par… | G4: amusant (agréable) | H4: drôle · bizarre · ennuyeux | I4: « Fun » = amusant, un bon moment. « Funny » = qui fait rire. Une fête est « fun », pas « funny ». | J4: 'Fun' = enjoyable, a good time. 'Funny' = causing laughter. A party is fun, not funny. | O4: data/tracks/enUsForFr.js
A5: PR-0004 | B5: enUsForFr | C5: vocab | D5: A2 | E5: vocab[3] | F5: « Funny » se traduit par… | G5: drôle (qui fait rire) | H5: amusant (qui distrait) · seulement bizarre · ennuyeux | I5: « Funny » te fait rire (une blague funny). Ça peut aussi vouloir dire « bizarre », mais jamais « amusant » — ça, c’est « fun ». | J5: 'Funny' makes you laugh (a funny joke). It can also mean 'strange', but never 'entertaining' — that's 'fun'. | O5: data/tracks/enUsForFr.js
A6: PR-0005 | B6: enUsForFr | C6: vocab | D6: A2 | E6: vocab[4] | F6: « You did a good job » — le mot « good » est un… | G6: adjectif (il décrit un nom) | H6: adverbe (il décrit un verbe) · verbe · préposition | I6: « Good » est un adjectif ; il décrit des noms (a good job). Pour dire COMMENT tu fais quelque chose, utilise l’adverbe « well ». | J6: 'Good' is an adjective; it describes nouns (a good job). To describe how you DO something, use the adverb 'well'. | O6: data/tracks/enUsForFr.js
A7: PR-0006 | B7: enUsForFr | C7: vocab | D7: A2 | E7: vocab[5] | F7: « Elle chante bien » se traduit par « She sings… » | G7: well | H7: good · goodly · nicely good | I7: Utilise l’adverbe « well » pour décrire une action : « She sings well ». « She sings good » est une erreur fréquente. | J7: Use the adverb 'well' to describe an action: 'She sings well.' 'She sings good' is a common error. | O7: data/tracks/enUsForFr.js
A8: PR-0007 | B8: enUsForFr | C8: vocab | D8: B1 | E8: vocab[6] | F8: Dans « Comment ça va ? » → « I'm well », le mot « well » signifie ici… | G8: bien (en bonne santé) | H8: le puits d’eau · bon (gentil) · beaucoup | I8: Après « to be » quand on parle de santé, « well » veut dire en bonne santé. « I'm good » est aussi accepté en anglais américain familier. | J8: After 'to be' about health, 'well' means in good health. 'I'm good' is also accepted in casual American English. | O8: data/tracks/enUsForFr.js
A9: PR-0008 | B9: enUsForFr | C9: vocab | D9: A2 | E9: vocab[7] | F9: « This test is hard » — ici, « hard » signifie… | G9: difficile | H9: à peine (presque pas) · presque · doux | I9: Comme adjectif, « hard » signifie difficile (ou dur, ferme). Ne le confonds pas avec l’adverbe « hardly ». | J9: As an adjective, 'hard' means difficult (or firm). Don't confuse it with the adverb 'hardly'. | O9: data/tracks/enUsForFr.js
A10: PR-0009 | B10: enUsForFr | C10: vocab | D10: B1 | E10: vocab[8] | F10: « He works hard » signifie… | G10: il travaille dur (avec effort) | H10: il ne travaille presque pas · il travaille difficilement · il travaille à peine | I10: « Hard » est aussi un adverbe et signifie « avec beaucoup d’effort ». « He works hard » = il travaille beaucoup. | J10: 'Hard' is also an adverb meaning 'with a lot of effort'. 'He works hard' = trabaja mucho. | O10: data/tracks/enUsForFr.js
A11: PR-0010 | B11: enUsForFr | C11: vocab | D11: B1 | E11: vocab[9] | F11: « She hardly works » signifie… | G11: elle ne travaille presque pas | H11: elle travaille dur · elle travaille difficilement · elle travaille beaucoup | I11: Piège ! « Hardly » signifie « presque pas / à peine », pas « dur ». « She hardly works » = elle ne travaille presque pas. | J11: Trap! 'Hardly' means 'almost not / barely', not 'hard'. 'She hardly works' = casi no trabaja. | O11: data/tracks/enUsForFr.js
A12: PR-0011 | B12: enUsForFr | C12: vocab | D12: A2 | E12: vocab[10] | F12: « The store is near » — ici, « near » signifie… | G12: près | H12: presque · loin · proche dans le temps | I12: « Near » veut dire près en distance. Ne le confonds pas avec « nearly » = presque. | J12: 'Near' means close in distance (cerca). Don't confuse it with 'nearly' = casi. | O12: data/tracks/enUsForFr.js
A13: PR-0012 | B13: enUsForFr | C13: vocab | D13: B1 | E13: vocab[11] | F13: « I nearly fell » signifie… | G13: j’ai failli tomber | H13: je suis tombé tout près · je suis vraiment tombé · je tombe souvent | I13: « Nearly » signifie « presque ». « I nearly fell » = j’ai failli tomber, mais je ne suis pas tombé. Ce n’est pas la même chose que « near ». | J13: 'Nearly' means 'almost' (casi). 'I nearly fell' = casi me caigo, but I didn't. Not the same as 'near'. | O13: data/tracks/enUsForFr.js
... A1549: PR-1548 | B1549: enGbForFr | C1549: trad | D1549: C1 | E1549: trad[121] | F1549: Traduire : « Bon, je ne vais pas te retenir plus longtemps. » (pour clore une conversation) | G1549: Right, I'll let you get on. | H1549: Well, I don't entertain you more. · Good, I won't detain you further, then. · So, I stop bothering you now, ok. | I1549: « I'll let you get on » signale poliment que tu mets fin à la conversation pour que l’autre puisse continuer ce qu’elle faisait. | J1549: 'I'll let you get on' politely signals you're ending the conversation so they can carry on. | O1549: data/tracks/enGbForFr.js

Sheet 2-Prononciation
A1: ID | B1: Cours | C1: Clé | D1: Niveau | E1: Phrase | F1: Prononciation écrite | G1: Bonne réponse | H1: Options incorrectes | I1: Explication en français | J1: Paires minimales | K1: VERDICT | L1: CORRECTION PROPOSÉE | M1: NOTE / MOTIF | N1: Fichier
A2: FO-001 | B2: enUsForFr | C2: FONO_BANK[0] | D2: A1 | E2: I need a glass of water. | F2: eye NEED-uh GLASS-uh WAH-der | G2: I need a glass of water. | H2: I need a glass of wonder. · I need a class of water. · I need a glass of water? | I2: En anglais américain, le T entre voyelles dans « water » s’adoucit en un bref battement proche du D, d’où le son « WAH-der ». | N2: data/tracks/enUsForFr.js
A3: FO-002 | B3: enUsForFr | C3: FONO_BANK[1] | D3: A2 | E3: This one is better than that one. | F3: this WUN-iz BED-er than THAT-wun | G3: This one is better than that one. | H3: This one is bedder than that one. · This one is butter than that one. · This one is better than that phone. | I3: Le double T de « better » devient un D battu, d’où la prononciation « BED-er ». | N3: data/tracks/enUsForFr.js
A4: FO-003 | B4: enUsForFr | C4: FONO_BANK[2] | D4: A2 | E4: What are you doing later? | F4: wuh-duh-yuh DOO-in LAY-der | G4: What are you doing later? | H4: What are you doing lately? · Water you doing later? · What do you do later? | I4: « What are you » se fond en « wuh-duh-yuh » avec des T battus, et « later » devient « LAY-der ». | N4: data/tracks/enUsForFr.js
A5: FO-004 | B5: enUsForFr | C5: FONO_BANK[3] | D5: B1 | E5: Let it go, it doesn't matter. | F5: LEH-diht GOH it DUZ-unt MAD-er | G5: Let it go, it doesn't matter. | H5: Let it go, it doesn't madder. · Led it go, it doesn't matter. · Let it go, it doesn't matter? | I5: « Let it » devient « LEH-diht » et « matter » devient « MAD-er », parce que les T se retrouvent entre voyelles. | N5: data/tracks/enUsForFr.js
A6: FO-005 | B6: enUsForFr | C6: FONO_BANK[4] | D6: B1 | E6: I got a lot of it done. | F6: eye GAH-duh LAH-duv it DUN | G6: I got a lot of it done. | H6: I got a lot of it dumb. · I gotta lot of it done. · I got a lodda it done. | I6: « Got a » et « lot of » deviennent « GAH-duh » et « LAH-duv », enchaînant les mots entre eux. | N6: data/tracks/enUsForFr.js
A7: FO-006 | B7: enUsForFr | C7: FONO_BANK[5] | D7: B1 | E7: Turn it off and on again. | F7: TUR-nih-DAWF and AWN uh-GEN | G7: Turn it off and on again. | H7: Turn it off in an engine. · Turn it off and on a gun. · Turn it up and on again. | I7: « Turn it off » s’enchaîne en « TUR-nih-DAWF » quand les consonnes finales se lient aux voyelles suivantes. | N7: data/tracks/enUsForFr.js
A8: FO-007 | B8: enUsForFr | C8: FONO_BANK[6] | D8: B1 | E8: Can I get a little bit of butter? | F8: kn-eye GEH-duh LIH-dul BIH-duv BUH-der | G8: Can I get a little bit of butter? | H8: Can I get a little bit of batter? · Can I get a little bit of bother? · Can I get a little bit of water? | I8: « Little », « bit of » et « butter » transforment tous leurs T en sons proches du D entre voyelles. | N8: data/tracks/enUsForFr.js
A9: FO-008 | B9: enUsForFr | C9: FONO_BANK[7] | D9: A2 | E9: Put it on the table. | F9: PUH-dih-DAWN thuh TAY-bul | G9: Put it on the table. | H9: Put it on the stable. · Put it on the cable. · Put it in the table. | I9: « Put it on » se lie et devient « PUH-dih-DAWN », les T se changeant en brefs battements de D. | N9: data/tracks/enUsForFr.js
A10: FO-009 | B10: enUsForFr | C10: FONO_BANK[8] | D10: B2 | E10: He's coming out of it slowly. | F10: heez KUH-min OW-duv it SLOH-lee | G10: He's coming out of it slowly. | H10: He's coming out of its holy. · He's coming out of a slowly. · He's coming out of it slower. | I10: « Out of it » se lie en « OW-duv it », le T battu reliant les mots. | N10: data/tracks/enUsForFr.js
A11: FO-010 | B11: enUsForFr | C11: FONO_BANK[9] | D11: B1 | E11: That's a lot better already. | F11: thats-uh LAH BED-er awl-REH-dee | G11: That's a lot better already. | H11: That's a lot bedder already. · That's a lot better all ready. · That's a lot batter already. | I11: « Lot better » devient « LAH BED-er », le T final de « lot » s’adoucissant devant le mot suivant. | N11: data/tracks/enUsForFr.js
A12: FO-011 | B12: enUsForFr | C12: FONO_BANK[10] | D12: B1 | E12: I'll pick it up in a minute. | F12: aisl PIH-kih-DUP in-uh MIH-nut | G12: I'll pick it up in a minute. | H12: I'll pick it up in a minit. · I'll pick a cup in a minute. · I'll pick it up in a bit. | I12: « Pick it up » se lie en « PIH-kih-DUP » quand chaque consonne finale rejoint la voyelle suivante. | N12: data/tracks/enUsForFr.js
A13: FO-012 | B13: enUsForFr | C13: FONO_BANK[11] | D13: B1 | E13: What time did you get in? | F13: wuh-TYME did-juh geh-DIN | G13: What time did you get in? | H13: What time did you get him? · What time do you get in? · What time did you begin? | I13: « Get in » se lie et devient « geh-DIN », unissant les mots avec un D doux. | N13: data/tracks/enUsForFr.js
... A157: FO-156 | B157: enGbForFr | C157: FONO_BANK[78] | D157: C2 | E157: The banana is over ripe. | F157: thuh buh-NAH-nuh-riz OH-vuh RYP | G157: The banana is over ripe. | H157: The banana rise over ripe. · The banana is over right. · The banana is over wiped. | I157: Un R intrusif relie « banana » et « is » en « buh-NAH-nuh-riz », tandis que « over » perd son propre R. | N157: data/tracks/enGbForFr.js

Sheet 3-Banque-de-mots
A1: ID | B1: Clé | C1: Mot du cours | D1: Sens en anglais (référence) | E1: Glose en français | F1: Niveau | G1: VERDICT | H1: GLOSE CORRIGÉE | I1: NOTE / MOTIF | J1: Fichier

Sheet 4-Échantillon-explications
A1: ID | B1: Langue du cours | C1: Clé | D1: Énoncé en français | E1: Options de réponse | F1: Notes d’explication | G1: VERDICT | H1: CORRECTION PROPOSÉE | I1: NOTE / MOTIF | J1: Fichier
A2: MC-0001 | B2: deForEn | C2: fvocab-31 | D2: Comment dit-on « rue » en allemand ? | J2: data/tracks/l10n/deForEn.fr.js
A3: MC-0002 | B3: deForEn | C3: fvocab-95 | D3: Comment dit-on « livre » en allemand ? | J3: data/tracks/l10n/deForEn.fr.js
A4: MC-0003 | B4: deForEn | C4: fvocab-159 | D4: Comment dit-on « correct » en allemand ? | J4: data/tracks/l10n/deForEn.fr.js
A5: MC-0004 | B5: deForEn | C5: fvocab-222 | D5: « das Ziel » signifie… | E5: but ; destination · aide · message ; nouvelle · permis de conduire | J5: data/tracks/l10n/deForEn.fr.js
A6: MC-0005 | B6: deForEn | C6: fvocab-286 | D6: « laut » signifie… | E6: bruyant · lourd ; difficile · important · intéressant | J6: data/tracks/l10n/deForEn.fr.js
A7: MC-0006 | B7: deForEn | C7: fvocab-350 | D7: « der Vorteil » signifie… | E7: avantage · ordre ; rangement · mariage · espoir | J7: data/tracks/l10n/deForEn.fr.js
A8: MC-0007 | B8: deForEn | C8: fvocab-414 | D8: « gelingen » signifie… | E8: réussir · avoir lieu · atteindre ; obtenir · améliorer | J8: data/tracks/l10n/deForEn.fr.js
A9: MC-0008 | B9: deForEn | C9: fvocab-477 | D9: Comment dit-on « simplement ; eh bien » en allemand ? | J9: data/tracks/l10n/deForEn.fr.js
A10: MC-0009 | B10: deForEn | C10: fvocab-541 | D10: Comment dit-on « s’avérer » en allemand ? | J10: data/tracks/l10n/deForEn.fr.js
A11: MC-0010 | B11: deForEn | C11: fvocab-605 | D11: Comment dit-on « personne de contact » en allemand ? | J11: data/tracks/l10n/deForEn.fr.js
A12: MC-0011 | B12: deForEn | C12: gram-24 | D12: ___ enfants jouent dans le jardin. | J12: data/tracks/l10n/deForEn.fr.js
A13: MC-0012 | B13: deForEn | C13: gram-74 | D13: Il travaille _____ gagner de l’argent. (« pour ») | J13: data/tracks/l10n/deForEn.fr.js
A14: MC-0013 | B14: deForEn | C14: gram-123 | D14: J’ai encore beaucoup à apprendre. (modal + infinitif) | J14: data/tracks/l10n/deForEn.fr.js
A15: MC-0014 | B15: deForEn | C15: gram-172 | D15: J’ai un ami. (objet à l’accusatif) | J15: data/tracks/l10n/deForEn.fr.js
A16: MC-0015 | B16: deForEn | C16: gram-222 | D16: L’eau fraîche a bon goût. | J16: data/tracks/l10n/deForEn.fr.js
A17: MC-0016 | B17: deForEn | C17: gram-271 | D17: ___ (entendre) | J17: data/tracks/l10n/deForEn.fr.js
A18: MC-0017 | B18: deForEn | C18: gram-321 | D18: J’ai ___ (parler). | J18: data/tracks/l10n/deForEn.fr.js
A19: MC-0018 | B19: deForEn | C19: gram-370 | D19: Hier, il ___ (lire). | J19: data/tracks/l10n/deForEn.fr.js
A20: MC-0019 | B20: deForEn | C20: gram-419 | D20: Je vais à l’école. (mouvement) | J20: data/tracks/l10n/deForEn.fr.js
... A31: MC-0030 | B31: deForEn | C31: trad-128 | D31: Traduire : « La nécessité est mère d’invention. » | J31: data/tracks/l10n/deForEn.fr.js
A32: MC-0031 | B32: deForEn | C32: vocab-6 | D32: « Gift » signifie… | E32: poison · un cadeau · talent · médicament | J32: data/tracks/l10n/deForEn.fr.js
A33: MC-0032 | B33: deForEn | C33: vocab-20 | D33: « Der Feierabend » signifie… | E33: la fin de la journée de travail · une soirée de fête · une fête · le vendredi soir | J33: data/tracks/l10n/deForEn.fr.js
A34: MC-0033 | B34: deForEn | C34: vocab-33 | D34: « Die Stadt » signifie… | E34: ville · village · pays · place | J34: data/tracks/l10n/deForEn.fr.js
A35: MC-0034 | B35: deForEn | C35: vocab-46 | D35: « Der Ausweis » signifie… | E35: pièce d’identité · seulement un passeport · un billet · un reçu | J35: data/tracks/l10n/deForEn.fr.js
A36: MC-0035 | B36: deForEn | C36: vocab-60 | D36: « Die Panne » signifie… | E36: une panne ou un incident · une roue de secours · un embouteillage · une réparation | J36: data/tracks/l10n/deForEn.fr.js
A37: MC-0036 | B37: deForEn | C37: vocab-73 | D37: « die Brücke » signifie… | E37: pont · tour · tunnel · mur | J37: data/tracks/l10n/deForEn.fr.js
A38: MC-0037 | B38: deForEn | C38: vocab-87 | D38: « der Regen » signifie… | E38: pluie · neige · vent · tonnerre | J38: data/tracks/l10n/deForEn.fr.js
A39: MC-0038 | B39: deForEn | C39: vocab-100 | D39: « die Umfrage » signifie… | E39: sondage · rumeur · réponse · plainte | J39: data/tracks/l10n/deForEn.fr.js
A40: MC-0039 | B40: deForEn | C40: vocab-113 | D40: « der Anspruch » signifie… | E40: droit (à quelque chose) · excuse · accord · refus | J40: data/tracks/l10n/deForEn.fr.js
A41: MC-0040 | B41: deForEn | C41: vocab-127 | D41: « die Zwangslage » signifie… | E41: situation difficile/impasse · occasion · célébration · accord | J41: data/tracks/l10n/deForEn.fr.js
A42: MC-0041 | B42: esForEn | C42: fvocab-30 | D42: « La hija » signifie… | E42: fille · fleur · vie · riz | J42: data/tracks/l10n/esForEn.fr.js
A43: MC-0042 | B43: esForEn | C43: fvocab-91 | D43: Comment dit-on « sortir » en espagnol ? | J43: data/tracks/l10n/esForEn.fr.js
A44: MC-0043 | B44: esForEn | C44: fvocab-152 | D44: « Antes » signifie… | E44: avant (dans le temps) · aussi · tôt · près | J44: data/tracks/l10n/esForEn.fr.js
A45: MC-0044 | B45: esForEn | C45: fvocab-213 | D45: Comment dit-on « glace (dessert) » en espagnol ? | J45: data/tracks/l10n/esForEn.fr.js
A46: MC-0045 | B46: esForEn | C46: fvocab-274 | D46: « Fuerte » signifie… | E46: fort · sucré · ouvert · fatigué | J46: data/tracks/l10n/esForEn.fr.js
A47: MC-0046 | B47: esForEn | C47: fvocab-334 | D47: « La edad » signifie… | E47: âge · mariage · histoire · bureau | J47: data/tracks/l10n/esForEn.fr.js
A48: MC-0047 | B48: esForEn | C48: fvocab-395 | D48: Comment dit-on « remercier » en espagnol ? | J48: data/tracks/l10n/esForEn.fr.js
A49: MC-0048 | B49: esForEn | C49: fvocab-456 | D49: « El desafío » signifie… | E49: défi · ressource · demande (requête) · outil | J49: data/tracks/l10n/esForEn.fr.js
A50: MC-0049 | B50: esForEn | C50: fvocab-517 | D50: Comment dit-on « entreprendre » en espagnol ? | J50: data/tracks/l10n/esForEn.fr.js
...

Sheet 5-Décisions
A1: ID | B1: Sujet | C1: Ce que nous avons décidé et pourquoi | D1: Exemple / où | E1: DÉCISION | F1: AUTRE PROPOSITION | G1: NOTE
A2: DEC-01 | B2: Ce que nous vous demandons ici | C2: Ici le français n’est pas ce qui est enseigné : c’est la voix qui EXPLIQUE une autre langue. Ce que vous relisez, c’est si l’explication française est exacte et naturelle. | D2: data/tracks/enUsForFr.js + enGbForFr.js — 1 548 questions et 156 items de prononciation · échantillon de 400 lignes des tables data/tracks/l10n/*.fr.js
A3: DEC-02 | B3: Nous avons besoin des deux | C3: Une explication peut être dans un français impeccable et rester fausse sur l’anglais ou l’allemand. Si vous repérez une erreur de contenu, dites-le : elle vaut autant que l’erreur de langue. | D3: « Boring » se traduit par… → « ennuyeux (qui provoque l’ennui) » contre « ennuyé (qui ressent l’ennui) » (data/tracks/enUsForFr.js)
A4: DEC-03 | B4: Gloses de la Banque de mots : onglet vide | C4: L’onglet 3-Banque-de-mots est vide pour cette voie, et ce n’est pas une erreur d’extraction : les gloses françaises n’ont pas de fichier à elles, elles vivent à l’intérieur des tables l10n et n’apparaissent donc que dans l’échantillon. Quand vous en croisez une, la question reste la même : est-ce le meilleur mot français pour ce sens, et les options incorrectes sont-elles vraiment incorrectes ? | D4: « Die Zeit » signifie… → temps / heure / horloge / moment (data/tracks/l10n/deForEn.fr.js)
A5: DEC-04 | B5: Registre | C5: Tutoiement, comme dans le reste de l’application. La question est tranchée — arbitrage du propriétaire du produit, 29 juillet 2026 — et elle est CLOSE : ne rouvrez pas « tu » contre « vous ». Signalez seulement les tournures au « tu » qui sonnent forcées. Une phrase d’exercice dont le sujet est un véritable pluriel emploie « vous » : c’est du nombre grammatical, pas du registre. | D5: Comment dit-on « année » en allemand ? (data/tracks/l10n/deForEn.fr.js)
A6: DEC-05 | B6: Échantillon, pas relecture exhaustive | C6: L’onglet 4-Échantillon-explications contient 400 lignes tirées des 13 554 entrées des dix tables l10n — environ trois pour cent. Nous cherchons les problèmes qui se répètent. Si vous voyez un motif, signalez-le UNE fois et nous le corrigeons sur tout le corpus. | D6: Onglet 4-Échantillon-explications — 400 lignes sur 13 554
A7: DEC-06 | B7: Langues que vous ne maîtrisez peut-être pas | C7: Inutile de savoir le japonais ou le russe pour relire le français : la référence en anglais vous dit ce que l’énoncé devrait signifier. N’« améliorez » pas la langue enseignée elle-même, elle a son propre relecteur. Si le contexte ne vous suffit pas, mettez DOUTE et nous prenons le relais. | D7: Échantillon l10n : deForEn · itForEn · jaForEn · koForEn · ruForEn · zhForEn
