Workbook

Sheet LÉEME
B1: SquirreLingo — Revisión de español (Español (Latinoamérica))
B2: Gracias por revisar. Este archivo contiene todo el español que la app le muestra a una persona usuaria en la versión 3.2.0. Está escrito por IA y necesita el visto bueno de alguien nativo antes de que salga públicamente.
B4: Lo primero: qué español queremos
B5: • Variedad: español latinoamericano. NO español de España. Donde un término cambie (computadora/ordenador, celular/móvil, jugo/zumo), queremos el latinoamericano.
B6: • Trato: «tú» informal en toda la app. Nunca «vosotros». «Usted» solo si una frase concreta lo pide.
B7: • Género: la app le habla directamente a quien la usa, así que buscamos redacción neutra donde se pueda — sin formas «/a» y sin dar por hecho el género de quien lee.
B8: • Tono: cercano, breve y alentador. Nunca regaña ni castiga.
B10: Cómo llenar el archivo
B11: 1. Revisa una pestaña a la vez. El orden sugerido está en la pestaña RESUMEN.
B12: 2. En cada fila hay una columna VEREDICTO con un menú desplegable. Elige un valor:
B13: – OK — el español está bien tal como está. No hace falta escribir nada más.
B14: – CAMBIAR — hay algo que corregir. Escribe el texto corregido completo en «CORRECCIÓN SUGERIDA».
... B26: Ejemplo de una fila bien llenada
B27: Español actual | C27: VEREDICTO | D27: CORRECCIÓN SUGERIDA | E27: NOTA / MOTIVO
B28: Elige tu próxima victoria rápida ⚡ | C28: CAMBIAR | D28: Elige tu próximo logro rápido ⚡ | E28: «victoria» suena a competencia; «logro» encaja mejor con el tono. Aplica igual en toda la app.
B31: Qué es lo más importante
B32: • La pestaña 1-Variantes-regionales es la de mayor riesgo. Ahí la app afirma «en México se dice X, en el Cono Sur Y». Una atribución equivocada es un error visible que daña la credibilidad. Si solo tienes tiempo para una pestaña, que sea esa.
B33: • En esa pestaña, las filas de tipo REFERENCIA son términos de ESPAÑA, con el fondo gris y la letra en cursiva. No son tu responsabilidad: están ahí porque la tarjeta muestra las dos mitades juntas y sin ver el contraste cuesta juzgar la tuya. Si algo te salta a la vista, dilo — lo tomamos como orientación, no como veredicto.
B34: • La pestaña 2-Decisiones recoge decisiones que tomamos a propósito y sobre las que necesitamos tu opinión explícita. Son pocas filas y valen mucho.
B35: • La pestaña 8-Muestra-contenido es una MUESTRA (unas 40 preguntas por idioma, de unas 0 en total). Sirve para detectar problemas sistemáticos. Si ves un patrón que se repite, dilo en la nota: lo arreglamos en todo el corpus, no solo en esa fila.
B37: Al terminar
B38: Llena tu nombre y la fecha en la pestaña RESUMEN y devuelve este mismo archivo .xlsx. No hace falta que lo cambies de formato ni que escribas un informe aparte: leemos las columnas directamente.

Sheet RESUMEN
B2: Resumen y firma de la revisión — Español (Latinoamérica) · Interfaz
B3: Lo que la app te dice a ti
B5: Nombre de quien revisa: | C5: María Rodríguez
B6: País / región de origen: | C6: México (CDMX)
B7: Fecha de entrega: | C7: 2026-08-14
B8: ¿Doy el visto bueno general? | C8: SÍ CON CAMBIOS
A11: Orden | B11: Pestaña | C11: Qué contiene | D11: Filas | E11: OK | F11: CAMBIAR | G11: DUDA | H11: Sin revisar
A12: 1 | B12: 1-Variantes-regionales | C12: Términos por país. LO MÁS IMPORTANTE — empieza por aquí. | D12: 325 | E12: =COUNTIF('1-Variantes-regionales'!$I$2:$I$326,"OK") | F12: =COUNTIF('1-Variantes-regionales'!$I$2:$I$326,"CAMBIAR") | G12: =COUNTIF('1-Variantes-regionales'!$I$2:$I$326,"DUDA") | H12: =D12-E12-F12-G12
A13: 2 | B13: 2-Decisiones | C13: Decisiones que tomamos a propósito y necesitan tu opinión. | D13: 16 | E13: =COUNTIF('2-Decisiones'!$E$2:$E$17,"APRUEBO") | F13: =COUNTIF('2-Decisiones'!$E$2:$E$17,"CAMBIAR") | G13: =COUNTIF('2-Decisiones'!$E$2:$E$17,"DUDA") | H13: =D13-E13-F13-G13
A14: 3 | B14: 3-Config-tarjeta | C14: Textos de la tarjeta de variantes, nombres de países y etiquetas. | D14: 117 | E14: =COUNTIF('3-Config-tarjeta'!$F$2:$F$118,"OK") | F14: =COUNTIF('3-Config-tarjeta'!$F$2:$F$118,"CAMBIAR") | G14: =COUNTIF('3-Config-tarjeta'!$F$2:$F$118,"DUDA") | H14: =D14-E14-F14-G14
A15: 4 | B15: 4-Preguntas-seguridad | C15: Las 10 preguntas de recuperación de contraseña. | D15: 10 | E15: =COUNTIF('4-Preguntas-seguridad'!$F$2:$F$11,"OK") | F15: =COUNTIF('4-Preguntas-seguridad'!$F$2:$F$11,"CAMBIAR") | G15: =COUNTIF('4-Preguntas-seguridad'!$F$2:$F$11,"DUDA") | H15: =D15-E15-F15-G15
A16: 5 | B16: 5-Interfaz | C16: Toda la interfaz: cuenta, ajustes, formularios, juego. | D16: 403 | E16: =COUNTIF('5-Interfaz'!$F$2:$F$404,"OK") | F16: =COUNTIF('5-Interfaz'!$F$2:$F$404,"CAMBIAR") | G16: =COUNTIF('5-Interfaz'!$F$2:$F$404,"DUDA") | H16: =D16-E16-F16-G16
A17: 6 | B17: 6-Otros-textos | C17: Tour guiado, nombres de idiomas, niveles, subtítulos. | D17: 58 | E17: =COUNTIF('6-Otros-textos'!$F$2:$F$59,"OK") | F17: =COUNTIF('6-Otros-textos'!$F$2:$F$59,"CAMBIAR") | G17: =COUNTIF('6-Otros-textos'!$F$2:$F$59,"DUDA") | H17: =D17-E17-F17-G17
A18: 7 | B18: 7-Ayuda-AcercaDe | C18: Texto largo de las páginas de Ayuda y Acerca de. | D18: 110 | E18: =COUNTIF('7-Ayuda-AcercaDe'!$F$2:$F$111,"OK") | F18: =COUNTIF('7-Ayuda-AcercaDe'!$F$2:$F$111,"CAMBIAR") | G18: =COUNTIF('7-Ayuda-AcercaDe'!$F$2:$F$111,"DUDA") | H18: =D18-E18-F18-G18
A19: 8 | B19: 8-Novedades | C19: Notas de versión traducidas. Prioridad baja, es histórico. | D19: 184 | E19: =COUNTIF('8-Novedades'!$F$2:$F$185,"OK") | F19: =COUNTIF('8-Novedades'!$F$2:$F$185,"CAMBIAR") | G19: =COUNTIF('8-Novedades'!$F$2:$F$185,"DUDA") | H19: =D19-E19-F19-G19
C20: TOTAL | D20: =SUM(D12:D19) | E20: =SUM(E12:E19) | F20: =SUM(F12:F19) | G20: =SUM(G12:G19) | H20: =SUM(H12:H19)
B22: «Sin revisar» baja a cero solo cuando cada fila tiene un veredicto. No hace falta llegar a cero para devolvernos el archivo: manda lo que tengas y seguimos desde ahí.

Sheet 1-Variantes-regionales
A1: ID | B1: Concepto Nº | C1: Concepto (inglés) | D1: Tipo | E1: Término actual | F1: Países asignados | G1: Etiqueta de grupo | H1: Variedad responsable | I1: VEREDICTO | J1: TÉRMINO CORREGIDO | K1: PAÍSES CORREGIDOS | L1: NOTA / MOTIVO
A2: VR-001-REF | B2: 1 | C2: car | D2: REFERENCIA | E2: coche | F2: ES | G2: España | H2: es-spain (orientativo) | I2: OK | L2: (Fila de España — solo comento: «coche» me suena correcto.)
A3: VR-001-DEF | B3: 1 | C3: car | D3: PREDETERMINADO | E3: carro | F3: (unlisted countries) | G3: Latinoamérica | H3: es-latam | I3: OK
A4: VR-001-a | B4: 1 | C4: car | D4: REGIONAL | E4: carro | F4: MX · GT · HN · SV · NI · CR · PA · CU · DO · PR · CO · VE · EC · PE | G4: Méx·CA·Andes | H4: es-latam | I4: OK
A5: VR-001-b | B5: 1 | C5: car | D5: REGIONAL | E5: auto | F5: AR · UY · PY · CL · BO | G5: Cono Sur | H5: es-latam | I5: OK
A6: VR-002-REF | B6: 2 | C6: to drive | D6: REFERENCIA | E6: conducir | F6: ES | G6: España | H6: es-spain (orientativo) | I6: OK
A7: VR-002-DEF | B7: 2 | C7: to drive | D7: PREDETERMINADO | E7: manejar | F7: (unlisted countries) | G7: Latinoamérica | H7: es-latam | I7: OK
A8: VR-002-a | B8: 2 | C8: to drive | D8: REGIONAL | E8: manejar | F8: (whole region) | G8: LatAm | H8: es-latam | I8: OK
A9: VR-003-REF | B9: 3 | C9: ticket (bus/event) | D9: REFERENCIA | E9: billete | F9: ES | G9: España | H9: es-spain (orientativo) | I9: OK
A10: VR-003-DEF | B10: 3 | C10: ticket (bus/event) | D10: PREDETERMINADO | E10: boleto | F10: (unlisted countries) | G10: Latinoamérica | H10: es-latam | I10: OK
A11: VR-003-a | B11: 3 | C11: ticket (bus/event) | D11: REGIONAL | E11: boleto | F11: (whole region) | G11: LatAm | H11: es-latam | I11: OK
A12: VR-004-REF | B12: 4 | C12: tire | D12: REFERENCIA | E12: neumático | F12: ES | G12: España | H12: es-spain (orientativo) | I12: OK
A13: VR-004-DEF | B13: 4 | C13: tire | D13: PREDETERMINADO | E13: llanta | F13: (unlisted countries) | G13: Latinoamérica | H13: es-latam | I13: OK
A14: VR-004-a | B14: 4 | C14: tire | D14: REGIONAL | E14: llanta | F14: MX · GT · HN · SV · NI · CR · PA · CO · VE · EC · PE · BO | G14: Méx·Andes | H14: es-latam | I14: OK
... A60: VR-016-DEF | B60: 16 | C60: peanut | D60: PREDETERMINADO | E60: maní | F60: (unlisted countries) | G60: Latinoamérica | H60: es-latam | I60: OK
A61: VR-016-a | B61: 16 | C61: peanut | D61: REGIONAL | E61: maní | F61: CU · DO · PR · CO · VE · EC · PE · BO · AR · UY · PY · CL | G61: casi toda LatAm | H61: es-latam | I61: DUDA | L61: En Perú y Bolivia oigo más «maní», pero no estoy segura de Chile. Confírmenlo con alguien de allá.
A62: VR-016-b | B62: 16 | C62: peanut | D62: REGIONAL | E62: cacahuate | F62: MX · GT · HN · SV · NI · CR · PA | G62: Méx·CA | H62: es-latam | I62: OK
A63: VR-017-REF | B63: 17 | C63: shrimp / prawn | D63: REFERENCIA | E63: gamba | F63: ES | G63: España | H63: es-spain (orientativo) | I63: OK
A64: VR-017-DEF | B64: 17 | C64: shrimp / prawn | D64: PREDETERMINADO | E64: camarón | F64: (unlisted countries) | G64: Latinoamérica | H64: es-latam | I64: OK
A65: VR-017-a | B65: 17 | C65: shrimp / prawn | D65: REGIONAL | E65: camarón | F65: (whole region) | G65: LatAm | H65: es-latam | I65: OK
A66: VR-018-REF | B66: 18 | C66: chili pepper | D66: REFERENCIA | E66: guindilla | F66: ES | G66: España | H66: es-spain (orientativo) | I66: OK
A67: VR-018-DEF | B67: 18 | C67: chili pepper | D67: PREDETERMINADO | E67: ají | F67: (unlisted countries) | G67: Latinoamérica | H67: es-latam | I67: OK
A68: VR-018-a | B68: 18 | C68: chili pepper | D68: REGIONAL | E68: ají | F68: CU · DO · PR · CO · VE · EC · PE · BO · AR · UY · PY · CL | G68: Caribe·Andes·Cono Sur | H68: es-latam | I68: OK
A69: VR-018-b | B69: 18 | C69: chili pepper | D69: REGIONAL | E69: chile | F69: MX · GT · HN · SV · NI · CR · PA | G69: Méx·CA | H69: es-latam | I69: OK
A70: VR-019-REF | B70: 19 | C70: corn on the cob | D70: REFERENCIA | E70: mazorca | F70: ES | G70: España | H70: es-spain (orientativo) | I70: OK
A71: VR-019-DEF | B71: 19 | C71: corn on the cob | D71: PREDETERMINADO | E71: elote | F71: (unlisted countries) | G71: Latinoamérica | H71: es-latam | I71: OK
A72: VR-019-a | B72: 19 | C72: corn on the cob | D72: REGIONAL | E72: elote | F72: MX · GT · HN · SV · NI · CR · PA | G72: Méx·CA | H72: es-latam | I72: OK
A73: VR-019-b | B73: 19 | C73: corn on the cob | D73: REGIONAL | E73: choclo | F73: CO · VE · EC · PE · BO · AR · UY · PY · CL | G73: Andes·Cono Sur | H73: es-latam | I73: OK
... A80: VR-021-DEF | B80: 21 | C80: banana | D80: PREDETERMINADO | E80: banana | F80: (unlisted countries) | G80: Latinoamérica | H80: es-latam | I80: OK
A81: VR-021-a | B81: 21 | C81: banana | D81: REGIONAL | E81: banana | F81: AR · UY · PY · CO | G81: Cono Sur·Col | H81: es-latam | I81: CAMBIAR | J81: banano | K81: CO | L81: En Colombia se dice «banano», no «banana». «Banana» es del Cono Sur.
A82: VR-021-b | B82: 21 | C82: banana | D82: REGIONAL | E82: guineo | F82: CU · DO · PR · GT · HN · SV · NI · CR · PA · EC | G82: Caribe·CA | H82: es-latam | I82: OK
A83: VR-021-c | B83: 21 | C83: banana | D83: REGIONAL | E83: cambur | F83: VE | G83: Ven | H83: es-latam | I83: OK | L83: «Cambur» en Venezuela está bien.
A84: VR-021-d | B84: 21 | C84: banana | D84: REGIONAL | E84: plátano | F84: MX · PE · CL · BO | G84: Méx·Perú | H84: es-latam | I84: OK
A85: VR-022-REF | B85: 22 | C85: refrigerator | D85: REFERENCIA | E85: frigorífico | F85: ES | G85: España | H85: es-spain (orientativo) | I85: OK
A86: VR-022-DEF | B86: 22 | C86: refrigerator | D86: PREDETERMINADO | E86: refrigerador | F86: (unlisted countries) | G86: Latinoamérica | H86: es-latam | I86: OK
A87: VR-022-a | B87: 22 | C87: refrigerator | D87: REGIONAL | E87: refrigerador | F87: MX · GT · HN · SV · NI · CR · PA · CL · PE · EC · BO | G87: Méx·Chile·Perú | H87: es-latam | I87: OK
A88: VR-022-b | B88: 22 | C88: refrigerator | D88: REGIONAL | E88: nevera | F88: CU · DO · PR · CO · VE · PA | G88: Caribe·Col·Ven | H88: es-latam | I88: OK
A89: VR-022-c | B89: 22 | C89: refrigerator | D89: REGIONAL | E89: heladera | F89: AR · UY · PY | G89: Cono Sur | H89: es-latam | I89: OK
A90: VR-023-REF | B90: 23 | C90: apartment / flat | D90: REFERENCIA | E90: piso | F90: ES | G90: España | H90: es-spain (orientativo) | I90: OK
A91: VR-023-DEF | B91: 23 | C91: apartment / flat | D91: PREDETERMINADO | E91: departamento | F91: (unlisted countries) | G91: Latinoamérica | H91: es-latam | I91: OK
...

Sheet 2-Decisiones
A1: ID | B1: Tema | C1: Qué decidimos y por qué | D1: Ejemplo / dónde | E1: DECISIÓN | F1: ALTERNATIVA PROPUESTA | G1: NOTA
A2: DEC-01 | B2: Variedad y trato | C2: Todo el español es latinoamericano con «tú» informal. Nunca «vosotros»; «usted» solo si una frase lo pidiera (ninguna lo hace hoy). | D2: «¿Olvidaste tu contraseña?», «Puedes cambiarlo cuando quieras» | E2: APRUEBO | G2: El «tú» informal es lo correcto para una app así.
A3: DEC-02 | B3: Redacción neutra en género | C3: La app le habla directamente a quien la usa, así que evitamos formas «/a» y adjetivos con género. Quedan al menos cinco excepciones sin resolver. | D3: «¡Bienvenido/a» (homeGreeting) · «de niño» (pregunta de seguridad) · «restablecerla tú mismo» · «Te sientes cómodo» · «¿No estás seguro?» | E3: CAMBIAR | F3: «¡Te damos la bienvenida!» en vez de «¡Bienvenido/a» | G3: La barra se ve mal y se lee peor en voz alta. «Te damos la bienvenida» sirve para todo el mundo y no suena forzado. Ver también mis correcciones en la pestaña 5.
A4: DEC-03 | B4: Anglicismos conservados | C4: Dejamos en inglés los términos tecnológicos que ya se usan tal cual: «beta tester», «beta», «Tablet», «laptop», «Chromebook», y los nombres de marcas. | D4: «Solicita ser beta tester» en vez de «probador de la versión beta» | E4: APRUEBO | G4: «Beta tester», «laptop» y «tablet» se usan tal cual. Traducirlos sonaría raro.
A5: DEC-04 | B5: Léxico latinoamericano | C5: Elegimos deliberadamente el término latinoamericano frente al peninsular. Confirma que no se coló ninguno de España. | D5: computadora / laptop / celular / correo / Ajustes / ícono / tarjetas de memoria | E5: APRUEBO | G5: No vi nada peninsular colado.
A6: DEC-05 | B6: «pista» = curso de idioma | C6: En el código un «track» es un curso de idioma. Lo tradujimos como «pista», que también significa pista de audio. | D6: «Se habilita por pista» (setGpTogCaudio). Alternativas: «por idioma», «por curso» | E6: CAMBIAR | F6: «por curso» | G6: «Pista» hace pensar en audio, sobre todo en una app que sí tiene audio. «Por curso» se entiende de inmediato.
A7: DEC-06 | B7: «Rueditas de apoyo» | C7: Traducción de «training wheels» para las pistas de tiempo verbal. El tono juguetón es intencional. | D7: «Rueditas de apoyo para tiempos verbales» (setGpTogTense) | E7: DUDA | G7: «Rueditas de apoyo» se entiende en México, pero no sé si en el Cono Sur. Quizá «ayuditas» sea más neutro.
A8: DEC-07 | B8: Comillas y rayas | C8: Usamos comillas angulares « » y raya — de forma consistente como estilo de la casa. | D8: «Verificar», «¿Olvidaste tu contraseña?» | E8: APRUEBO | G8: Las comillas angulares se ven bien.
A9: DEC-08 | B9: Glosario del producto | C9: Nombres fijos que se repiten en toda la app. Si cambias uno, hay que cambiarlo en todas partes: dilo una vez aquí. | D9: Quiz Rápido · Lecciones · Gimnasio de Gramática · Banco de Palabras · modo Alfabeto · Ajustes · MCER · prueba de nivel · racha · combo · Modo repaso · «Ojo» · TDAH | E9: APRUEBO | G9: El glosario me parece consistente. «Banco de Palabras» y «Quiz Rápido» funcionan.
A10: DEC-09 | B10: Atribuciones por país (riesgo alto) | C10: Cada fila REGIONAL de la pestaña 1 afirma que un término se usa en unos países concretos. Es lo más visible y lo más fácil de equivocar. | D10: «banana / guineo / cambur / plátano», «playera / remera / polera / franela / camiseta» | E10: CAMBIAR | F10: Ver mis correcciones en la pestaña 1 | G10: Solo dos atribuciones mal de las que revisé.
A11: DEC-10 | B11: Términos de España (fuera de tu alcance) | C11: Las filas REFERENCIA son los términos peninsulares. Todavía no tenemos a nadie de España revisando; tu opinión aquí es orientativa, no vinculante. | D11: «coche», «ordenador», «pajita», «bombilla», «zumo» | E11: APRUEBO | G11: Entendido: los términos de España los dejo como referencia. Los que vi me suenan bien, pero que los confirme alguien de allá.
A12: DEC-11 | B12: Colisión: «bombilla» | C12: «bombilla» ya está usada como el término de España para el foco (concepto 28), así que no pudimos usarla también para el sorbete chileno. Hoy Chile ve «sorbete», que no es correcto para Chile. | D12: Concepto 55 (drinking straw). ¿Ponemos «pajita» para Chile, lo dejamos fuera, u otra opción? | E12: CAMBIAR | F12: Poner «bombilla» para Chile en el sorbete y cambiar la referencia de España del foco a «bombilla (de luz)» | G12: En Chile «bombilla» es el sorbete, sin duda. «Pajita» no se usa allá. Si el problema es que la palabra choca, conviene desambiguar la de España en vez de dejar Chile mal.
A13: DEC-12 | B13: Colisión: «grifo» | C13: «grifo» ya está usada como el término de España para la llave del agua (concepto 59), así que no pudimos usarla también para la gasolinera peruana. Hoy Perú ve «gasolinera», aunque en Perú se dice «grifo». | D13: Concepto 68 (gas station). ¿Aceptable así, o preferimos «grifo» para Perú? | E13: CAMBIAR | F13: Usar «grifo» para Perú en la gasolinera | G13: En Perú es «grifo», siempre. Dejar «gasolinera» es un error visible para cualquier peruano.
A14: DEC-13 | B14: Cola excluida a propósito | C14: Dejamos fuera palabras cuyo reparto por país es difuso o muy coloquial. Puedes autorizar que se agreguen. | D14: green beans (ejote/vainita/chaucha/poroto verde) · sandwich · niño/chamaco/pibe/chamo · tipo/chavo/parce · ropa interior · calcomanía | E14: APRUEBO | G14: De acuerdo con dejar fuera la cola. «Chamaco», «pibe» y demás cambian demasiado.
A15: DEC-14 | B15: Registro coloquial en «trabajo» | C15: El concepto 69 usa formas informales (chamba, laburo, pega). ¿Encaja el registro en una app de aprendizaje? | D15: Concepto 69 (job/work informal) | E15: DUDA | G15: «Chamba» y «laburo» son muy coloquiales para una app de aprendizaje. Yo los dejaría, pero marcados como informales.
A16: DEC-15 | B16: Novedades: «Cuatro idiomas nuevos» | C16: Una nota de la versión 2.13.0 dice «Cuatro idiomas nuevos» pero enumera tres. El error viene del inglés original y lo tradujimos igual, a propósito. | D16: Pestaña 9 — v2.13.0, primera viñeta | E16: APRUEBO | G16: Entendido, lo dejo como está.
A17: DEC-16 | B17: Muestra de contenido | C17: La pestaña 8 es una muestra de 400 preguntas de unas 14.000. Buscamos problemas SISTEMÁTICOS, no una revisión exhaustiva. | D17: Si algo se repite (por ejemplo una fórmula de explicación que suena rara), señálalo una vez y lo arreglamos en todo el corpus. | E17: APRUEBO | G17: Entendido: aviso de patrones, no fila por fila.

Sheet 3-Config-tarjeta
A1: ID | B1: Sección | C1: Clave / ubicación | D1: Inglés (referencia) | E1: Español actual | F1: VEREDICTO | G1: CORRECCIÓN SUGERIDA | H1: NOTA / MOTIVO | I1: Prioridad | J1: Nota del equipo | K1: Archivo
A2: CF-01 | B2: Textos de la tarjeta | C2: title | D2: ui.title | E2: También se dice | F2: OK | I2: Alta
A3: CF-02 | B3: Textos de la tarjeta | C3: inYourRegion | D3: ui.inYourRegion | E3: en tu región | F3: OK | I3: Alta
A4: CF-03 | B4: Textos de la tarjeta | C4: variantes | D4: ui.variantes | E4: variantes regionales | F4: OK | I4: Alta
A5: CF-04 | B5: Textos de la tarjeta | C5: hide | D5: ui.hide | E5: ocultar | F5: OK | I5: Alta
A6: CF-05 | B6: Textos de la tarjeta | C6: refPhrase | D6: ui.refPhrase | E6: En España | F6: OK | I6: Alta
A7: CF-06 | B7: Textos de la tarjeta | C7: regGroupPhrase | D7: ui.regGroupPhrase | E7: En Latinoamérica | F7: OK | I7: Alta
A8: CF-07 | B8: Textos de la tarjeta | C8: refFlag | D8: ui.refFlag | E8: 🇪🇸 | F8: OK | I8: Alta
A9: CF-08 | B9: Textos de la tarjeta | C9: regFlag | D9: ui.regFlag | E9: 🌎 | F9: OK | I9: Alta
A10: CF-09 | B10: Nombres de países | C10: MX | D10: ISO MX | E10: México | F10: OK | I10: Alta
A11: CF-10 | B11: Nombres de países | C11: GT | D11: ISO GT | E11: Guatemala | F11: OK | I11: Alta
A12: CF-11 | B12: Nombres de países | C12: HN | D12: ISO HN | E12: Honduras | F12: OK | I12: Alta
A13: CF-12 | B13: Nombres de países | C13: SV | D13: ISO SV | E13: El Salvador | F13: OK | I13: Alta
... A118: CF-117 | B118: Etiquetas de grupo de países | C118: reference.label | D118: (reference variety name) | E118: España | F118: OK | I118: Alta

Sheet 4-Preguntas-seguridad
A1: ID | B1: Sección | C1: Clave / ubicación | D1: Inglés (referencia) | E1: Español actual | F1: VEREDICTO | G1: CORRECCIÓN SUGERIDA | H1: NOTA / MOTIVO | I1: Prioridad | J1: Nota del equipo | K1: Archivo
A2: PS-01 | B2: Pregunta de seguridad | C2: first_pet | D2: What was the name of your first pet? | E2: ¿Cómo se llamaba tu primera mascota? | F2: OK | I2: Alta | K2: lib/securityQuestions.js
A3: PS-02 | B3: Pregunta de seguridad | C3: childhood_street | D3: What street did you live on as a child? | E3: ¿En qué calle viviste de niño? | F3: CAMBIAR | G3: ¿En qué calle viviste en tu infancia? | H3: «De niño» tiene género. «En tu infancia» es lo más natural y neutro. | I3: Alta | J3: «de niño» tiene género. En otras partes la infancia se menciona de forma neutra («de la infancia»). ¿Alternativa preferida? | K3: lib/securityQuestions.js
A4: PS-03 | B4: Pregunta de seguridad | C4: mother_maiden | D4: What is your mother's maiden name? | E4: ¿Cuál es el apellido de soltera de tu madre? | F4: OK | I4: Alta | K4: lib/securityQuestions.js
A5: PS-04 | B5: Pregunta de seguridad | C5: first_school | D5: What was the name of your first school? | E5: ¿Cómo se llamaba tu primera escuela? | F5: OK | I5: Alta | K5: lib/securityQuestions.js
A6: PS-05 | B6: Pregunta de seguridad | C6: childhood_nickname | D6: What was your childhood nickname? | E6: ¿Cuál era tu apodo de la infancia? | F6: OK | I6: Alta | K6: lib/securityQuestions.js
A7: PS-06 | B7: Pregunta de seguridad | C7: first_car | D7: What was the make of your first car? | E7: ¿De qué marca fue tu primer auto? | F7: OK | I7: Alta | K7: lib/securityQuestions.js
A8: PS-07 | B8: Pregunta de seguridad | C8: birth_city | D8: In what city were you born? | E8: ¿En qué ciudad naciste? | F8: OK | I8: Alta | K8: lib/securityQuestions.js
A9: PS-08 | B9: Pregunta de seguridad | C9: best_friend | D9: What is the first name of your oldest friend? | E9: ¿Cuál es el nombre de tu amistad más antigua? | F9: CAMBIAR | G9: ¿Cómo se llama tu amistad más antigua? | H9: «¿Cuál es el nombre de…?» es correcto pero rígido. «¿Cómo se llama…?» es como lo diría cualquiera. | I9: Alta | K9: lib/securityQuestions.js
A10: PS-09 | B10: Pregunta de seguridad | C10: first_job | D10: What was your first job? | E10: ¿Cuál fue tu primer trabajo? | F10: OK | I10: Alta | K10: lib/securityQuestions.js
A11: PS-10 | B11: Pregunta de seguridad | C11: grandmother_name | D11: What was your maternal grandmother's first name? | E11: ¿Cómo se llamaba tu abuela materna? | F11: OK | I11: Alta | K11: lib/securityQuestions.js

Sheet 5-Interfaz
A1: ID | B1: Sección | C1: Clave / ubicación | D1: Inglés (referencia) | E1: Español actual | F1: VEREDICTO | G1: CORRECCIÓN SUGERIDA | H1: NOTA / MOTIVO | I1: Prioridad | J1: Nota del equipo | K1: Archivo
A2: IU-0001 | B2: Inicio de sesión y registro | C2: authAgreeMid | D2: and | E2: y la | F2: OK | I2: Alta | J2: Fragmento que se concatena. Confirma que se lee bien completo: «Acepto los Términos del servicio y la Política de privacidad». | K2: lib/playStrings.js
A3: IU-0002 | B3: Inicio de sesión y registro | C3: authAgreePp | D3: Privacy Policy | E3: Política de privacidad | F3: OK | I3: Media | K3: lib/playStrings.js
A4: IU-0003 | B4: Inicio de sesión y registro | C4: authAgreePre | D4: I agree to the | E4: Acepto los | F4: OK | I4: Alta | J4: Fragmento que se concatena — ver authAgreeMid. | K4: lib/playStrings.js
A5: IU-0004 | B5: Inicio de sesión y registro | C5: authAgreeTos | D5: Terms of Service | E5: Términos del servicio | F5: OK | I5: Media | K5: lib/playStrings.js
A6: IU-0005 | B6: Inicio de sesión y registro | C6: authBetaLink | D6: Apply to beta test | E6: Solicita ser beta tester | F6: OK | I6: Alta | J6: Anglicismo «beta tester» conservado a propósito. | K6: lib/playStrings.js
A7: IU-0006 | B7: Inicio de sesión y registro | C7: authBetaPre | D7: Don't have an invite yet? | E7: ¿Aún no tienes invitación? | F7: OK | I7: Media | K7: lib/playStrings.js
A8: IU-0007 | B8: Inicio de sesión y registro | C8: authBtnSignin | D8: SIGN IN | E8: INICIAR SESIÓN | F8: OK | I8: Media | K8: lib/playStrings.js
A9: IU-0008 | B9: Inicio de sesión y registro | C9: authBtnSignup | D9: SIGN UP | E9: REGISTRARSE | F9: OK | I9: Media | K9: lib/playStrings.js
A10: IU-0009 | B10: Inicio de sesión y registro | C10: authConfirmEmail | D10: Confirm email | E10: Confirmar correo | F10: OK | I10: Media | K10: lib/playStrings.js
A11: IU-0010 | B11: Inicio de sesión y registro | C11: authConfirmPassword | D11: Confirm password | E11: Confirmar contraseña | F11: OK | I11: Media | K11: lib/playStrings.js
A12: IU-0011 | B12: Inicio de sesión y registro | C12: authEmail | D12: Email | E12: Correo electrónico | F12: OK | I12: Media | K12: lib/playStrings.js
A13: IU-0012 | B13: Inicio de sesión y registro | C13: authErrAgree | D13: You need to agree to the Terms of Service and Privacy Policy to continue. | E13: Debes aceptar los Términos del servicio y la Política de privacidad para continuar. | F13: OK | I13: Media | K13: lib/playStrings.js
A14: IU-0013 | B14: Inicio de sesión y registro | C14: authErrEmailExists | D14: An account with that email already exists. Try signing in, or use 'Forgot password' if you don't remember your password. | E14: Ya existe una cuenta con ese correo. Intenta iniciar sesión, o usa «¿Olvidaste tu contraseña?» si no la recuerdas. | F14: OK | I14: Media | K14: lib/playStrings.js
A15: IU-0014 | B15: Inicio de sesión y registro | C15: authErrEmailExistsShort | D15: An account with that email already exists. Try signing in instead. | E15: Ya existe una cuenta con ese correo. Mejor intenta iniciar sesión. | F15: OK | I15: Media | K15: lib/playStrings.js
A16: IU-0015 | B16: Inicio de sesión y registro | C16: authErrEmailMismatch | D16: Email addresses don't match. | E16: Los correos no coinciden. | F16: OK | I16: Media | K16: lib/playStrings.js
A17: IU-0016 | B17: Inicio de sesión y registro | C17: authErrGeneric | D17: Something went wrong. | E17: Algo salió mal. | F17: OK | I17: Media | K17: lib/playStrings.js
A18: IU-0017 | B18: Inicio de sesión y registro | C18: authErrInvalidCreds | D18: Invalid login credentials. | E18: Credenciales incorrectas. | F18: CAMBIAR | G18: Correo o contraseña incorrectos. | H18: «Credenciales» suena a trámite. Es mejor decir qué falló. | I18: Media | K18: lib/playStrings.js
A19: IU-0018 | B19: Inicio de sesión y registro | C19: authErrPwLen | D19: Password must be at least 6 characters. | E19: La contraseña debe tener al menos 6 caracteres. | F19: OK | I19: Media | K19: lib/playStrings.js
A20: IU-0019 | B20: Inicio de sesión y registro | C20: authErrPwMismatch | D20: Passwords don't match. | E20: Las contraseñas no coinciden. | F20: OK | I20: Media | K20: lib/playStrings.js
A21: IU-0020 | B21: Inicio de sesión y registro | C21: authErrUserLen | D21: Username must be at least 3 characters. | E21: El nombre de usuario debe tener al menos 3 caracteres. | F21: OK | I21: Media | K21: lib/playStrings.js
A22: IU-0021 | B22: Inicio de sesión y registro | C22: authErrUserRequired | D22: Username is required. | E22: El nombre de usuario es obligatorio. | F22: OK | I22: Media | K22: lib/playStrings.js
A23: IU-0022 | B23: Inicio de sesión y registro | C23: authErrUserTaken | D23: That username is already taken — try Verify above for some available alternatives. | E23: Ese nombre de usuario ya está en uso — prueba «Verificar» arriba para ver alternativas disponibles. | F23: OK | I23: Media | K23: lib/playStrings.js
A24: IU-0023 | B24: Inicio de sesión y registro | C24: authForgot | D24: Forgot password? | E24: ¿Olvidaste tu contraseña? | F24: OK | I24: Media | K24: lib/playStrings.js
A25: IU-0024 | B25: Inicio de sesión y registro | C25: authHaveAccount | D25: Already have an account? Sign in | E25: ¿Ya tienes una cuenta? Inicia sesión | F25: OK | I25: Media | K25: lib/playStrings.js
A26: IU-0025 | B26: Inicio de sesión y registro | C26: authIdentifier | D26: Email or username | E26: Correo o nombre de usuario | F26: OK | I26: Media | K26: lib/playStrings.js
A27: IU-0026 | B27: Inicio de sesión y registro | C27: authInfoConfirm | D27: Check your email to confirm your account, then sign in. | E27: Revisa tu correo para confirmar tu cuenta y luego inicia sesión. | F27: OK | I27: Media | K27: lib/playStrings.js
A28: IU-0027 | B28: Inicio de sesión y registro | C28: authNeedAccount | D28: Need an account? Sign up | E28: ¿Necesitas una cuenta? Regístrate | F28: OK | I28: Media | K28: lib/playStrings.js
A29: IU-0028 | B29: Inicio de sesión y registro | C29: authPassword | D29: Password | E29: Contraseña | F29: OK | I29: Media | K29: lib/playStrings.js
A30: IU-0029 | B30: Inicio de sesión y registro | C30: authSigninHint | D30: You can sign in with either your username or your email — either works. | E30: Puedes iniciar sesión con tu nombre de usuario o tu correo — cualquiera funciona. | F30: OK | I30: Media | K30: lib/playStrings.js
... A84: IU-0083 | B84: Ajustes | C84: setComingSoon | D84: Coming soon. | E84: Próximamente. | F84: OK | I84: Media | K84: lib/playStrings.js
A85: IU-0084 | B85: Ajustes | C85: setCountryNote | D85: Combined with your native language, this determines the regional label shown on the home screen (e.g. Spanish + Venezuela → "Español (Latinoamérica)"). | E85: Junto con tu idioma nativo, esto determina la etiqueta regional que se muestra en la pantalla de inicio (p. ej. español + Venezuela → "Español (Latinoamérica)"). | F85: OK | I85: Alta | J85: Contiene un ejemplo entre comillas rectas " " en vez de comillas angulares « ». ¿Unificamos? | K85: lib/playStrings.js
A86: IU-0085 | B86: Ajustes | C86: setDrawerTitle | D86: Settings | E86: Ajustes | F86: OK | I86: Media | K86: lib/playStrings.js
A87: IU-0086 | B87: Ajustes | C87: setErrChoosePhoto | D87: Choose a photo to upload. | E87: Elige una foto para subir. | F87: OK | I87: Media | K87: lib/playStrings.js
A88: IU-0087 | B88: Ajustes | C88: setErrCurPwRequired | D88: Enter your current password to confirm this change. | E88: Ingresa tu contraseña actual para confirmar este cambio. | F88: OK | I88: Media | K88: lib/playStrings.js
A89: IU-0088 | B89: Ajustes | C89: setErrCurPwWrong | D89: Current password is incorrect. | E89: La contraseña actual es incorrecta. | F89: OK | I89: Media | K89: lib/playStrings.js
A90: IU-0089 | B90: Ajustes | C90: setErrEmailsMismatch | D90: Emails don't match. | E90: Los correos no coinciden. | F90: OK | I90: Media | K90: lib/playStrings.js
A91: IU-0090 | B91: Ajustes | C91: setErrGeneric | D91: Something went wrong. | E91: Algo salió mal. | F91: OK | I91: Media | K91: lib/playStrings.js
A92: IU-0091 | B92: Ajustes | C92: setErrPhotoSize | D92: Photo must be under 3MB. | E92: La foto debe pesar menos de 3 MB. | F92: OK | I92: Media | K92: lib/playStrings.js
A93: IU-0092 | B93: Ajustes | C93: setErrPickFlag | D93: Pick a flag. | E93: Elige una bandera. | F93: OK | I93: Media | K93: lib/playStrings.js
...

Sheet 6-Otros-textos
A1: ID | B1: Sección | C1: Clave / ubicación | D1: Inglés (referencia) | E1: Español actual | F1: VEREDICTO | G1: CORRECCIÓN SUGERIDA | H1: NOTA / MOTIVO | I1: Prioridad | J1: Nota del equipo | K1: Archivo
A2: OT-001 | B2: Tour guiado (primer inicio) | C2: STEPS[0].title | D2: Welcome to SquirreLingo! | E2: ¡Te damos la bienvenida a SquirreLingo! | F2: OK | I2: Media | K2: lib/guideSteps.js
A3: OT-002 | B3: Tour guiado (primer inicio) | C3: STEPS[0].body | D3: Language practice built for short, low-pressure bursts — answer a handful of questions, see how you did, stop whenever you like. Here's a quick 60-second tour of how to get around. | E3: Práctica de idiomas hecha para ratitos cortos y sin presión: responde un puñado de preguntas, mira cómo te fue y para cuando quieras. Aquí tienes un recorrido rápido de 60 segundos para ubicarte. | F3: OK | I3: Media | K3: lib/guideSteps.js
A4: OT-003 | B4: Tour guiado (primer inicio) | C4: STEPS[1].title | D4: Pick a language | E4: Elige un idioma | F4: OK | I4: Media | K4: lib/guideSteps.js
A5: OT-004 | B5: Tour guiado (primer inicio) | C5: STEPS[1].body | D5: Tap any language bubble on the home screen to start practicing it. Each bubble shows your current level and progress, and every language is tracked separately — so you can dabble in a few without losing your place in any. | E5: Toca cualquier burbuja de idioma en la pantalla de inicio para empezar a practicarlo. Cada burbuja muestra tu nivel y tu progreso, y cada idioma se registra por separado, así que puedes probar varios sin perder tu lugar en ninguno. | F5: OK | I5: Media | K5: lib/guideSteps.js
A6: OT-005 | B6: Tour guiado (primer inicio) | C6: STEPS[2].title | D6: Find your level | E6: Encuentra tu nivel | F6: OK | I6: Media | K6: lib/guideSteps.js
A7: OT-006 | B7: Tour guiado (primer inicio) | C7: STEPS[2].body | D7: New to a language? Take its short, untimed placement quiz from the start screen — it samples every difficulty tier and sets you at the right one. Not sure? Just start playing; you'll be offered a level-up once you're answering well. | E7: ¿Apenas empiezas con un idioma? Haz su prueba de nivel, corta y sin cronómetro, desde la pantalla de inicio: toma preguntas de todos los niveles y te ubica en el correcto. ¿Tienes dudas? Solo empieza a jugar; te ofreceremos subir de nivel cuando estés respondiendo bien. | F7: OK | I7: Media | K7: lib/guideSteps.js
A8: OT-007 | B8: Tour guiado (primer inicio) | C8: STEPS[3].title | D8: Two ways to practice | E8: Dos formas de practicar | F8: OK | I8: Media | K8: lib/guideSteps.js
A9: OT-008 | B9: Tour guiado (primer inicio) | C9: STEPS[3].body | D9: Quick Quiz is fast and game-style — a timer, a combo counter, and streaks. Lessons is calmer — no timer, one topic at a time, with the explanation right after each answer. Switch between them anytime; both build the same progress. | E9: El Quiz Rápido es veloz y con estilo de juego: cronómetro, contador de combos y rachas. Las Lecciones son más tranquilas: sin cronómetro, un tema a la vez y con la explicación justo después de cada respuesta. Cambia entre ellos cuando quieras; ambos suman el mismo progreso. | F9: OK | I9: Media | K9: lib/guideSteps.js
A10: OT-009 | B10: Tour guiado (primer inicio) | C10: STEPS[4].title | D10: Play a round | E10: Juega una ronda | F10: OK | I10: Media | K10: lib/guideSteps.js
A11: OT-010 | B11: Tour guiado (primer inicio) | C11: STEPS[4].body | D11: Each round mixes a few question types — a colored tag shows which is which. There's no penalty for a wrong answer, and a combo (⚡) builds as you chain correct ones. Where audio exists, tap the speaker to hear the question read aloud. | E11: Cada ronda mezcla varios tipos de pregunta; una etiqueta de color indica cuál es cuál. No hay penalización por una respuesta incorrecta, y el combo (⚡) crece a medida que encadenas respuestas correctas. Donde haya audio, toca el altavoz para escuchar la pregunta en voz alta. | F11: OK | I11: Media | K11: lib/guideSteps.js
A12: OT-011 | B12: Tour guiado (primer inicio) | C12: STEPS[5].title | D12: Wrong answers teach you | E12: Las respuestas incorrectas te enseñan | F12: OK | I12: Media | K12: lib/guideSteps.js
A13: OT-012 | B13: Tour guiado (primer inicio) | C13: STEPS[5].body | D13: Miss one and you get a quick “Heads up” — the rule, plus which form you actually picked — so a wrong tap becomes a mini-lesson instead of just a red mark. Turn on Review mode in Settings to pause on each explanation. | E13: Si fallas una, recibes un rápido «Ojo»: la regla y la forma que elegiste, para que un toque equivocado se convierta en una mini-lección en vez de solo una marca roja. Activa el Modo repaso en Ajustes para hacer una pausa en cada explicación. | F13: OK | I13: Media | K13: lib/guideSteps.js
... A44: OT-043 | B44: Niveles de habilidad | C44: LEVEL_DESCRIPTIONS.intermediate | D44: You can hold a conversation — rounds lean toward richer grammar and phrasing. | E44: Puedes mantener una conversación — las rondas se inclinan hacia gramática y expresiones más ricas. | F44: OK | I44: Media | K44: lib/skillLevels.js
A45: OT-044 | B45: Niveles de habilidad | C45: LEVEL_DESCRIPTIONS.expert | D45: You're comfortable — rounds lean toward nuance, idioms, and tricky details. | E45: Te sientes cómodo — las rondas se inclinan hacia matices, modismos y detalles difíciles. | F45: CAMBIAR | G45: Te sientes a gusto — las rondas se inclinan hacia matices, modismos y detalles difíciles. | H45: «Cómodo» tiene género. «A gusto» es invariable. | I45: Alta | J45: «Te sientes cómodo» tiene género masculino. ¿Alternativa neutra? | K45: lib/skillLevels.js
A46: OT-045 | B46: Niveles de habilidad | C46: LEVEL_DESCRIPTIONS.native | D46: No difficulty bias — everything in the track is fair game. | E46: Sin sesgo de dificultad — todo el contenido del idioma entra en juego. | F46: OK | I46: Media | K46: lib/skillLevels.js
A47: OT-046 | B47: Selector de idioma | C47: LANG_LABELS | D47: English | E47: Español | F47: OK | I47: Media | K47: lib/LangSwitcher.js
A48: OT-047 | B48: Subtítulos de idioma (pantalla de inicio) | C48: es-latam-for-en | E48: Para hispanohablantes · Español latinoamericano | F48: OK | I48: Media | K48: lib/trackSublabels.js
A49: OT-048 | B49: Subtítulos de idioma (pantalla de inicio) | C49: es-spain-for-en | E49: Para hispanohablantes · Español de España · vosotros, distinción | F49: OK | I49: Media | K49: lib/trackSublabels.js
A50: OT-049 | B50: Subtítulos de idioma (pantalla de inicio) | C50: it-for-en | E50: Para hispanohablantes · Italiano | F50: OK | I50: Media | K50: lib/trackSublabels.js
A51: OT-050 | B51: Subtítulos de idioma (pantalla de inicio) | C51: fr-for-en | E51: Para hispanohablantes · Francés (Francia) | F51: OK | I51: Media | K51: lib/trackSublabels.js
A52: OT-051 | B52: Subtítulos de idioma (pantalla de inicio) | C52: fr-ca-for-en | E52: Para hispanohablantes · Francés canadiense | F52: OK | I52: Media | K52: lib/trackSublabels.js
A53: OT-052 | B53: Subtítulos de idioma (pantalla de inicio) | C53: pt-br-for-en | E53: Para hispanohablantes · Portugués brasileño | F53: OK | I53: Media | K53: lib/trackSublabels.js
A54: OT-053 | B54: Subtítulos de idioma (pantalla de inicio) | C54: pt-pt-for-en | E54: Para hispanohablantes · Portugués europeo | F54: OK | I54: Media | K54: lib/trackSublabels.js
A55: OT-054 | B55: Subtítulos de idioma (pantalla de inicio) | C55: de-for-en | E55: Para hispanohablantes · Alemán | F55: OK | I55: Media | K55: lib/trackSublabels.js
A56: OT-055 | B56: Subtítulos de idioma (pantalla de inicio) | C56: ru-for-en | E56: Para hispanohablantes · Ruso | F56: OK | I56: Media | K56: lib/trackSublabels.js
A57: OT-056 | B57: Subtítulos de idioma (pantalla de inicio) | C57: ja-for-en | E57: Para hispanohablantes · Japonés | F57: OK | I57: Media | K57: lib/trackSublabels.js
A58: OT-057 | B58: Subtítulos de idioma (pantalla de inicio) | C58: zh-for-en | E58: Para hispanohablantes · Chino mandarín | F58: OK | I58: Media | K58: lib/trackSublabels.js
A59: OT-058 | B59: Subtítulos de idioma (pantalla de inicio) | C59: ko-for-en | E59: Para hispanohablantes · Coreano | F59: OK | I59: Media | K59: lib/trackSublabels.js

Sheet 7-Ayuda-AcercaDe
A1: ID | B1: Sección | C1: Clave / ubicación | D1: Inglés (referencia) | E1: Español actual | F1: VEREDICTO | G1: CORRECCIÓN SUGERIDA | H1: NOTA / MOTIVO | I1: Prioridad | J1: Nota del equipo | K1: Archivo
A2: AY-0001 | B2: Página de Ayuda | C2: title | D2: How SquirreLingo works | E2: Cómo funciona SquirreLingo | I2: Media | K2: lib/helpAboutContent.js
A3: AY-0002 | B3: Página de Ayuda | C3: crossref | D3: Looking for the bigger picture instead? See the {{about|About page}}. | E3: ¿Buscas una visión más general? Mira la {{about|página Acerca de}}. | I3: Media | K3: lib/helpAboutContent.js
A4: AY-0003 | B4: Página de Ayuda | C4: sections[0].title | D4: Finding Help and the menu | E4: Encontrar la Ayuda y el menú | I4: Media | K4: lib/helpAboutContent.js
A5: AY-0004 | B5: Página de Ayuda | C5: sections[0].body[0] | D5: The *?* button in the top-right corner of the home screen opens this Help page anytime — it’s right there so you never have to go hunting for it. | E5: El botón *?* en la esquina superior derecha de la pantalla de inicio abre esta página de Ayuda cuando quieras — está ahí a la vista para que nunca tengas que salir a buscarla. | I5: Media | K5: lib/helpAboutContent.js
A6: AY-0005 | B6: Página de Ayuda | C6: sections[0].body[1] | D6: Next to it, your *profile picture* opens a slide-out menu with everything else: *What’s New* (a dot appears when there’s a release you haven’t seen yet), *How to use SquirreLingo* (the same quick animated tour you got on your first sign-in — reopen it anytime), and *About* (what the app is, how the modes work, and what’s planned next). Below a divider, the full *Settings* section sits right there too — username, email, password, native language/country, profile picture, gameplay preferences — no extra tap needed to open it. This whole menu and every Settings label appear in your native language. | E6: Al lado, tu *foto de perfil* abre un menú lateral con todo lo demás: *Novedades* (aparece un punto cuando hay una versión nueva que aún no has visto), *Cómo usar SquirreLingo* (el mismo recorrido animado que viste la primera vez que entraste — ábrelo cuando quieras) y *Acerca de* (qué es la app, cómo funcionan los modos y qué viene después). Debajo de un divisor está también toda la sección de *Ajustes* — nombre de usuario, correo, contraseña, idioma y país nativo, foto de perfil, preferencias de juego — sin ningún toque extra para abrirla. Todo este menú y cada etiqueta de Ajustes aparecen en tu idioma nativo. | I6: Media | K6: lib/helpAboutContent.js
A7: AY-0006 | B7: Página de Ayuda | C7: sections[1].title | D7: SquirreLingo in your language | E7: SquirreLingo en tu idioma | I7: Media | K7: lib/helpAboutContent.js
A8: AY-0007 | B8: Página de Ayuda | C8: sections[1].body[0] | D8: SquirreLingo doesn’t just teach in your language — *the app itself adapts to it*. Wherever your native language is supported, the whole interface follows it: the sign-in and sign-up screens, password recovery, the first-run onboarding, the slide-out menu and every Settings label, the beta-application form, and everything inside a round — subtitles, answer choices, explanations and the Word Bank. | E8: SquirreLingo no solo enseña en tu idioma — *la app misma se adapta a él*. Donde tu idioma nativo esté disponible, toda la interfaz lo sigue: las pantallas de iniciar sesión y registrarse, la recuperación de contraseña, la configuración inicial la primera vez, el menú lateral y cada etiqueta de Ajustes, el formulario para la beta y todo lo que pasa dentro de una ronda — subtítulos, opciones de respuesta, explicaciones y el Banco de Palabras. | I8: Media | K8: lib/helpAboutContent.js
A9: AY-0008 | B9: Página de Ayuda | C9: sections[1].body[1] | D9: The app *picks your language automatically* from your browser the first time you arrive, so there’s nothing to set up. Prefer a different one? A small *🌐 language pill* sits in the corner of every screen before you sign in — tap it to switch anytime, and your choice sticks. | E9: La app *elige tu idioma automáticamente* desde tu navegador la primera vez que entras, así que no tienes que configurar nada. ¿Prefieres otro? Una pequeña *pastilla 🌐 de idioma* está en la esquina de cada pantalla antes de iniciar sesión — tócala para cambiar cuando quieras, y tu elección se guarda. | I9: Media | K9: lib/helpAboutContent.js
A10: AY-0009 | B10: Página de Ayuda | C10: sections[1].body[2] | D10: More interface languages are being added over time, and coverage keeps widening as native-language content fills in. | E10: Con el tiempo se irán agregando más idiomas de interfaz, y la cobertura se amplía a medida que se completa el contenido en cada idioma nativo. | I10: Media | K10: lib/helpAboutContent.js
A11: AY-0010 | B11: Página de Ayuda | C11: sections[2].title | D11: Choosing what to learn | E11: Elegir qué aprender | I11: Media | K11: lib/helpAboutContent.js
A12: AY-0011 | B12: Página de Ayuda | C12: sections[2].body[0] | D12: Your *native language* (set in Settings) decides which languages show up as bubbles to learn — you’ll see the languages available to learn from your own, and more language pairs keep getting added over time. Each bubble’s name shows in your native language too (e.g. you’d see “German” rather than “Deutsch”) — no need to recognize a language from its flag or name in its own script. Your *native country* is separate — it just personalizes the badge in the top icon row. | E12: Tu *idioma nativo* (que defines en Ajustes) decide qué idiomas aparecen como burbujas para aprender — verás los idiomas que puedes aprender desde el tuyo, y con el tiempo se agregan más pares de idiomas. El nombre de cada burbuja también aparece en tu idioma nativo (por ejemplo, verías “Alemán” y no “Deutsch”) — no hace falta reconocer un idioma por su bandera o por su nombre en su propia escritura. Tu *país de origen* es aparte — solo personaliza la insignia en la fila de íconos de arriba. | I12: Media | K12: lib/helpAboutContent.js
A13: AY-0012 | B13: Página de Ayuda | C13: sections[2].body[1] | D13: Each language bubble shows your current skill level and XP progress toward the next one. Tap any bubble to start practicing that language — progress is tracked independently per language. | E13: Cada burbuja de idioma muestra tu nivel actual y tu progreso de XP hacia el siguiente. Toca cualquier burbuja para empezar a practicar ese idioma — el progreso se guarda por separado para cada idioma. | I13: Media | K13: lib/helpAboutContent.js
... A111: AY-0110 | B111: Página Acerca de | C111: footer | D111: Questions about how something specific works? The {{help|Help page}} has a full walkthrough of every screen and icon. Found a bug, or have an idea? There’s a {{feedback|feedback form}} for that too. Know someone who’d like to {{beta|apply to beta test}}? | E111: ¿Dudas sobre cómo funciona algo específico? La {{help|página de Ayuda}} tiene un recorrido completo por cada pantalla e ícono. ¿Encontraste un error o tienes una idea? También hay un {{feedback|formulario de comentarios}} para eso. ¿Conoces a alguien que quiera {{beta|postularse como beta tester}}? | I111: Media | K111: lib/helpAboutContent.js

Sheet 8-Novedades
A1: ID | B1: Sección | C1: Clave / ubicación | D1: Inglés (referencia) | E1: Español actual | F1: VEREDICTO | G1: CORRECCIÓN SUGERIDA | H1: NOTA / MOTIVO | I1: Prioridad | J1: Nota del equipo | K1: Archivo
A2: NV-0001 | B2: v3.2.0 — 2026-07-27 | C2: v3.2.0 · bullet 1 | D2: Newest native language available: Portuguese. Set your native language to Portuguese and the whole app follows — the menus, Settings, sign-in and onboarding, the subtitle under each question, the answer choices, the explanations, the Word Bank and pronunciation practice, plus the Help and About pages. Portuguese speakers get 12 languages to study: Spanish (Latin America & Spain), French (France & Québec), Italian, German, Russian, Japanese, Korean and Mandarin, plus American and British English — each a full course, not a starter set. A card surfaces the Brazil↔Portugal differences (ônibus/autocarro, trem/comboio, tela/ecrã, geladeira/frigorífico) as they come up. | E2: Nuevo idioma nativo disponible: portugués. Elige el portugués como tu idioma nativo y toda la app te sigue: los menús, los Ajustes, el inicio de sesión y la bienvenida, el subtítulo debajo de cada pregunta, las opciones de respuesta, las explicaciones, el Banco de Palabras y la práctica de pronunciación, además de las páginas de Ayuda y Acerca de. Quienes hablan portugués tienen 12 idiomas para estudiar: español (Latinoamérica y España), francés (Francia y Quebec), italiano, alemán, ruso, japonés, coreano y mandarín, más inglés americano y británico, cada uno como un curso completo y no un conjunto inicial. Una tarjeta muestra las diferencias entre Brasil y Portugal (ônibus/autocarro, trem/comboio, tela/ecrã, geladeira/frigorífico) a medida que aparecen. | I2: Baja | K2: lib/version.js
A3: NV-0002 | B3: v3.2.0 — 2026-07-27 | C3: v3.2.0 · bullet 2 | D3: A new look: SquirreLingo now wears a friendly two-squirrel mascot logo — the same characters as the animated co-hosts — on the browser tab, the home-screen icon, link-share previews and inside the app itself, replacing the old pink squirrel mark. The pinks and purples across the app have been warmed to match it. | E3: Nueva imagen: SquirreLingo ahora luce un logo con la mascota de dos ardillas —los mismos personajes que los presentadores animados— en la pestaña del navegador, el ícono de la pantalla de inicio, las vistas previas de los enlaces que compartes y dentro de la propia app, reemplazando la antigua ardilla rosa. Los rosas y morados de toda la app se ajustaron a tonos más cálidos para que combinen. | I3: Baja | K3: lib/version.js
A4: NV-0003 | B4: v3.2.0 — 2026-07-27 | C4: v3.2.0 · bullet 3 | D4: Add SquirreLingo to your home screen and it now opens as a real app — its own icon, its own name, and no browser bars around it. | E4: Agrega SquirreLingo a tu pantalla de inicio y ahora se abre como una app de verdad: con su propio ícono, su propio nombre y sin las barras del navegador alrededor. | I4: Baja | K4: lib/version.js
A5: NV-0004 | B5: v3.2.0 — 2026-07-27 | C5: v3.2.0 · bullet 4 | D5: Other general bug fixes and code changes. | E5: Otros arreglos de errores y cambios de código. | I5: Baja | K5: lib/version.js
A6: NV-0005 | B6: v3.1.1 — 2026-07-26 | C6: v3.1.1 · bullet 1 | D6: Learning English is now a full course for Spanish speakers — the complete grammar set (hundreds of questions) plus both American and British English, so it matches every other language. | E6: Aprender inglés ahora es un curso completo para hispanohablantes: el conjunto completo de gramática (cientos de preguntas) más inglés americano y británico, para que esté a la par de los demás idiomas. | I6: Baja | K6: lib/version.js
A7: NV-0006 | B7: v3.1.1 — 2026-07-26 | C7: v3.1.1 · bullet 2 | D7: The slide-out menu and the “How to use SquirreLingo” walkthrough now appear fully in your native language — the last few labels and the walkthrough that still showed in English when set to Spanish are fixed. | E7: El menú lateral y el recorrido “Cómo usar SquirreLingo” ahora aparecen completamente en tu idioma nativo: se corrigieron las últimas etiquetas y el recorrido que todavía salían en inglés cuando estaba en español. | I7: Baja | K7: lib/version.js
A8: NV-0007 | B8: v3.1.1 — 2026-07-26 | C8: v3.1.1 · bullet 3 | D8: The card that shows how a word changes from country to country and region to region now covers more everyday words. | E8: La tarjeta que muestra cómo cambia una palabra de país en país y de región en región ahora cubre más palabras de uso diario. | I8: Baja | K8: lib/version.js
A9: NV-0008 | B9: v3.1.1 — 2026-07-26 | C9: v3.1.1 · bullet 4 | D9: Other general bug fixes and code changes. | E9: Otros arreglos de errores y cambios de código. | I9: Baja | K9: lib/version.js
A10: NV-0009 | B10: v3.1.0 — 2026-07-25 | C10: v3.1.0 · bullet 1 | D10: Newest native language available: Spanish. Set your native language to Spanish and the whole app adapts to it — the menus, Settings, sign-in and onboarding, the subtitle under each question, the answer choices, the explanations and the Word Bank all appear in your native language, on every language you can study. What you're learning still leads each question, so the immersion is unchanged — your native language now rides underneath instead of English. | E10: Nuevo idioma nativo disponible: español. Elige el español como tu idioma nativo y toda la app se adapta a ti: los menús, los Ajustes, el inicio de sesión y la bienvenida, el subtítulo debajo de cada pregunta, las opciones de respuesta, las explicaciones y el Banco de Palabras aparecen en tu idioma nativo, en cada idioma que estudies. Lo que estás aprendiendo sigue encabezando cada pregunta, así que la inmersión no cambia: ahora tu idioma nativo va por debajo en lugar del inglés. | I10: Baja | K10: lib/version.js
A11: NV-0010 | B11: v3.1.0 — 2026-07-25 | C11: v3.1.0 · bullet 2 | D11: SquirreLingo now detects your device's language when you first arrive and switches automatically, with a language switcher in the corner to change it whenever you like. | E11: Ahora SquirreLingo detecta el idioma de tu dispositivo la primera vez que entras y cambia solo, con un selector de idioma en la esquina para cambiarlo cuando quieras. | I11: Baja | K11: lib/version.js
A12: NV-0011 | B12: v3.1.0 — 2026-07-25 | C12: v3.1.0 · bullet 3 | D12: A new card shows how a word changes from country to country and region to region — highlighting the form used where you're from, and how it's said elsewhere. | E12: Una nueva tarjeta te muestra cómo cambia una palabra de país en país y de región en región, resaltando la forma que se usa de donde eres y cómo se dice en otros lugares. | I12: Baja | K12: lib/version.js
A13: NV-0012 | B13: v3.1.0 — 2026-07-25 | C13: v3.1.0 · bullet 4 | D13: Other general bug fixes and code changes. | E13: Otros arreglos de errores y cambios de código. | I13: Baja | K13: lib/version.js
... A185: NV-0184 | B185: v1.0.0 — 2026-07-05 | C185: v1.0.0 · bullet 7 | D185: "Don't repeat too soon" freshness rotation across questions | E185: Rotación de frescura entre preguntas del tipo "no repetir demasiado pronto" | I185: Baja | K185: lib/version.js
