Workbook

Sheet LÉEME
B1: SquirreLingo — Explicaciones en español (Español (Latinoamérica))
B2: En este archivo el español no es lo que se enseña: es la voz que EXPLICA otro idioma. Son los cursos de inglés para hispanohablantes, las glosas en español del Banco de Palabras de otros idiomas, y una muestra de la capa en español que acompaña a cada curso. Versión 3.2.0.
B4: Qué te estamos pidiendo
B5: • ¿La explicación en español es correcta sobre el idioma que describe?
B6: • ¿Suena natural, o se nota traducida del inglés?
B7: • En las glosas del Banco de Palabras: ¿es la mejor palabra en español para ese significado?
B8: • Una explicación puede estar en español impecable y aun así decir algo falso sobre el inglés. Si ves un error de contenido, dilo: nos sirve tanto como el de idioma.
B10: Si no dominas el idioma del curso
B11: • No hace falta que sepas japonés o ruso. La columna de referencia en inglés te dice qué debería significar la palabra; tú juzgas si la glosa en español lo dice bien. Si no te alcanza el contexto, marca DUDA y seguimos nosotros.
B13: Cómo llenar el archivo
B14: 1. Revisa una pestaña a la vez. El orden sugerido está en la pestaña RESUMEN.
B15: 2. En cada fila hay una columna VEREDICTO con un menú desplegable. Elige un valor:
... B22: Ejemplo de una fila bien llenada
B23: Glosa en español | C23: VEREDICTO | D23: CORRECCIÓN SUGERIDA | E23: NOTA / MOTIVO
B24: hora; clase | C24: CAMBIAR | D24: hora (de reloj); clase (lección) | E24: «hora; clase» sin aclaración es ambiguo — parecen dos cosas sin relación. Conviene marcar cuál es cuál.
B27: Sobre la pestaña de muestra
B28: • Trae unas 40 preguntas por idioma de unas 13.974 en total. Sirve para detectar problemas que se repiten. Si ves un patrón, señálalo UNA vez en la nota: lo arreglamos en todo el corpus, no solo en esa fila.
B30: Al terminar
B31: Llena tu nombre y la fecha en la pestaña RESUMEN y devuelve este mismo archivo .xlsx.

Sheet RESUMEN
B2: Resumen y firma de la revisión — Español (Latinoamérica) · Explicaciones en español
B3: El español que explica OTROS idiomas
B5: Nombre de quien revisa:
B6: País / región de origen:
B7: Fecha de entrega:
B8: ¿Doy el visto bueno general?
A11: Orden | B11: Pestaña | C11: Qué contiene | D11: Filas | E11: OK | F11: CAMBIAR | G11: DUDA | H11: Sin revisar
A12: 1 | B12: 1-Preguntas | C12: Cada pregunta completa: enunciado, respuesta correcta, opciones incorrectas y explicación. | D12: 1548 | E12: =COUNTIF('1-Preguntas'!$L$2:$L$1549,"OK") -> 0 | F12: =COUNTIF('1-Preguntas'!$L$2:$L$1549,"CAMBIAR") -> 0 | G12: =COUNTIF('1-Preguntas'!$L$2:$L$1549,"DUDA") -> 0 | H12: =D12-E12-F12-G12 -> 1548
A13: 2 | B13: 2-Pronunciación | C13: Ejercicios de pronunciación: frase, respelling y pares mínimos. | D13: 156 | E13: =COUNTIF('2-Pronunciación'!$K$2:$K$157,"OK") -> 0 | F13: =COUNTIF('2-Pronunciación'!$K$2:$K$157,"CAMBIAR") -> 0 | G13: =COUNTIF('2-Pronunciación'!$K$2:$K$157,"DUDA") -> 0 | H13: =D13-E13-F13-G13 -> 156
A14: 3 | B14: 3-Banco-de-palabras | C14: El Banco de Palabras — vocabulario de alta frecuencia. | D14: 2768 | E14: =COUNTIF('3-Banco-de-palabras'!$G$2:$G$2769,"OK") -> 0 | F14: =COUNTIF('3-Banco-de-palabras'!$G$2:$G$2769,"CAMBIAR") -> 0 | G14: =COUNTIF('3-Banco-de-palabras'!$G$2:$G$2769,"DUDA") -> 0 | H14: =D14-E14-F14-G14 -> 2768
A15: 4 | B15: 4-Muestra-explicaciones | C15: Muestra de la capa en español sobre los cursos de otros idiomas. | D15: 400 | E15: =COUNTIF('4-Muestra-explicaciones'!$G$2:$G$401,"OK") -> 0 | F15: =COUNTIF('4-Muestra-explicaciones'!$G$2:$G$401,"CAMBIAR") -> 0 | G15: =COUNTIF('4-Muestra-explicaciones'!$G$2:$G$401,"DUDA") -> 0 | H15: =D15-E15-F15-G15 -> 400
A16: 5 | B16: 5-Decisiones | C16: Decisiones que tomamos a propósito y necesitan tu opinión. | D16: 6 | E16: =COUNTIF('5-Decisiones'!$E$2:$E$7,"APRUEBO") -> 0 | F16: =COUNTIF('5-Decisiones'!$E$2:$E$7,"CAMBIAR") -> 0 | G16: =COUNTIF('5-Decisiones'!$E$2:$E$7,"DUDA") -> 0 | H16: =D16-E16-F16-G16 -> 6
C17: TOTAL | D17: =SUM(D12:D16) -> 4878 | E17: =SUM(E12:E16) -> 0 | F17: =SUM(F12:F16) -> 0 | G17: =SUM(G12:G16) -> 0 | H17: =SUM(H12:H16) -> 4878
B19: «Sin revisar» baja a cero solo cuando cada fila tiene un veredicto. No hace falta llegar a cero para devolvernos el archivo: manda lo que tengas y seguimos desde ahí.

Sheet 1-Preguntas
A1: ID | B1: Curso | C1: Categoría | D1: Nivel | E1: Clave | F1: Enunciado | G1: Respuesta correcta | H1: Opciones incorrectas | I1: Explicación en español | J1: Explicación en inglés (referencia) | K1: Notas de las opciones | L1: VEREDICTO | M1: CORRECCIÓN SUGERIDA | N1: NOTA / MOTIVO | O1: Archivo
A2: PR-0001 | B2: enUsForEs | C2: vocab | D2: A2 | E2: vocab[0] | F2: 'Boring' se traduce como... | G2: aburrido (que causa aburrimiento) | H2: aburrido (que siente aburrimiento) · aburridor · abrumador | I2: 'Boring' describe algo que CAUSA aburrimiento (una película boring). 'Bored' describe a la persona que lo SIENTE. | J2: 'Boring' describes something that CAUSES boredom (a boring movie). 'Bored' describes the person who FEELS it. | O2: data/tracks/enUsForEs.js
A3: PR-0002 | B3: enUsForEs | C3: vocab | D3: A2 | E3: vocab[1] | F3: 'I am bored' significa... | G3: estoy aburrido (lo siento) | H3: soy aburrido (aburro a otros) · soy aburridor · estoy aburriendo | I3: 'Bored' (-ed) es lo que SIENTES. Úsalo para ti: 'I am bored'. No lo confundas con 'boring' (-ing). | J3: 'Bored' (-ed) is how you FEEL. Use it for yourself: 'I am bored.' Don't confuse with 'boring' (-ing). | O3: data/tracks/enUsForEs.js
A4: PR-0003 | B4: enUsForEs | C4: vocab | D4: A2 | E4: vocab[2] | F4: 'Fun' (como en 'The party was fun') se traduce como... | G4: divertido (agradable) | H4: chistoso / gracioso · raro · aburrido | I4: 'Fun' = entretenido, que se disfruta. 'Funny' = que da risa. Una fiesta es 'fun', no 'funny'. | J4: 'Fun' = enjoyable, a good time. 'Funny' = causing laughter. A party is fun, not funny. | O4: data/tracks/enUsForEs.js
A5: PR-0004 | B5: enUsForEs | C5: vocab | D5: A2 | E5: vocab[3] | F5: 'Funny' se traduce como... | G5: chistoso / gracioso (da risa) | H5: divertido (entretenido) · extraño solamente · aburrido | I5: 'Funny' te hace reír (un chiste funny). También puede significar 'extraño', pero nunca 'entretenido' — eso es 'fun'. | J5: 'Funny' makes you laugh (a funny joke). It can also mean 'strange', but never 'entertaining' — that's 'fun'. | O5: data/tracks/enUsForEs.js
A6: PR-0005 | B6: enUsForEs | C6: vocab | D6: A2 | E6: vocab[4] | F6: 'You did a good job' — la palabra 'good' es un... | G6: adjetivo (describe un sustantivo) | H6: adverbio (describe un verbo) · verbo · preposición | I6: 'Good' es adjetivo; describe sustantivos (a good job). Para describir CÓMO haces algo, usa el adverbio 'well'. | J6: 'Good' is an adjective; it describes nouns (a good job). To describe how you DO something, use the adverb 'well'. | O6: data/tracks/enUsForEs.js
A7: PR-0006 | B7: enUsForEs | C7: vocab | D7: A2 | E7: vocab[5] | F7: 'Ella canta bien' se traduce como 'She sings...' | G7: well | H7: good · goodly · nicely good | I7: Usa el adverbio 'well' para describir una acción: 'She sings well'. 'She sings good' es un error frecuente. | J7: Use the adverb 'well' to describe an action: 'She sings well.' 'She sings good' is a common error. | O7: data/tracks/enUsForEs.js
A8: PR-0007 | B8: enUsForEs | C8: vocab | D8: B1 | E8: vocab[6] | F8: En '¿Cómo estás?' → 'I'm well', la palabra 'well' aquí significa... | G8: bien (de salud) | H8: el pozo de agua · bueno (bondadoso) · muy | I8: Tras 'to be' sobre salud, 'well' significa estar sano. 'I'm good' también se acepta en inglés americano informal. | J8: After 'to be' about health, 'well' means in good health. 'I'm good' is also accepted in casual American English. | O8: data/tracks/enUsForEs.js
A9: PR-0008 | B9: enUsForEs | C9: vocab | D9: A2 | E9: vocab[7] | F9: 'This test is hard' — 'hard' aquí significa... | G9: difícil | H9: apenas · casi · suave | I9: Como adjetivo, 'hard' significa difícil (o duro/firme). No lo confundas con el adverbio 'hardly'. | J9: As an adjective, 'hard' means difficult (or firm). Don't confuse it with the adverb 'hardly'. | O9: data/tracks/enUsForEs.js
A10: PR-0009 | B10: enUsForEs | C10: vocab | D10: B1 | E10: vocab[8] | F10: 'He works hard' significa... | G10: trabaja duro (con esfuerzo) | H10: casi no trabaja · trabaja difícilmente · trabaja apenas | I10: 'Hard' también es adverbio y significa 'con mucho esfuerzo'. 'He works hard' = trabaja mucho. | J10: 'Hard' is also an adverb meaning 'with a lot of effort'. 'He works hard' = trabaja mucho. | O10: data/tracks/enUsForEs.js
A11: PR-0010 | B11: enUsForEs | C11: vocab | D11: B1 | E11: vocab[9] | F11: 'She hardly works' significa... | G11: casi no trabaja | H11: trabaja duro · trabaja difícilmente · trabaja mucho | I11: ¡Trampa! 'Hardly' significa 'casi no / apenas', no 'duro'. 'She hardly works' = casi no trabaja. | J11: Trap! 'Hardly' means 'almost not / barely', not 'hard'. 'She hardly works' = casi no trabaja. | O11: data/tracks/enUsForEs.js
A12: PR-0011 | B12: enUsForEs | C12: vocab | D12: A2 | E12: vocab[10] | F12: 'The store is near' — 'near' aquí significa... | G12: cerca | H12: casi · lejos · cercano de tiempo | I12: 'Near' significa cerca en distancia. No lo confundas con 'nearly' = casi. | J12: 'Near' means close in distance (cerca). Don't confuse it with 'nearly' = casi. | O12: data/tracks/enUsForEs.js
A13: PR-0012 | B13: enUsForEs | C13: vocab | D13: B1 | E13: vocab[11] | F13: 'I nearly fell' significa... | G13: casi me caigo | H13: me caí cerca · me caí de verdad · me caigo a menudo | I13: 'Nearly' significa 'casi'. 'I nearly fell' = casi me caigo, pero no. No es lo mismo que 'near'. | J13: 'Nearly' means 'almost' (casi). 'I nearly fell' = casi me caigo, but I didn't. Not the same as 'near'. | O13: data/tracks/enUsForEs.js
... A1549: PR-1548 | B1549: enGbForEs | C1549: trad | D1549: C1 | E1549: trad[121] | F1549: Translate: 'Bueno, no te entretengo más.' (para cerrar una charla) | G1549: Right, I'll let you get on. | H1549: Well, I don't entertain you more. · Good, I won't detain you further, then. · So, I stop bothering you now, ok. | I1549: 'I'll let you get on' señala con cortesía que terminas la charla para que la otra persona siga a lo suyo. | J1549: 'I'll let you get on' politely signals you're ending the conversation so they can carry on. | O1549: data/tracks/enGbForEs.js

Sheet 2-Pronunciación
A1: ID | B1: Curso | C1: Clave | D1: Nivel | E1: Frase | F1: Pronunciación escrita | G1: Respuesta correcta | H1: Opciones incorrectas | I1: Explicación en español | J1: Pares mínimos | K1: VEREDICTO | L1: CORRECCIÓN SUGERIDA | M1: NOTA / MOTIVO | N1: Archivo
A2: FO-001 | B2: enUsForEs | C2: FONO_BANK[0] | D2: A1 | E2: I need a glass of water. | F2: eye NEED-uh GLASS-uh WAH-der | G2: I need a glass of water. | H2: I need a glass of wonder. · I need a class of water. · I need a glass of water? | I2: En el inglés americano la T entre vocales en 'water' se suaviza a un golpe rápido parecido a la D, por eso suena 'WAH-der'. | N2: data/tracks/enUsForEs.js
A3: FO-002 | B3: enUsForEs | C3: FONO_BANK[1] | D3: A2 | E3: This one is better than that one. | F3: this WUN-iz BED-er than THAT-wun | G3: This one is better than that one. | H3: This one is bedder than that one. · This one is butter than that one. · This one is better than that phone. | I3: La doble T en 'better' se convierte en un sonido de D golpeada, por eso se pronuncia 'BED-er'. | N3: data/tracks/enUsForEs.js
A4: FO-003 | B4: enUsForEs | C4: FONO_BANK[2] | D4: A2 | E4: What are you doing later? | F4: wuh-duh-yuh DOO-in LAY-der | G4: What are you doing later? | H4: What are you doing lately? · Water you doing later? · What do you do later? | I4: 'What are you' se fusiona en 'wuh-duh-yuh' con Ts golpeadas, y 'later' se vuelve 'LAY-der'. | N4: data/tracks/enUsForEs.js
A5: FO-004 | B5: enUsForEs | C5: FONO_BANK[3] | D5: B1 | E5: Let it go, it doesn't matter. | F5: LEH-diht GOH it DUZ-unt MAD-er | G5: Let it go, it doesn't matter. | H5: Let it go, it doesn't madder. · Led it go, it doesn't matter. · Let it go, it doesn't matter? | I5: 'Let it' se golpea en 'LEH-diht' y 'matter' se vuelve 'MAD-er' porque las Ts caen entre vocales. | N5: data/tracks/enUsForEs.js
A6: FO-005 | B6: enUsForEs | C6: FONO_BANK[4] | D6: B1 | E6: I got a lot of it done. | F6: eye GAH-duh LAH-duv it DUN | G6: I got a lot of it done. | H6: I got a lot of it dumb. · I gotta lot of it done. · I got a lodda it done. | I6: 'Got a' y 'lot of' se golpean en 'GAH-duh' y 'LAH-duv', encadenando las palabras. | N6: data/tracks/enUsForEs.js
A7: FO-006 | B7: enUsForEs | C7: FONO_BANK[5] | D7: B1 | E7: Turn it off and on again. | F7: TUR-nih-DAWF and AWN uh-GEN | G7: Turn it off and on again. | H7: Turn it off in an engine. · Turn it off and on a gun. · Turn it up and on again. | I7: 'Turn it off' se enlaza en 'TUR-nih-DAWF' cuando las consonantes finales se conectan con las vocales siguientes. | N7: data/tracks/enUsForEs.js
A8: FO-007 | B8: enUsForEs | C8: FONO_BANK[6] | D8: B1 | E8: Can I get a little bit of butter? | F8: kn-eye GEH-duh LIH-dul BIH-duv BUH-der | G8: Can I get a little bit of butter? | H8: Can I get a little bit of batter? · Can I get a little bit of bother? · Can I get a little bit of water? | I8: 'Little', 'bit of' y 'butter' golpean todas sus Ts en sonidos parecidos a la D entre vocales. | N8: data/tracks/enUsForEs.js
A9: FO-008 | B9: enUsForEs | C9: FONO_BANK[7] | D9: A2 | E9: Put it on the table. | F9: PUH-dih-DAWN thuh TAY-bul | G9: Put it on the table. | H9: Put it on the stable. · Put it on the cable. · Put it in the table. | I9: 'Put it on' se enlaza y golpea en 'PUH-dih-DAWN', con las Ts volviéndose golpes rápidos de D. | N9: data/tracks/enUsForEs.js
A10: FO-009 | B10: enUsForEs | C10: FONO_BANK[8] | D10: B2 | E10: He's coming out of it slowly. | F10: heez KUH-min OW-duv it SLOH-lee | G10: He's coming out of it slowly. | H10: He's coming out of its holy. · He's coming out of a slowly. · He's coming out of it slower. | I10: 'Out of it' se enlaza en 'OW-duv it' con la T golpeada conectando las palabras. | N10: data/tracks/enUsForEs.js
A11: FO-010 | B11: enUsForEs | C11: FONO_BANK[9] | D11: B1 | E11: That's a lot better already. | F11: thats-uh LAH BED-er awl-REH-dee | G11: That's a lot better already. | H11: That's a lot bedder already. · That's a lot better all ready. · That's a lot batter already. | I11: 'Lot better' se golpea en 'LAH BED-er', con la T final de 'lot' suavizada antes de la siguiente palabra. | N11: data/tracks/enUsForEs.js
A12: FO-011 | B12: enUsForEs | C12: FONO_BANK[10] | D12: B1 | E12: I'll pick it up in a minute. | F12: aisl PIH-kih-DUP in-uh MIH-nut | G12: I'll pick it up in a minute. | H12: I'll pick it up in a minit. · I'll pick a cup in a minute. · I'll pick it up in a bit. | I12: 'Pick it up' se enlaza en 'PIH-kih-DUP' cuando cada consonante final se une a la siguiente vocal. | N12: data/tracks/enUsForEs.js
A13: FO-012 | B13: enUsForEs | C13: FONO_BANK[11] | D13: B1 | E13: What time did you get in? | F13: wuh-TYME did-juh geh-DIN | G13: What time did you get in? | H13: What time did you get him? · What time do you get in? · What time did you begin? | I13: 'Get in' se enlaza y golpea en 'geh-DIN', uniendo las palabras con una D suave. | N13: data/tracks/enUsForEs.js
... A157: FO-156 | B157: enGbForEs | C157: FONO_BANK[78] | D157: C2 | E157: The banana is over ripe. | F157: thuh buh-NAH-nuh-riz OH-vuh RYP | G157: The banana is over ripe. | H157: The banana rise over ripe. · The banana is over right. · The banana is over wiped. | I157: Una R intrusiva enlaza 'banana' e 'is' como 'buh-NAH-nuh-riz', mientras 'over' pierde su propia R. | N157: data/tracks/enGbForEs.js

Sheet 3-Banco-de-palabras
A1: ID | B1: Clave | C1: Palabra del curso | D1: Significado en inglés (referencia) | E1: Glosa en español | F1: Nivel | G1: VEREDICTO | H1: GLOSA CORREGIDA | I1: NOTA / MOTIVO | J1: Archivo
A2: BP-0001 | B2: [0] | C2: die Zeit | D2: time | E2: tiempo | F2: A1 | J2: data/vocab/deWords.es.js
A3: BP-0002 | B3: [1] | C3: das Jahr | D3: year | E3: año | F3: A1 | J3: data/vocab/deWords.es.js
A4: BP-0003 | B4: [2] | C4: der Tag | D4: day | E4: día | F4: A1 | J4: data/vocab/deWords.es.js
A5: BP-0004 | B5: [3] | C5: die Woche | D5: week | E5: semana | F5: A1 | J5: data/vocab/deWords.es.js
A6: BP-0005 | B6: [4] | C6: der Monat | D6: month | E6: mes | F6: A1 | J6: data/vocab/deWords.es.js
A7: BP-0006 | B7: [5] | C7: die Stunde | D7: hour; lesson | E7: hora; clase | F7: A1 | J7: data/vocab/deWords.es.js
A8: BP-0007 | B8: [6] | C8: die Nacht | D8: night | E8: noche | F8: A1 | J8: data/vocab/deWords.es.js
A9: BP-0008 | B9: [7] | C9: der Morgen | D9: morning | E9: mañana | F9: A1 | J9: data/vocab/deWords.es.js
A10: BP-0009 | B10: [8] | C10: der Abend | D10: evening | E10: tarde-noche | F10: A1 | J10: data/vocab/deWords.es.js
A11: BP-0010 | B11: [9] | C11: der Mann | D11: man; husband | E11: hombre; esposo | F11: A1 | J11: data/vocab/deWords.es.js
A12: BP-0011 | B12: [10] | C12: die Frau | D12: woman; wife; Mrs. | E12: mujer; esposa; señora | F12: A1 | J12: data/vocab/deWords.es.js
A13: BP-0012 | B13: [11] | C13: das Kind | D13: child | E13: niño | F13: A1 | J13: data/vocab/deWords.es.js
... A2769: BP-2768 | B2769: [620] | C2769: 姑且 (gūqiě) | D2769: for the moment/tentatively | E2769: por el momento/tentativamente | F2769: C2 | J2769: data/vocab/zhWords.es.js

Sheet 4-Muestra-explicaciones
A1: ID | B1: Idioma del curso | C1: Clave | D1: Enunciado en español | E1: Opciones de respuesta | F1: Notas de explicación | G1: VEREDICTO | H1: CORRECCIÓN SUGERIDA | I1: NOTA / MOTIVO | J1: Archivo
A2: MC-0001 | B2: deForEn | C2: fvocab-31 | D2: ¿Cómo se dice 'calle' en alemán? | J2: data/tracks/l10n/deForEn.es.js
A3: MC-0002 | B3: deForEn | C3: fvocab-95 | D3: ¿Cómo se dice 'libro' en alemán? | J3: data/tracks/l10n/deForEn.es.js
A4: MC-0003 | B4: deForEn | C4: fvocab-159 | D4: ¿Cómo se dice 'correcto' en alemán? | J4: data/tracks/l10n/deForEn.es.js
A5: MC-0004 | B5: deForEn | C5: fvocab-222 | D5: 'das Ziel' significa... | E5: meta; destino · ayuda · mensaje; noticia · licencia de conducir | J5: data/tracks/l10n/deForEn.es.js
A6: MC-0005 | B6: deForEn | C6: fvocab-286 | D6: 'laut' significa... | E6: ruidoso · pesado; difícil · importante · interesante | J6: data/tracks/l10n/deForEn.es.js
A7: MC-0006 | B7: deForEn | C7: fvocab-350 | D7: 'der Vorteil' significa... | E7: ventaja · orden; limpieza · boda · esperanza | J7: data/tracks/l10n/deForEn.es.js
A8: MC-0007 | B8: deForEn | C8: fvocab-414 | D8: 'gelingen' significa... | E8: salir bien · tener lugar · alcanzar; lograr · mejorar | J8: data/tracks/l10n/deForEn.es.js
A9: MC-0008 | B9: deForEn | C9: fvocab-477 | D9: ¿Cómo se dice 'simplemente; pues' en alemán? | J9: data/tracks/l10n/deForEn.es.js
A10: MC-0009 | B10: deForEn | C10: fvocab-541 | D10: ¿Cómo se dice 'resultar (ser)' en alemán? | J10: data/tracks/l10n/deForEn.es.js
A11: MC-0010 | B11: deForEn | C11: fvocab-605 | D11: ¿Cómo se dice 'persona de contacto' en alemán? | J11: data/tracks/l10n/deForEn.es.js
A12: MC-0011 | B12: deForEn | C12: gram-24 | D12: ___ niños están jugando en el jardín. | J12: data/tracks/l10n/deForEn.es.js
A13: MC-0012 | B13: deForEn | C13: gram-74 | D13: Él trabaja _____ ganar dinero. ('para') | J13: data/tracks/l10n/deForEn.es.js
A14: MC-0013 | B14: deForEn | C14: gram-123 | D14: Todavía tengo que aprender mucho. (modal + infinitivo) | J14: data/tracks/l10n/deForEn.es.js
A15: MC-0014 | B15: deForEn | C15: gram-172 | D15: Tengo un amigo. (objeto acusativo) | J15: data/tracks/l10n/deForEn.es.js
A16: MC-0015 | B16: deForEn | C16: gram-222 | D16: El agua fresca sabe rico. | J16: data/tracks/l10n/deForEn.es.js
A17: MC-0016 | B17: deForEn | C17: gram-271 | D17: ___ (oír) | J17: data/tracks/l10n/deForEn.es.js
A18: MC-0017 | B18: deForEn | C18: gram-321 | D18: He ___ (hablar). | J18: data/tracks/l10n/deForEn.es.js
A19: MC-0018 | B19: deForEn | C19: gram-370 | D19: Ayer él ___ (leer). | J19: data/tracks/l10n/deForEn.es.js
A20: MC-0019 | B20: deForEn | C20: gram-419 | D20: Voy a la escuela. (movimiento) | J20: data/tracks/l10n/deForEn.es.js
... A31: MC-0030 | B31: deForEn | C31: trad-128 | D31: Traducir: 'La necesidad es la madre del ingenio.' | J31: data/tracks/l10n/deForEn.es.js
A32: MC-0031 | B32: deForEn | C32: vocab-6 | D32: 'Gift' significa... | E32: veneno · un regalo · talento · medicina | J32: data/tracks/l10n/deForEn.es.js
A33: MC-0032 | B33: deForEn | C33: vocab-20 | D33: 'Der Feierabend' significa... | E33: el fin de la jornada laboral · una tarde festiva · una fiesta de celebración · el viernes por la noche | J33: data/tracks/l10n/deForEn.es.js
A34: MC-0033 | B34: deForEn | C34: vocab-33 | D34: 'Die Stadt' significa... | E34: ciudad/pueblo · aldea · país · plaza | J34: data/tracks/l10n/deForEn.es.js
A35: MC-0034 | B35: deForEn | C35: vocab-46 | D35: 'Der Ausweis' significa... | E35: documento de identidad · solo un pasaporte · un boleto · un recibo | J35: data/tracks/l10n/deForEn.es.js
A36: MC-0035 | B36: deForEn | C36: vocab-60 | D36: 'Die Panne' significa... | E36: una avería o percance · una llanta de repuesto · un atasco de tráfico · una reparación | J36: data/tracks/l10n/deForEn.es.js
A37: MC-0036 | B37: deForEn | C37: vocab-73 | D37: 'die Brücke' significa... | E37: puente · torre · túnel · pared | J37: data/tracks/l10n/deForEn.es.js
A38: MC-0037 | B38: deForEn | C38: vocab-87 | D38: 'der Regen' significa... | E38: lluvia · nieve · viento · trueno | J38: data/tracks/l10n/deForEn.es.js
A39: MC-0038 | B39: deForEn | C39: vocab-100 | D39: 'die Umfrage' significa... | E39: encuesta · rumor · respuesta · queja | J39: data/tracks/l10n/deForEn.es.js
A40: MC-0039 | B40: deForEn | C40: vocab-113 | D40: 'der Anspruch' significa... | E40: derecho (a algo) · disculpa · acuerdo · negativa | J40: data/tracks/l10n/deForEn.es.js
A41: MC-0040 | B41: deForEn | C41: vocab-127 | D41: 'die Zwangslage' significa... | E41: aprieto/situación difícil · oportunidad · celebración · acuerdo | J41: data/tracks/l10n/deForEn.es.js
A42: MC-0041 | B42: frCaForEn | C42: fvocab-31 | D42: ¿Cómo se dice 'minuto' en francés? | J42: data/tracks/l10n/frCaForEn.es.js
A43: MC-0042 | B43: frCaForEn | C43: fvocab-95 | D43: ¿Cómo se dice 'sal' en francés? | J43: data/tracks/l10n/frCaForEn.es.js
A44: MC-0043 | B44: frCaForEn | C44: fvocab-159 | D44: ¿Cómo se dice 'difícil' en francés? | J44: data/tracks/l10n/frCaForEn.es.js
A45: MC-0044 | B45: frCaForEn | C45: fvocab-222 | D45: 'La sacoche' significa... | E45: bolso; cartera · río · tormenta · número (cantidad) | J45: data/tracks/l10n/frCaForEn.es.js
A46: MC-0045 | B46: frCaForEn | C46: fvocab-286 | D46: 'Envoyer' significa... | E46: enviar · volver a casa; entrar de nuevo · vender · bajar | J46: data/tracks/l10n/frCaForEn.es.js
A47: MC-0046 | B47: frCaForEn | C47: fvocab-349 | D47: ¿Cómo se dice 'viaje' en francés? | J47: data/tracks/l10n/frCaForEn.es.js
A48: MC-0047 | B48: frCaForEn | C48: fvocab-413 | D48: ¿Cómo se dice 'seguir' en francés? | J48: data/tracks/l10n/frCaForEn.es.js
A49: MC-0048 | B49: frCaForEn | C49: fvocab-477 | D49: ¿Cómo se dice 'tarde (con retraso)' en francés? | J49: data/tracks/l10n/frCaForEn.es.js
A50: MC-0049 | B50: frCaForEn | C50: fvocab-540 | D50: 'Prévoir' significa... | E50: prever; planificar · posponer; aplazar · pelear; discutir · llevar a cabo; lograr | J50: data/tracks/l10n/frCaForEn.es.js
...

Sheet 5-Decisiones
A1: ID | B1: Tema | C1: Qué decidimos y por qué | D1: Ejemplo / dónde | E1: DECISIÓN | F1: ALTERNATIVA PROPUESTA | G1: NOTA
A2: DEC-01 | B2: Qué estamos preguntando aquí | C2: Aquí el español no es lo que se enseña: es la voz que EXPLICA otro idioma. Lo que revisas es si la explicación en español es correcta y natural. | D2: Cursos de inglés para hispanohablantes · glosas del Banco de Palabras de alemán, japonés, coreano, ruso y chino
A3: DEC-02 | B3: Necesitamos las dos cosas | C3: Una explicación puede estar en español impecable y aun así ser falsa sobre el inglés o el alemán. Si detectas un error de contenido, dilo: es tan útil como el de idioma. | D3: «'Boring' se traduce como aburrido (que causa aburrimiento)»
A4: DEC-03 | B4: Glosas del Banco de Palabras | C4: Son traducciones de una sola palabra. La columna de en medio trae la palabra original y su significado en inglés como referencia; la glosa en español es lo que revisas. | D4: die Zeit (time) → «tiempo»
A5: DEC-04 | B5: Registro | C5: «tú» informal, igual que en el resto de la app. | D5: «¿Cómo se dice…?»
A6: DEC-05 | B6: Muestra, no revisión exhaustiva | C6: La pestaña de muestra trae unas 40 preguntas por idioma de unas 13.974 en total. Buscamos problemas que se repitan. Si ves un patrón, señálalo UNA vez y lo arreglamos en todo el corpus. | D6: Pestaña 4-Muestra-explicaciones
A7: DEC-06 | B7: Idiomas que quizá no domines | C7: No hace falta que sepas japonés o ruso para revisar la glosa en español: la referencia en inglés te dice qué debería significar. Si no te alcanza el contexto, marca DUDA. | D7: Glosas de jaWords, koWords, ruWords, zhWords
