Workbook

Sheet LÉEME
B1: SquirreLingo — Contenido enseñado en español (Español (Latinoamérica))
B2: Este archivo es el español que la app ENSEÑA: las preguntas, las respuestas, las explicaciones y el vocabulario del curso de español para personas angloparlantes, en la versión 3.2.0. Es distinto del paquete de interfaz: aquí un error no incomoda, enseña mal.
B4: Qué te estamos pidiendo
B5: • ¿La respuesta marcada como correcta es correcta?
B6: • ¿Alguna de las opciones incorrectas también podría ser válida? Si es así, la pregunta está rota aunque la respuesta marcada sea buena. Esto es lo más valioso que puedes encontrar.
B7: • ¿La explicación en español dice algo cierto y útil, y suena natural?
B8: • ¿El nivel (A1–C2) está bien puesto para esa pregunta?
B10: Variedad
B11: • Español latinoamericano neutro: seseo, yeísmo, sin vosotros. Donde hay divergencia regional, el curso la enseña como contenido en vez de esconderla (carro/coche, celular/móvil, jugo/zumo).
B12: • Las explicaciones y las notas del Banco de Palabras están en INGLÉS a propósito: quien estudia este curso habla inglés. Revisa que el dato sea correcto, no que esté traducido.
B14: Cómo llenar el archivo
B15: 1. Revisa una pestaña a la vez. El orden sugerido está en la pestaña RESUMEN.
... B27: Ejemplo de una fila bien llenada
B28: Enunciado | C28: VEREDICTO | D28: CORRECCIÓN SUGERIDA | E28: NOTA / MOTIVO
B29: ¿Cómo se dice 'window' en español? | C29: CAMBIAR | D29: Cambiar 'el suelo' por 'la pared' | E29: 'el suelo' funciona, pero 'la pared' contrasta mejor con 'la ventana'. La explicación en español además es circular: dice «'la puerta' es puerta».
B32: Al terminar
B33: Llena tu nombre y la fecha en la pestaña RESUMEN y devuelve este mismo archivo .xlsx.

Sheet RESUMEN
B2: Resumen y firma de la revisión — Español (Latinoamérica) · Contenido enseñado
B3: El español que la app le enseña a quien lo está aprendiendo
B5: Nombre de quien revisa:
B6: País / región de origen:
B7: Fecha de entrega:
B8: ¿Doy el visto bueno general?
A11: Orden | B11: Pestaña | C11: Qué contiene | D11: Filas | E11: OK | F11: CAMBIAR | G11: DUDA | H11: Sin revisar
A12: 1 | B12: 1-Preguntas | C12: Cada pregunta completa: enunciado, respuesta correcta, opciones incorrectas y explicación. | D12: 665 | E12: =COUNTIF('1-Preguntas'!$L$2:$L$666,"OK") -> 0 | F12: =COUNTIF('1-Preguntas'!$L$2:$L$666,"CAMBIAR") -> 0 | G12: =COUNTIF('1-Preguntas'!$L$2:$L$666,"DUDA") -> 0 | H12: =D12-E12-F12-G12 -> 665
A13: 2 | B13: 2-Pronunciación | C13: Ejercicios de pronunciación: frase, respelling y pares mínimos. | D13: 79 | E13: =COUNTIF('2-Pronunciación'!$K$2:$K$80,"OK") -> 0 | F13: =COUNTIF('2-Pronunciación'!$K$2:$K$80,"CAMBIAR") -> 0 | G13: =COUNTIF('2-Pronunciación'!$K$2:$K$80,"DUDA") -> 0 | H13: =D13-E13-F13-G13 -> 79
A14: 3 | B14: 3-Banco-de-palabras | C14: El Banco de Palabras — vocabulario de alta frecuencia. | D14: 609 | E14: =COUNTIF('3-Banco-de-palabras'!$H$2:$H$610,"OK") -> 0 | F14: =COUNTIF('3-Banco-de-palabras'!$H$2:$H$610,"CAMBIAR") -> 0 | G14: =COUNTIF('3-Banco-de-palabras'!$H$2:$H$610,"DUDA") -> 0 | H14: =D14-E14-F14-G14 -> 609
A15: 4 | B15: 4-Decisiones | C15: Decisiones que tomamos a propósito y necesitan tu opinión. | D15: 8 | E15: =COUNTIF('4-Decisiones'!$E$2:$E$9,"APRUEBO") -> 0 | F15: =COUNTIF('4-Decisiones'!$E$2:$E$9,"CAMBIAR") -> 0 | G15: =COUNTIF('4-Decisiones'!$E$2:$E$9,"DUDA") -> 0 | H15: =D15-E15-F15-G15 -> 8
C16: TOTAL | D16: =SUM(D12:D15) -> 1361 | E16: =SUM(E12:E15) -> 0 | F16: =SUM(F12:F15) -> 0 | G16: =SUM(G12:G15) -> 0 | H16: =SUM(H12:H15) -> 1361
B18: «Sin revisar» baja a cero solo cuando cada fila tiene un veredicto. No hace falta llegar a cero para devolvernos el archivo: manda lo que tengas y seguimos desde ahí.

Sheet 1-Preguntas
A1: ID | B1: Curso | C1: Categoría | D1: Nivel | E1: Clave | F1: Enunciado | G1: Respuesta correcta | H1: Opciones incorrectas | I1: Explicación en español | J1: Explicación en inglés (referencia) | K1: Notas de las opciones | L1: VEREDICTO | M1: CORRECCIÓN SUGERIDA | N1: NOTA / MOTIVO | O1: Archivo
A2: PR-0001 | B2: esForEn | C2: vocab | D2: A2 | E2: vocab[0] | F2: ¿Cómo se dice 'window' en español? | G2: la ventana | H2: la puerta · el techo · el suelo | I2: 'La ventana' es window. 'La puerta' es puerta, 'el techo' es techo, 'el suelo' es suelo. | J2: 'La ventana' is window. 'La puerta' is door, 'el techo' is ceiling/roof, 'el suelo' is floor. | K2: (respuesta incorrecta) → 'window' en español es 'la ventana'. la puerta → door. el techo → ceiling/roof. el suelo → floor. | O2: data/tracks/esForEn.js
A3: PR-0002 | B3: esForEn | C3: vocab | D3: A2 | E3: vocab[1] | F3: ¿Cómo se dice 'to forget' en español? | G3: olvidar | H3: recordar · encontrar · perder | I3: 'Olvidar' significa to forget. 'Recordar' es lo contrario; 'encontrar' es to find, 'perder' es to lose. | J3: 'Olvidar' means to forget. 'Recordar' is the opposite (to remember); 'encontrar' is to find, 'perder' is to lose. | K3: (respuesta incorrecta) → 'to forget' en español es 'olvidar'. recordar → to remember — the opposite. encontrar → to find. perder → to lose. | O3: data/tracks/esForEn.js
A4: PR-0003 | B4: esForEn | C4: vocab | D4: A2 | E4: vocab[2] | F4: 'La almohada' significa... | G4: pillow | H4: blanket · mattress · curtain | I4: 'La almohada' es pillow. Manta es blanket, colchón es mattress, cortina es curtain. | J4: 'La almohada' is pillow. Blanket is 'la manta', mattress is 'el colchón', curtain is 'la cortina'. | K4: (respuesta incorrecta) → 'La almohada' significa 'pillow'. blanket → 'la manta'. mattress → 'el colchón'. curtain → 'la cortina'. | O4: data/tracks/esForEn.js
A5: PR-0004 | B5: esForEn | C5: vocab | D5: B1 | E5: vocab[3] | F5: ¿Cómo se dice 'deadline' en español? | G5: la fecha límite | H5: la hora feliz · el plazo libre · la cita rápida | I5: 'La fecha límite' (o 'el plazo') es la forma estándar de decir deadline. Las otras opciones son frases inventadas. | J5: 'La fecha límite' (or 'el plazo') is the standard way to say deadline. The other options are invented phrases. | K5: (respuesta incorrecta) → 'deadline' en español es 'la fecha límite'. 'el plazo' también sirve. la hora feliz → 'happy hour' — invented here. el plazo libre → an invented phrase. la cita rápida → 'a quick date' — invented here. | O5: data/tracks/esForEn.js
A6: PR-0005 | B6: esForEn | C6: vocab | D6: B1 | E6: vocab[4] | F6: 'Madrugar' significa... | G6: to wake up early | H6: to stay up late · to take a nap · to oversleep | I6: 'Madrugar' significa levantarse temprano. Está relacionado con 'la madrugada'. | J6: 'Madrugar' means to wake up early / get an early start. It's related to 'la madrugada' (early morning hours). | K6: (respuesta incorrecta) → 'Madrugar' significa 'to wake up early'. Ligado a 'la madrugada'. to stay up late → 'trasnochar'. to take a nap → 'tomar una siesta'. to oversleep → 'quedarse dormido'. | O6: data/tracks/esForEn.js
A7: PR-0006 | B7: esForEn | C7: vocab | D7: A2 | E7: vocab[5] | F7: ¿Cómo se dice 'keyboard' en español? | G7: el teclado | H7: el ratón · la pantalla · el cable | I7: 'El teclado' es keyboard. 'El ratón' es mouse, 'la pantalla' es screen, 'el cable' es cable. | J7: 'El teclado' is keyboard. 'El ratón' is mouse, 'la pantalla' is screen, 'el cable' is cable. | K7: (respuesta incorrecta) → 'keyboard' en español es 'el teclado'. el ratón → mouse. la pantalla → screen. el cable → cable. | O7: data/tracks/esForEn.js
A8: PR-0007 | B8: esForEn | C8: vocab | D8: B1 | E8: vocab[6] | F8: 'Aprovechar' significa... | G8: to make the most of | H8: to waste · to forget about · to postpone | I8: 'Aprovechar' significa sacarle el máximo provecho a algo, casi siempre en sentido positivo. | J8: 'Aprovechar' means to make the most of / take advantage of an opportunity — usually positive in Spanish. | K8: (respuesta incorrecta) → 'Aprovechar' significa 'to make the most of'. Suele tener un sentido positivo. to waste → 'desperdiciar'. to forget about → 'olvidarse de'. to postpone → 'posponer'. | O8: data/tracks/esForEn.js
A9: PR-0008 | B9: esForEn | C9: vocab | D9: A2 | E9: vocab[7] | F9: ¿Cómo se dice 'stubborn' en español? | G9: terco | H9: amable · tímido · generoso | I9: 'Terco' significa stubborn. 'Amable' es kind, 'tímido' es shy, 'generoso' es generous. | J9: 'Terco' (also 'testarudo') means stubborn. 'Amable' is kind, 'tímido' is shy, 'generoso' is generous. | K9: (respuesta incorrecta) → 'stubborn' en español es 'terco'. 'testarudo' también. amable → kind. tímido → shy. generoso → generous. | O9: data/tracks/esForEn.js
A10: PR-0009 | B10: esForEn | C10: vocab | D10: B1 | E10: vocab[8] | F10: 'La factura' significa... | G10: the bill/invoice | H10: the receipt bag · the folder · the contract | I10: 'La factura' es the bill/invoice. Recibo es receipt, carpeta es folder, contrato es contract. | J10: 'La factura' is a bill or invoice. A receipt is 'el recibo', folder is 'la carpeta', contract is 'el contrato'. | K10: (respuesta incorrecta) → 'La factura' significa 'the bill/invoice'. the receipt bag → a receipt is 'el recibo'. the folder → 'la carpeta'. the contract → 'el contrato'. | O10: data/tracks/esForEn.js
A11: PR-0010 | B11: esForEn | C11: vocab | D11: A2 | E11: vocab[9] | F11: ¿Cómo se dice 'to fix' (repair) en español? | G11: arreglar | H11: romper · mover · vender | I11: 'Arreglar' significa to fix/repair. 'Romper' es to break, 'mover' es to move, 'vender' es to sell. | J11: 'Arreglar' means to fix or repair. 'Romper' is to break, 'mover' is to move, 'vender' is to sell. | K11: (respuesta incorrecta) → 'to fix (repair)' en español es 'arreglar'. romper → to break. mover → to move. vender → to sell. | O11: data/tracks/esForEn.js
A12: PR-0011 | B12: esForEn | C12: vocab | D12: B1 | E12: vocab[10] | F12: 'Chismear' significa... | G12: to gossip | H12: to cook · to shout · to travel | I12: 'Chismear' significa hablar de chismes; viene del sustantivo 'el chisme'. | J12: 'Chismear' means to gossip, from the noun 'el chisme' (gossip/rumor). | K12: (respuesta incorrecta) → 'Chismear' significa 'to gossip'. De 'el chisme'. to cook → 'cocinar'. to shout → 'gritar'. to travel → 'viajar'. | O12: data/tracks/esForEn.js
A13: PR-0012 | B13: esForEn | C13: vocab | D13: A2 | E13: vocab[11] | F13: ¿Cómo se dice 'roommate' en español? | G13: el compañero de cuarto | H13: el vecino lejano · el desconocido · el invitado | I13: 'El compañero de cuarto' (o 'de piso' en España) es roommate. Vecino es neighbor, desconocido es stranger, invitado es guest. | J13: 'El compañero de cuarto' (or 'compañero de piso' in Spain) is roommate. 'Vecino' is neighbor, 'desconocido' is stranger, 'invitado' is guest. | K13: (respuesta incorrecta) → 'roommate' en español es 'el compañero de cuarto'. 'compañero de piso' en España. el vecino lejano → distant neighbor. el desconocido → stranger. el invitado → guest. | O13: data/tracks/esForEn.js
... A666: PR-0665 | B666: esForEn | C666: trad | D666: C2 | E666: trad[126] | F666: Translate: 'He was caught red-handed.' | G666: Lo agarraron con las manos en la masa. | H666: Lo atraparon con las manos rojas. · Lo pillaron con la mano teñida de rojo. · Lo capturaron con las manos ensangrentadas. | I666: El español imagina las manos 'en la masa', no manos literalmente rojas o ensangrentadas. | J666: Spanish pictures hands 'in the dough' (from baking/theft imagery), not literally red hands. | K666: (respuesta incorrecta) → 'He was caught red-handed' es 'Lo agarraron con las manos en la masa' en español natural. El español imagina las manos 'en la masa'. Lo atraparon con las manos rojas. → el calco literal — el español no lo dice así. Lo pillaron con la mano teñida de rojo. → literalmente 'with a hand dyed red' — no es la forma natural. Lo capturaron con las manos ensangrentadas. → literalmente 'with bloodied hands' — no es la forma natural. | O666: data/tracks/esForEn.js

Sheet 2-Pronunciación
A1: ID | B1: Curso | C1: Clave | D1: Nivel | E1: Frase | F1: Pronunciación escrita | G1: Respuesta correcta | H1: Opciones incorrectas | I1: Explicación en español | J1: Pares mínimos | K1: VEREDICTO | L1: CORRECCIÓN SUGERIDA | M1: NOTA / MOTIVO | N1: Archivo
A2: FO-001 | B2: esForEn | C2: FONO_BANK[0] | D2: A2 | E2: ¿Qué hora es? | F2: keh‿OH-rah‿ehs | G2: ¿Qué hora es? | H2: ¿Qué horror es? · ¿Cómo te va? · ¿Qué comes tú? | I2: 'Hora' y 'horror' suenan muy parecido. | N2: data/tracks/esForEn.js
A3: FO-002 | B3: esForEn | C3: FONO_BANK[1] | D3: A2 | E3: ¿Puedes ayudarme con esto? | F3: PWEH-dehs ah-yoo-DAR-meh kohn‿EHS-toh | G3: ¿Puedes ayudarme con esto? | H3: ¿Puedes ayunarme con eso? · ¿Puedo ayudarte con eso? · ¿Puedes odiarme por eso? | I3: 'Ayudarme' vs. 'ayunarme' (cerca de 'ayunar'). | N3: data/tracks/esForEn.js
A4: FO-003 | B4: esForEn | C4: FONO_BANK[2] | D4: B1 | E4: Se me hace tarde, tengo que irme. | F4: seh meh AH-seh TAR-deh, TEHN-goh keh‿EER-meh | G4: Se me hace tarde, tengo que irme. | H4: Se me hace tarde, tengo que reírme. · Se me olvida todo, tengo que dormir. · Se me hace fácil, tengo que decirlo. | I4: 'Irme' y 'reírme' comparten la terminación '-írme'. | N4: data/tracks/esForEn.js
A5: FO-004 | B5: esForEn | C5: FONO_BANK[3] | D5: B1 | E5: ¿Te gustaría salir a cenar esta noche? | F5: teh goos-tah-REE-ah sah-LEER‿ah seh-NAR‿EHS-tah NOH-cheh | G5: ¿Te gustaría salir a cenar esta noche? | H5: ¿Te gustaría salir a contar esta noche? · ¿Te gustaría salir a correr esta noche? · ¿Te gustaría subir a ver la noche? | I5: 'Cenar', 'contar' y 'correr' empiezan igual. | N5: data/tracks/esForEn.js
A6: FO-005 | B6: esForEn | C6: FONO_BANK[4] | D6: A2 | E6: ¿Dónde dejaste las llaves? | F6: DOHN-deh deh-HAHS-teh lahs YAH-vehs | G6: ¿Dónde dejaste las llaves? | H6: ¿Dónde dejaste las calles? · ¿Cómo dejaste las llaves? · ¿Dónde compraste las llaves? | I6: 'Llaves' y 'calles' riman mucho. | N6: data/tracks/esForEn.js
A7: FO-006 | B7: esForEn | C7: FONO_BANK[5] | D7: A2 | E7: ¿Cuánto cuesta esta camisa? | F7: KWAHN-toh KWEHS-tah‿EHS-tah kah-MEE-sah | G7: ¿Cuánto cuesta esta camisa? | H7: ¿Cuánto cuesta esta cosecha? · ¿Cómo se ve esta camisa? · ¿Dónde compraste esta camisa? | I7: 'Camisa' y 'cosecha' comparten ritmo. | N7: data/tracks/esForEn.js
A8: FO-007 | B8: esForEn | C8: FONO_BANK[6] | D8: B1 | E8: Perdón, ¿me puede repetir eso? | F8: pehr-DOHN, meh PWEH-deh reh-peh-TEER‿EH-soh | G8: Perdón, ¿me puede repetir eso? | H8: Perdón, ¿me puede recibir eso? · Perdón, ¿me puede permitir eso? · Perdón, ¿me puede regalar eso? | I8: 'Repetir', 'recibir', 'permitir' y 'regalar' comparten sonidos iniciales. | N8: data/tracks/esForEn.js
A9: FO-008 | B9: esForEn | C9: FONO_BANK[7] | D9: B1 | E9: ¿A qué hora empieza la película? | F9: ah‿keh‿OH-rah‿ehm-PYEH-sah lah peh-LEE-koo-lah | G9: ¿A qué hora empieza la película? | H9: ¿A qué hora empieza la reunión? · ¿A qué hora termina la película? · ¿A qué hora llega la comida? | I9: El sujeto y el verbo pueden cambiar — hay que captar ambos. | N9: data/tracks/esForEn.js
A10: FO-009 | B10: esForEn | C10: FONO_BANK[8] | D10: A2 | E10: Vamos a la playa el sábado. | F10: BAH-mohs ah lah PLAH-yah‿ehl SAH-bah-doh | G10: Vamos a la playa el sábado. | H10: Vamos a la plaza el sábado. · Vamos a la playa el sábado pasado. · Vamos a la plancha el sábado. | I10: La 'b' y la 'v' se pronuncian exactamente igual en español — 'vamos' empieza con sonido de 'b'. 'Playa' vs 'plaza' es la trampa auditiva: en Latinoamérica la 'z' suena igual que la 's' (seseo). | N10: data/tracks/esForEn.js
A11: FO-010 | B11: esForEn | C11: FONO_BANK[9] | D11: A2 | E11: Hace mucho calor hoy. | F11: AH-seh MOO-choh kah-LOHR‿oy | G11: Hace mucho calor hoy. | H11: Hace mucho color hoy. · Hace poco calor hoy. · Hizo mucho calor ayer. | I11: La 'h' siempre es muda en español — 'hace' empieza directo en la vocal, y 'hoy' es puro "oy". 'Calor' y 'color' se diferencian por una sola vocal. | N11: data/tracks/esForEn.js
A12: FO-011 | B12: esForEn | C12: FONO_BANK[10] | D12: A2 | E12: ¿Me pasas la sal, por favor? | F12: meh PAH-sahs lah SAHL, pohr fah-BOHR | G12: ¿Me pasas la sal, por favor? | H12: ¿Me pesas la sal, por favor? · ¿Me pasas la sala, por favor? · ¿Me pasas el pan, por favor? | I12: 'Pasas' vs 'pesas' se distinguen por una sola vocal — las cinco vocales puras del español nunca se relajan ni se reducen, así que las distinciones a/e pesan por completo. Y 'favor' muestra otra vez b/v: "fah-BOHR". | N12: data/tracks/esForEn.js
A13: FO-012 | B13: esForEn | C13: FONO_BANK[11] | D13: A2 | E13: Mañana cumplo veinte años. | F13: mah-NYAH-nah KOOM-ploh BAYN-teh AH-nyohs | G13: Mañana cumplo veinte años. | H13: Mañana cumplo treinta años. · Mañana compro veinte años. · Ayer cumplí veinte años. | I13: La 'ñ' es una letra propia con su propio sonido — 'mañana', 'años'. 'Cumplo' vs 'compro' y 'veinte' vs 'treinta' son las trampas para el oído. | N13: data/tracks/esForEn.js
... A80: FO-079 | B80: esForEn | C80: FONO_BANK[78] | D80: C2 | E80: Esto no va a cambiar si nadie hace nada. | F80: EHS-toh noh VAH‿kahm-BYAHR see NAH-dyeh AH-seh NAH-dah | G80: Esto no va a cambiar si nadie hace nada. | H80: Esto no va a cambiar si nadie hace nadar. · Esto no va a cambiar si nadie ase nada. · Esto no iba a cambiar si nadie hace nada. | I80: El habla rápida contrae 'va a' en una sola vocal y también puede debilitar 'iba a' de forma parecida, mientras que el seseo hace que 'hace' y 'ase' (de asar) suenen igual, y una sílaba final puede convertir 'nada' en 'nadar'. | N80: data/tracks/esForEn.js

Sheet 3-Banco-de-palabras
A1: ID | B1: Clave | C1: Palabra en español | D1: Significado en inglés | E1: Categoría gramatical | F1: Nivel | G1: Nota didáctica | H1: VEREDICTO | I1: CORRECCIÓN SUGERIDA | J1: NOTA / MOTIVO | K1: Archivo
A2: BP-0001 | B2: [0] | C2: el tiempo | D2: time; weather | E2: n | F2: A1 | G2: One word for both — context decides. | K2: data/vocab/esLatAmWords.js
A3: BP-0002 | B3: [1] | C3: el año | D3: year | E3: n | F3: A1 | K3: data/vocab/esLatAmWords.js
A4: BP-0003 | B4: [2] | C4: el día | D4: day | E4: n | F4: A1 | G4: Ends in -a but is masculine: el día. | K4: data/vocab/esLatAmWords.js
A5: BP-0004 | B5: [3] | C5: la vez | D5: time (occasion) | E5: n | F5: A1 | G5: Una vez = once; a veces = sometimes. | K5: data/vocab/esLatAmWords.js
A6: BP-0005 | B6: [4] | C6: la vida | D6: life | E6: n | F6: A1 | K6: data/vocab/esLatAmWords.js
A7: BP-0006 | B7: [5] | C7: el hombre | D7: man | E7: n | F7: A1 | K7: data/vocab/esLatAmWords.js
A8: BP-0007 | B8: [6] | C8: la mujer | D8: woman; wife | E8: n | F8: A1 | K8: data/vocab/esLatAmWords.js
A9: BP-0008 | B9: [7] | C9: el niño | D9: child; boy | E9: n | F9: A1 | K9: data/vocab/esLatAmWords.js
A10: BP-0009 | B10: [8] | C10: la mano | D10: hand | E10: n | F10: A1 | G10: Ends in -o but is feminine: la mano. | K10: data/vocab/esLatAmWords.js
A11: BP-0010 | B11: [9] | C11: el ojo | D11: eye | E11: n | F11: A1 | K11: data/vocab/esLatAmWords.js
A12: BP-0011 | B12: [10] | C12: el agua | D12: water | E12: n | F12: A1 | G12: Feminine noun that takes 'el' for sound: el agua fría. | K12: data/vocab/esLatAmWords.js
A13: BP-0012 | B13: [11] | C13: la mesa | D13: table | E13: n | F13: A1 | K13: data/vocab/esLatAmWords.js
A14: BP-0013 | B14: [12] | C14: la silla | D14: chair | E14: n | F14: A1 | K14: data/vocab/esLatAmWords.js
A15: BP-0014 | B15: [13] | C15: la puerta | D15: door | E15: n | F15: A1 | K15: data/vocab/esLatAmWords.js
A16: BP-0015 | B16: [14] | C16: el libro | D16: book | E16: n | F16: A1 | K16: data/vocab/esLatAmWords.js
A17: BP-0016 | B17: [15] | C17: la escuela | D17: school | E17: n | F17: A1 | K17: data/vocab/esLatAmWords.js
A18: BP-0017 | B18: [16] | C18: la ciudad | D18: city | E18: n | F18: A1 | K18: data/vocab/esLatAmWords.js
A19: BP-0018 | B19: [17] | C19: el país | D19: country (nation) | E19: n | F19: A1 | K19: data/vocab/esLatAmWords.js
A20: BP-0019 | B20: [18] | C20: el mundo | D20: world | E20: n | F20: A1 | K20: data/vocab/esLatAmWords.js
A21: BP-0020 | B21: [19] | C21: la noche | D21: night | E21: n | F21: A1 | K21: data/vocab/esLatAmWords.js
A22: BP-0021 | B22: [20] | C22: la mañana | D22: morning | E22: n | F22: A1 | G22: As an adverb, mañana = tomorrow. | K22: data/vocab/esLatAmWords.js
A23: BP-0022 | B23: [21] | C23: la semana | D23: week | E23: n | F23: A1 | K23: data/vocab/esLatAmWords.js
A24: BP-0023 | B24: [22] | C24: el mes | D24: month | E24: n | F24: A1 | K24: data/vocab/esLatAmWords.js
A25: BP-0024 | B25: [23] | C25: la hora | D25: hour; time of day | E25: n | F25: A1 | K25: data/vocab/esLatAmWords.js
A26: BP-0025 | B26: [24] | C26: el minuto | D26: minute | E26: n | F26: A1 | K26: data/vocab/esLatAmWords.js
A27: BP-0026 | B27: [25] | C27: el nombre | D27: name | E27: n | F27: A1 | K27: data/vocab/esLatAmWords.js
A28: BP-0027 | B28: [26] | C28: la familia | D28: family | E28: n | F28: A1 | K28: data/vocab/esLatAmWords.js
A29: BP-0028 | B29: [27] | C29: el padre | D29: father | E29: n | F29: A1 | G29: Los padres = parents, not just fathers. | K29: data/vocab/esLatAmWords.js
A30: BP-0029 | B30: [28] | C30: la madre | D30: mother | E30: n | F30: A1 | K30: data/vocab/esLatAmWords.js
A31: BP-0030 | B31: [29] | C31: el hijo | D31: son | E31: n | F31: A1 | G31: Los hijos = children (sons and daughters). | K31: data/vocab/esLatAmWords.js
A32: BP-0031 | B32: [30] | C32: la hija | D32: daughter | E32: n | F32: A1 | K32: data/vocab/esLatAmWords.js
A33: BP-0032 | B33: [31] | C33: el hermano | D33: brother | E33: n | F33: A1 | K33: data/vocab/esLatAmWords.js
A34: BP-0033 | B34: [32] | C34: la hermana | D34: sister | E34: n | F34: A1 | K34: data/vocab/esLatAmWords.js
A35: BP-0034 | B35: [33] | C35: el amigo | D35: friend | E35: n | F35: A1 | K35: data/vocab/esLatAmWords.js
A36: BP-0035 | B36: [34] | C36: el gato | D36: cat | E36: n | F36: A1 | K36: data/vocab/esLatAmWords.js
A37: BP-0036 | B37: [35] | C37: el pan | D37: bread | E37: n | F37: A1 | K37: data/vocab/esLatAmWords.js
A38: BP-0037 | B38: [36] | C38: la leche | D38: milk | E38: n | F38: A1 | K38: data/vocab/esLatAmWords.js
A39: BP-0038 | B39: [37] | C39: el café | D39: coffee | E39: n | F39: A1 | K39: data/vocab/esLatAmWords.js
A40: BP-0039 | B40: [38] | C40: la fruta | D40: fruit | E40: n | F40: A1 | K40: data/vocab/esLatAmWords.js
...

Sheet 4-Decisiones
A1: ID | B1: Tema | C1: Qué decidimos y por qué | D1: Ejemplo / dónde | E1: DECISIÓN | F1: ALTERNATIVA PROPUESTA | G1: NOTA
A2: DEC-01 | B2: Qué estamos preguntando aquí | C2: Este paquete NO es sobre cómo se lee la app. Es sobre el español que la app ENSEÑA a personas angloparlantes que están aprendiendo. Un error aquí no incomoda: enseña mal. | D2: Curso «Español (Latinoamérica)» para hablantes de inglés
A3: DEC-02 | B3: Las opciones incorrectas importan tanto como la correcta | C3: Cada pregunta tiene una respuesta correcta y tres incorrectas. Si alguna «incorrecta» también es válida, la pregunta está rota aunque la respuesta marcada sea buena. | D3: «¿Cómo se dice 'window'?» → la ventana / la puerta / el techo / el suelo
A4: DEC-03 | B4: Variedad | C4: El curso enseña español latinoamericano neutro: seseo, yeísmo, sin vosotros. Donde hay divergencia regional se enseña como contenido, no se esconde. | D4: carro/coche · celular/móvil · jugo/zumo · chévere/chido/bacán
A5: DEC-04 | B5: Explicaciones sin traducir (problema conocido) | C5: Unas 400 notas de opciones incorrectas tienen el texto en inglés en el campo español. Ya lo detectamos y lo vamos a rehacer — no hace falta que las marques una por una, pero avísanos si ves otras formas del mismo problema. | D5: «el techo → ceiling/roof.» en el campo español
A6: DEC-05 | B6: Explicaciones circulares (problema conocido) | C6: Algunas explicaciones en español se generaron traduciendo la explicación inglesa, y quedaron sin decir nada. | D6: «'La puerta' es puerta, 'el techo' es techo»
A7: DEC-06 | B7: Nivel MCER | C7: Cada pregunta lleva un nivel (A1–C2). Si una te parece mal ubicada, dilo: cambia a quién se le muestra. | D7: Columna «Nivel»
A8: DEC-07 | B8: Notas didácticas del Banco de Palabras | C8: Las notas del Banco de Palabras están en inglés a propósito (el curso es para angloparlantes). Revisa que el dato sea correcto, no el idioma. | D8: «el día» → «Ends in -a but is masculine»
A9: DEC-08 | B9: Pronunciación escrita | C9: La pronunciación se escribe con un respelling legible, no con AFI. Confirma que se lee bien para una persona angloparlante. | D9: «¿Qué hora es?» → keh‿OH-rah‿ehs
